2022-01-29 02:18:14,510 ERROR: Exception on /_styles.css [GET] [int /home/new_user/Desktop/Flask_ss/venv/lib/python3.8/site-packages/flask/app.py:1457]
Traceback (most recent call last):
  File "/home/new_user/Desktop/Flask_ss/venv/lib/python3.8/site-packages/flask/app.py", line 1516, in full_dispatch_request
    rv = self.dispatch_request()
  File "/home/new_user/Desktop/Flask_ss/venv/lib/python3.8/site-packages/flask/app.py", line 1492, in dispatch_request
    self.raise_routing_exception(req)
  File "/home/new_user/Desktop/Flask_ss/venv/lib/python3.8/site-packages/flask/app.py", line 1474, in raise_routing_exception
    raise request.routing_exception  # type: ignore
  File "/home/new_user/Desktop/Flask_ss/venv/lib/python3.8/site-packages/flask/ctx.py", line 367, in match_request
    result = self.url_adapter.match(return_rule=True)  # type: ignore
  File "/home/new_user/Desktop/Flask_ss/venv/lib/python3.8/site-packages/werkzeug/routing.py", line 2032, in match
    raise NotFound()
werkzeug.exceptions.NotFound: 404 Not Found: The requested URL was not found on the server. If you entered the URL manually please check your spelling and try again.

During handling of the above exception, another exception occurred:

Traceback (most recent call last):
  File "/home/new_user/Desktop/Flask_ss/venv/lib/python3.8/site-packages/flask/app.py", line 2073, in wsgi_app
    response = self.full_dispatch_request()
  File "/home/new_user/Desktop/Flask_ss/venv/lib/python3.8/site-packages/flask/app.py", line 1518, in full_dispatch_request
    rv = self.handle_user_exception(e)
  File "/home/new_user/Desktop/Flask_ss/venv/lib/python3.8/site-packages/flask/app.py", line 1386, in handle_user_exception
    return self.handle_http_exception(e)
  File "/home/new_user/Desktop/Flask_ss/venv/lib/python3.8/site-packages/flask/app.py", line 1326, in handle_http_exception
    return self.ensure_sync(handler)(e)
TypeError: not_found_error() takes 0 positional arguments but 1 was given
2022-01-29 02:18:14,986 ERROR: Exception on /favicon.ico [GET] [int /home/new_user/Desktop/Flask_ss/venv/lib/python3.8/site-packages/flask/app.py:1457]
Traceback (most recent call last):
  File "/home/new_user/Desktop/Flask_ss/venv/lib/python3.8/site-packages/flask/app.py", line 1516, in full_dispatch_request
    rv = self.dispatch_request()
  File "/home/new_user/Desktop/Flask_ss/venv/lib/python3.8/site-packages/flask/app.py", line 1492, in dispatch_request
    self.raise_routing_exception(req)
  File "/home/new_user/Desktop/Flask_ss/venv/lib/python3.8/site-packages/flask/app.py", line 1474, in raise_routing_exception
    raise request.routing_exception  # type: ignore
  File "/home/new_user/Desktop/Flask_ss/venv/lib/python3.8/site-packages/flask/ctx.py", line 367, in match_request
    result = self.url_adapter.match(return_rule=True)  # type: ignore
  File "/home/new_user/Desktop/Flask_ss/venv/lib/python3.8/site-packages/werkzeug/routing.py", line 2032, in match
    raise NotFound()
werkzeug.exceptions.NotFound: 404 Not Found: The requested URL was not found on the server. If you entered the URL manually please check your spelling and try again.

During handling of the above exception, another exception occurred:

Traceback (most recent call last):
  File "/home/new_user/Desktop/Flask_ss/venv/lib/python3.8/site-packages/flask/app.py", line 2073, in wsgi_app
    response = self.full_dispatch_request()
  File "/home/new_user/Desktop/Flask_ss/venv/lib/python3.8/site-packages/flask/app.py", line 1518, in full_dispatch_request
    rv = self.handle_user_exception(e)
  File "/home/new_user/Desktop/Flask_ss/venv/lib/python3.8/site-packages/flask/app.py", line 1386, in handle_user_exception
    return self.handle_http_exception(e)
  File "/home/new_user/Desktop/Flask_ss/venv/lib/python3.8/site-packages/flask/app.py", line 1326, in handle_http_exception
    return self.ensure_sync(handler)(e)
TypeError: not_found_error() takes 0 positional arguments but 1 was given
2022-01-29 02:22:47,791 INFO: Microbial startup [int /home/new_user/Desktop/Flask_ss/app/__init__.py:77]
2022-01-29 02:23:06,655 INFO: Microbial startup [int /home/new_user/Desktop/Flask_ss/app/__init__.py:77]
2022-01-29 02:23:10,407 ERROR: Exception on /_styles.css [GET] [int /home/new_user/Desktop/Flask_ss/venv/lib/python3.8/site-packages/flask/app.py:1457]
Traceback (most recent call last):
  File "/home/new_user/Desktop/Flask_ss/venv/lib/python3.8/site-packages/flask/app.py", line 1516, in full_dispatch_request
    rv = self.dispatch_request()
  File "/home/new_user/Desktop/Flask_ss/venv/lib/python3.8/site-packages/flask/app.py", line 1492, in dispatch_request
    self.raise_routing_exception(req)
  File "/home/new_user/Desktop/Flask_ss/venv/lib/python3.8/site-packages/flask/app.py", line 1474, in raise_routing_exception
    raise request.routing_exception  # type: ignore
  File "/home/new_user/Desktop/Flask_ss/venv/lib/python3.8/site-packages/flask/ctx.py", line 367, in match_request
    result = self.url_adapter.match(return_rule=True)  # type: ignore
  File "/home/new_user/Desktop/Flask_ss/venv/lib/python3.8/site-packages/werkzeug/routing.py", line 2032, in match
    raise NotFound()
werkzeug.exceptions.NotFound: 404 Not Found: The requested URL was not found on the server. If you entered the URL manually please check your spelling and try again.

During handling of the above exception, another exception occurred:

Traceback (most recent call last):
  File "/home/new_user/Desktop/Flask_ss/venv/lib/python3.8/site-packages/flask/app.py", line 2073, in wsgi_app
    response = self.full_dispatch_request()
  File "/home/new_user/Desktop/Flask_ss/venv/lib/python3.8/site-packages/flask/app.py", line 1518, in full_dispatch_request
    rv = self.handle_user_exception(e)
  File "/home/new_user/Desktop/Flask_ss/venv/lib/python3.8/site-packages/flask/app.py", line 1386, in handle_user_exception
    return self.handle_http_exception(e)
  File "/home/new_user/Desktop/Flask_ss/venv/lib/python3.8/site-packages/flask/app.py", line 1326, in handle_http_exception
    return self.ensure_sync(handler)(e)
TypeError: not_found_error() takes 0 positional arguments but 1 was given
2022-01-29 02:23:11,052 ERROR: Exception on /favicon.ico [GET] [int /home/new_user/Desktop/Flask_ss/venv/lib/python3.8/site-packages/flask/app.py:1457]
Traceback (most recent call last):
  File "/home/new_user/Desktop/Flask_ss/venv/lib/python3.8/site-packages/flask/app.py", line 1516, in full_dispatch_request
    rv = self.dispatch_request()
  File "/home/new_user/Desktop/Flask_ss/venv/lib/python3.8/site-packages/flask/app.py", line 1492, in dispatch_request
    self.raise_routing_exception(req)
  File "/home/new_user/Desktop/Flask_ss/venv/lib/python3.8/site-packages/flask/app.py", line 1474, in raise_routing_exception
    raise request.routing_exception  # type: ignore
  File "/home/new_user/Desktop/Flask_ss/venv/lib/python3.8/site-packages/flask/ctx.py", line 367, in match_request
    result = self.url_adapter.match(return_rule=True)  # type: ignore
  File "/home/new_user/Desktop/Flask_ss/venv/lib/python3.8/site-packages/werkzeug/routing.py", line 2032, in match
    raise NotFound()
werkzeug.exceptions.NotFound: 404 Not Found: The requested URL was not found on the server. If you entered the URL manually please check your spelling and try again.

During handling of the above exception, another exception occurred:

Traceback (most recent call last):
  File "/home/new_user/Desktop/Flask_ss/venv/lib/python3.8/site-packages/flask/app.py", line 2073, in wsgi_app
    response = self.full_dispatch_request()
  File "/home/new_user/Desktop/Flask_ss/venv/lib/python3.8/site-packages/flask/app.py", line 1518, in full_dispatch_request
    rv = self.handle_user_exception(e)
  File "/home/new_user/Desktop/Flask_ss/venv/lib/python3.8/site-packages/flask/app.py", line 1386, in handle_user_exception
    return self.handle_http_exception(e)
  File "/home/new_user/Desktop/Flask_ss/venv/lib/python3.8/site-packages/flask/app.py", line 1326, in handle_http_exception
    return self.ensure_sync(handler)(e)
TypeError: not_found_error() takes 0 positional arguments but 1 was given
2022-01-29 02:26:19,344 ERROR: Exception on /_styles.css [GET] [int /home/new_user/Desktop/Flask_ss/venv/lib/python3.8/site-packages/flask/app.py:1457]
Traceback (most recent call last):
  File "/home/new_user/Desktop/Flask_ss/venv/lib/python3.8/site-packages/flask/app.py", line 1516, in full_dispatch_request
    rv = self.dispatch_request()
  File "/home/new_user/Desktop/Flask_ss/venv/lib/python3.8/site-packages/flask/app.py", line 1492, in dispatch_request
    self.raise_routing_exception(req)
  File "/home/new_user/Desktop/Flask_ss/venv/lib/python3.8/site-packages/flask/app.py", line 1474, in raise_routing_exception
    raise request.routing_exception  # type: ignore
  File "/home/new_user/Desktop/Flask_ss/venv/lib/python3.8/site-packages/flask/ctx.py", line 367, in match_request
    result = self.url_adapter.match(return_rule=True)  # type: ignore
  File "/home/new_user/Desktop/Flask_ss/venv/lib/python3.8/site-packages/werkzeug/routing.py", line 2032, in match
    raise NotFound()
werkzeug.exceptions.NotFound: 404 Not Found: The requested URL was not found on the server. If you entered the URL manually please check your spelling and try again.

During handling of the above exception, another exception occurred:

Traceback (most recent call last):
  File "/home/new_user/Desktop/Flask_ss/venv/lib/python3.8/site-packages/flask/app.py", line 2073, in wsgi_app
    response = self.full_dispatch_request()
  File "/home/new_user/Desktop/Flask_ss/venv/lib/python3.8/site-packages/flask/app.py", line 1518, in full_dispatch_request
    rv = self.handle_user_exception(e)
  File "/home/new_user/Desktop/Flask_ss/venv/lib/python3.8/site-packages/flask/app.py", line 1386, in handle_user_exception
    return self.handle_http_exception(e)
  File "/home/new_user/Desktop/Flask_ss/venv/lib/python3.8/site-packages/flask/app.py", line 1326, in handle_http_exception
    return self.ensure_sync(handler)(e)
TypeError: not_found_error() takes 0 positional arguments but 1 was given
2022-01-29 02:26:19,505 ERROR: Exception on /favicon.ico [GET] [int /home/new_user/Desktop/Flask_ss/venv/lib/python3.8/site-packages/flask/app.py:1457]
Traceback (most recent call last):
  File "/home/new_user/Desktop/Flask_ss/venv/lib/python3.8/site-packages/flask/app.py", line 1516, in full_dispatch_request
    rv = self.dispatch_request()
  File "/home/new_user/Desktop/Flask_ss/venv/lib/python3.8/site-packages/flask/app.py", line 1492, in dispatch_request
    self.raise_routing_exception(req)
  File "/home/new_user/Desktop/Flask_ss/venv/lib/python3.8/site-packages/flask/app.py", line 1474, in raise_routing_exception
    raise request.routing_exception  # type: ignore
  File "/home/new_user/Desktop/Flask_ss/venv/lib/python3.8/site-packages/flask/ctx.py", line 367, in match_request
    result = self.url_adapter.match(return_rule=True)  # type: ignore
  File "/home/new_user/Desktop/Flask_ss/venv/lib/python3.8/site-packages/werkzeug/routing.py", line 2032, in match
    raise NotFound()
werkzeug.exceptions.NotFound: 404 Not Found: The requested URL was not found on the server. If you entered the URL manually please check your spelling and try again.

During handling of the above exception, another exception occurred:

Traceback (most recent call last):
  File "/home/new_user/Desktop/Flask_ss/venv/lib/python3.8/site-packages/flask/app.py", line 2073, in wsgi_app
    response = self.full_dispatch_request()
  File "/home/new_user/Desktop/Flask_ss/venv/lib/python3.8/site-packages/flask/app.py", line 1518, in full_dispatch_request
    rv = self.handle_user_exception(e)
  File "/home/new_user/Desktop/Flask_ss/venv/lib/python3.8/site-packages/flask/app.py", line 1386, in handle_user_exception
    return self.handle_http_exception(e)
  File "/home/new_user/Desktop/Flask_ss/venv/lib/python3.8/site-packages/flask/app.py", line 1326, in handle_http_exception
    return self.ensure_sync(handler)(e)
TypeError: not_found_error() takes 0 positional arguments but 1 was given
2022-01-29 02:30:09,023 INFO: Microbial startup [int /home/new_user/Desktop/Flask_ss/app/__init__.py:77]
2022-01-29 02:30:18,544 INFO: Microbial startup [int /home/new_user/Desktop/Flask_ss/app/__init__.py:77]
2022-01-29 02:30:34,387 ERROR: Exception on /_styles.css [GET] [int /home/new_user/Desktop/Flask_ss/venv/lib/python3.8/site-packages/flask/app.py:1457]
Traceback (most recent call last):
  File "/home/new_user/Desktop/Flask_ss/venv/lib/python3.8/site-packages/flask/app.py", line 1516, in full_dispatch_request
    rv = self.dispatch_request()
  File "/home/new_user/Desktop/Flask_ss/venv/lib/python3.8/site-packages/flask/app.py", line 1492, in dispatch_request
    self.raise_routing_exception(req)
  File "/home/new_user/Desktop/Flask_ss/venv/lib/python3.8/site-packages/flask/app.py", line 1474, in raise_routing_exception
    raise request.routing_exception  # type: ignore
  File "/home/new_user/Desktop/Flask_ss/venv/lib/python3.8/site-packages/flask/ctx.py", line 367, in match_request
    result = self.url_adapter.match(return_rule=True)  # type: ignore
  File "/home/new_user/Desktop/Flask_ss/venv/lib/python3.8/site-packages/werkzeug/routing.py", line 2032, in match
    raise NotFound()
werkzeug.exceptions.NotFound: 404 Not Found: The requested URL was not found on the server. If you entered the URL manually please check your spelling and try again.

During handling of the above exception, another exception occurred:

Traceback (most recent call last):
  File "/home/new_user/Desktop/Flask_ss/venv/lib/python3.8/site-packages/flask/app.py", line 2073, in wsgi_app
    response = self.full_dispatch_request()
  File "/home/new_user/Desktop/Flask_ss/venv/lib/python3.8/site-packages/flask/app.py", line 1518, in full_dispatch_request
    rv = self.handle_user_exception(e)
  File "/home/new_user/Desktop/Flask_ss/venv/lib/python3.8/site-packages/flask/app.py", line 1386, in handle_user_exception
    return self.handle_http_exception(e)
  File "/home/new_user/Desktop/Flask_ss/venv/lib/python3.8/site-packages/flask/app.py", line 1326, in handle_http_exception
    return self.ensure_sync(handler)(e)
TypeError: not_found_error() takes 0 positional arguments but 1 was given
2022-01-29 02:30:34,722 ERROR: Exception on /favicon.ico [GET] [int /home/new_user/Desktop/Flask_ss/venv/lib/python3.8/site-packages/flask/app.py:1457]
Traceback (most recent call last):
  File "/home/new_user/Desktop/Flask_ss/venv/lib/python3.8/site-packages/flask/app.py", line 1516, in full_dispatch_request
    rv = self.dispatch_request()
  File "/home/new_user/Desktop/Flask_ss/venv/lib/python3.8/site-packages/flask/app.py", line 1492, in dispatch_request
    self.raise_routing_exception(req)
  File "/home/new_user/Desktop/Flask_ss/venv/lib/python3.8/site-packages/flask/app.py", line 1474, in raise_routing_exception
    raise request.routing_exception  # type: ignore
  File "/home/new_user/Desktop/Flask_ss/venv/lib/python3.8/site-packages/flask/ctx.py", line 367, in match_request
    result = self.url_adapter.match(return_rule=True)  # type: ignore
  File "/home/new_user/Desktop/Flask_ss/venv/lib/python3.8/site-packages/werkzeug/routing.py", line 2032, in match
    raise NotFound()
werkzeug.exceptions.NotFound: 404 Not Found: The requested URL was not found on the server. If you entered the URL manually please check your spelling and try again.

During handling of the above exception, another exception occurred:

Traceback (most recent call last):
  File "/home/new_user/Desktop/Flask_ss/venv/lib/python3.8/site-packages/flask/app.py", line 2073, in wsgi_app
    response = self.full_dispatch_request()
  File "/home/new_user/Desktop/Flask_ss/venv/lib/python3.8/site-packages/flask/app.py", line 1518, in full_dispatch_request
    rv = self.handle_user_exception(e)
  File "/home/new_user/Desktop/Flask_ss/venv/lib/python3.8/site-packages/flask/app.py", line 1386, in handle_user_exception
    return self.handle_http_exception(e)
  File "/home/new_user/Desktop/Flask_ss/venv/lib/python3.8/site-packages/flask/app.py", line 1326, in handle_http_exception
    return self.ensure_sync(handler)(e)
TypeError: not_found_error() takes 0 positional arguments but 1 was given
2022-01-29 02:32:37,304 ERROR: Exception on /_styles.css [GET] [int /home/new_user/Desktop/Flask_ss/venv/lib/python3.8/site-packages/flask/app.py:1457]
Traceback (most recent call last):
  File "/home/new_user/Desktop/Flask_ss/venv/lib/python3.8/site-packages/flask/app.py", line 1516, in full_dispatch_request
    rv = self.dispatch_request()
  File "/home/new_user/Desktop/Flask_ss/venv/lib/python3.8/site-packages/flask/app.py", line 1492, in dispatch_request
    self.raise_routing_exception(req)
  File "/home/new_user/Desktop/Flask_ss/venv/lib/python3.8/site-packages/flask/app.py", line 1474, in raise_routing_exception
    raise request.routing_exception  # type: ignore
  File "/home/new_user/Desktop/Flask_ss/venv/lib/python3.8/site-packages/flask/ctx.py", line 367, in match_request
    result = self.url_adapter.match(return_rule=True)  # type: ignore
  File "/home/new_user/Desktop/Flask_ss/venv/lib/python3.8/site-packages/werkzeug/routing.py", line 2032, in match
    raise NotFound()
werkzeug.exceptions.NotFound: 404 Not Found: The requested URL was not found on the server. If you entered the URL manually please check your spelling and try again.

During handling of the above exception, another exception occurred:

Traceback (most recent call last):
  File "/home/new_user/Desktop/Flask_ss/venv/lib/python3.8/site-packages/flask/app.py", line 2073, in wsgi_app
    response = self.full_dispatch_request()
  File "/home/new_user/Desktop/Flask_ss/venv/lib/python3.8/site-packages/flask/app.py", line 1518, in full_dispatch_request
    rv = self.handle_user_exception(e)
  File "/home/new_user/Desktop/Flask_ss/venv/lib/python3.8/site-packages/flask/app.py", line 1386, in handle_user_exception
    return self.handle_http_exception(e)
  File "/home/new_user/Desktop/Flask_ss/venv/lib/python3.8/site-packages/flask/app.py", line 1326, in handle_http_exception
    return self.ensure_sync(handler)(e)
TypeError: not_found_error() takes 0 positional arguments but 1 was given
2022-01-29 02:32:37,691 ERROR: Exception on /favicon.ico [GET] [int /home/new_user/Desktop/Flask_ss/venv/lib/python3.8/site-packages/flask/app.py:1457]
Traceback (most recent call last):
  File "/home/new_user/Desktop/Flask_ss/venv/lib/python3.8/site-packages/flask/app.py", line 1516, in full_dispatch_request
    rv = self.dispatch_request()
  File "/home/new_user/Desktop/Flask_ss/venv/lib/python3.8/site-packages/flask/app.py", line 1492, in dispatch_request
    self.raise_routing_exception(req)
  File "/home/new_user/Desktop/Flask_ss/venv/lib/python3.8/site-packages/flask/app.py", line 1474, in raise_routing_exception
    raise request.routing_exception  # type: ignore
  File "/home/new_user/Desktop/Flask_ss/venv/lib/python3.8/site-packages/flask/ctx.py", line 367, in match_request
    result = self.url_adapter.match(return_rule=True)  # type: ignore
  File "/home/new_user/Desktop/Flask_ss/venv/lib/python3.8/site-packages/werkzeug/routing.py", line 2032, in match
    raise NotFound()
werkzeug.exceptions.NotFound: 404 Not Found: The requested URL was not found on the server. If you entered the URL manually please check your spelling and try again.

During handling of the above exception, another exception occurred:

Traceback (most recent call last):
  File "/home/new_user/Desktop/Flask_ss/venv/lib/python3.8/site-packages/flask/app.py", line 2073, in wsgi_app
    response = self.full_dispatch_request()
  File "/home/new_user/Desktop/Flask_ss/venv/lib/python3.8/site-packages/flask/app.py", line 1518, in full_dispatch_request
    rv = self.handle_user_exception(e)
  File "/home/new_user/Desktop/Flask_ss/venv/lib/python3.8/site-packages/flask/app.py", line 1386, in handle_user_exception
    return self.handle_http_exception(e)
  File "/home/new_user/Desktop/Flask_ss/venv/lib/python3.8/site-packages/flask/app.py", line 1326, in handle_http_exception
    return self.ensure_sync(handler)(e)
TypeError: not_found_error() takes 0 positional arguments but 1 was given
2022-01-29 02:32:42,111 ERROR: Exception on /_styles.css [GET] [int /home/new_user/Desktop/Flask_ss/venv/lib/python3.8/site-packages/flask/app.py:1457]
Traceback (most recent call last):
  File "/home/new_user/Desktop/Flask_ss/venv/lib/python3.8/site-packages/flask/app.py", line 1516, in full_dispatch_request
    rv = self.dispatch_request()
  File "/home/new_user/Desktop/Flask_ss/venv/lib/python3.8/site-packages/flask/app.py", line 1492, in dispatch_request
    self.raise_routing_exception(req)
  File "/home/new_user/Desktop/Flask_ss/venv/lib/python3.8/site-packages/flask/app.py", line 1474, in raise_routing_exception
    raise request.routing_exception  # type: ignore
  File "/home/new_user/Desktop/Flask_ss/venv/lib/python3.8/site-packages/flask/ctx.py", line 367, in match_request
    result = self.url_adapter.match(return_rule=True)  # type: ignore
  File "/home/new_user/Desktop/Flask_ss/venv/lib/python3.8/site-packages/werkzeug/routing.py", line 2032, in match
    raise NotFound()
werkzeug.exceptions.NotFound: 404 Not Found: The requested URL was not found on the server. If you entered the URL manually please check your spelling and try again.

During handling of the above exception, another exception occurred:

Traceback (most recent call last):
  File "/home/new_user/Desktop/Flask_ss/venv/lib/python3.8/site-packages/flask/app.py", line 2073, in wsgi_app
    response = self.full_dispatch_request()
  File "/home/new_user/Desktop/Flask_ss/venv/lib/python3.8/site-packages/flask/app.py", line 1518, in full_dispatch_request
    rv = self.handle_user_exception(e)
  File "/home/new_user/Desktop/Flask_ss/venv/lib/python3.8/site-packages/flask/app.py", line 1386, in handle_user_exception
    return self.handle_http_exception(e)
  File "/home/new_user/Desktop/Flask_ss/venv/lib/python3.8/site-packages/flask/app.py", line 1326, in handle_http_exception
    return self.ensure_sync(handler)(e)
TypeError: not_found_error() takes 0 positional arguments but 1 was given
2022-01-29 02:32:42,263 ERROR: Exception on /favicon.ico [GET] [int /home/new_user/Desktop/Flask_ss/venv/lib/python3.8/site-packages/flask/app.py:1457]
Traceback (most recent call last):
  File "/home/new_user/Desktop/Flask_ss/venv/lib/python3.8/site-packages/flask/app.py", line 1516, in full_dispatch_request
    rv = self.dispatch_request()
  File "/home/new_user/Desktop/Flask_ss/venv/lib/python3.8/site-packages/flask/app.py", line 1492, in dispatch_request
    self.raise_routing_exception(req)
  File "/home/new_user/Desktop/Flask_ss/venv/lib/python3.8/site-packages/flask/app.py", line 1474, in raise_routing_exception
    raise request.routing_exception  # type: ignore
  File "/home/new_user/Desktop/Flask_ss/venv/lib/python3.8/site-packages/flask/ctx.py", line 367, in match_request
    result = self.url_adapter.match(return_rule=True)  # type: ignore
  File "/home/new_user/Desktop/Flask_ss/venv/lib/python3.8/site-packages/werkzeug/routing.py", line 2032, in match
    raise NotFound()
werkzeug.exceptions.NotFound: 404 Not Found: The requested URL was not found on the server. If you entered the URL manually please check your spelling and try again.

During handling of the above exception, another exception occurred:

Traceback (most recent call last):
  File "/home/new_user/Desktop/Flask_ss/venv/lib/python3.8/site-packages/flask/app.py", line 2073, in wsgi_app
    response = self.full_dispatch_request()
  File "/home/new_user/Desktop/Flask_ss/venv/lib/python3.8/site-packages/flask/app.py", line 1518, in full_dispatch_request
    rv = self.handle_user_exception(e)
  File "/home/new_user/Desktop/Flask_ss/venv/lib/python3.8/site-packages/flask/app.py", line 1386, in handle_user_exception
    return self.handle_http_exception(e)
  File "/home/new_user/Desktop/Flask_ss/venv/lib/python3.8/site-packages/flask/app.py", line 1326, in handle_http_exception
    return self.ensure_sync(handler)(e)
TypeError: not_found_error() takes 0 positional arguments but 1 was given
2022-01-29 02:35:31,601 ERROR: Exception on /_styles.css [GET] [int /home/new_user/Desktop/Flask_ss/venv/lib/python3.8/site-packages/flask/app.py:1457]
Traceback (most recent call last):
  File "/home/new_user/Desktop/Flask_ss/venv/lib/python3.8/site-packages/flask/app.py", line 1516, in full_dispatch_request
    rv = self.dispatch_request()
  File "/home/new_user/Desktop/Flask_ss/venv/lib/python3.8/site-packages/flask/app.py", line 1492, in dispatch_request
    self.raise_routing_exception(req)
  File "/home/new_user/Desktop/Flask_ss/venv/lib/python3.8/site-packages/flask/app.py", line 1474, in raise_routing_exception
    raise request.routing_exception  # type: ignore
  File "/home/new_user/Desktop/Flask_ss/venv/lib/python3.8/site-packages/flask/ctx.py", line 367, in match_request
    result = self.url_adapter.match(return_rule=True)  # type: ignore
  File "/home/new_user/Desktop/Flask_ss/venv/lib/python3.8/site-packages/werkzeug/routing.py", line 2032, in match
    raise NotFound()
werkzeug.exceptions.NotFound: 404 Not Found: The requested URL was not found on the server. If you entered the URL manually please check your spelling and try again.

During handling of the above exception, another exception occurred:

Traceback (most recent call last):
  File "/home/new_user/Desktop/Flask_ss/venv/lib/python3.8/site-packages/flask/app.py", line 2073, in wsgi_app
    response = self.full_dispatch_request()
  File "/home/new_user/Desktop/Flask_ss/venv/lib/python3.8/site-packages/flask/app.py", line 1518, in full_dispatch_request
    rv = self.handle_user_exception(e)
  File "/home/new_user/Desktop/Flask_ss/venv/lib/python3.8/site-packages/flask/app.py", line 1386, in handle_user_exception
    return self.handle_http_exception(e)
  File "/home/new_user/Desktop/Flask_ss/venv/lib/python3.8/site-packages/flask/app.py", line 1326, in handle_http_exception
    return self.ensure_sync(handler)(e)
TypeError: not_found_error() takes 0 positional arguments but 1 was given
2022-01-29 02:35:31,849 ERROR: Exception on /favicon.ico [GET] [int /home/new_user/Desktop/Flask_ss/venv/lib/python3.8/site-packages/flask/app.py:1457]
Traceback (most recent call last):
  File "/home/new_user/Desktop/Flask_ss/venv/lib/python3.8/site-packages/flask/app.py", line 1516, in full_dispatch_request
    rv = self.dispatch_request()
  File "/home/new_user/Desktop/Flask_ss/venv/lib/python3.8/site-packages/flask/app.py", line 1492, in dispatch_request
    self.raise_routing_exception(req)
  File "/home/new_user/Desktop/Flask_ss/venv/lib/python3.8/site-packages/flask/app.py", line 1474, in raise_routing_exception
    raise request.routing_exception  # type: ignore
  File "/home/new_user/Desktop/Flask_ss/venv/lib/python3.8/site-packages/flask/ctx.py", line 367, in match_request
    result = self.url_adapter.match(return_rule=True)  # type: ignore
  File "/home/new_user/Desktop/Flask_ss/venv/lib/python3.8/site-packages/werkzeug/routing.py", line 2032, in match
    raise NotFound()
werkzeug.exceptions.NotFound: 404 Not Found: The requested URL was not found on the server. If you entered the URL manually please check your spelling and try again.

During handling of the above exception, another exception occurred:

Traceback (most recent call last):
  File "/home/new_user/Desktop/Flask_ss/venv/lib/python3.8/site-packages/flask/app.py", line 2073, in wsgi_app
    response = self.full_dispatch_request()
  File "/home/new_user/Desktop/Flask_ss/venv/lib/python3.8/site-packages/flask/app.py", line 1518, in full_dispatch_request
    rv = self.handle_user_exception(e)
  File "/home/new_user/Desktop/Flask_ss/venv/lib/python3.8/site-packages/flask/app.py", line 1386, in handle_user_exception
    return self.handle_http_exception(e)
  File "/home/new_user/Desktop/Flask_ss/venv/lib/python3.8/site-packages/flask/app.py", line 1326, in handle_http_exception
    return self.ensure_sync(handler)(e)
TypeError: not_found_error() takes 0 positional arguments but 1 was given
2022-01-29 02:50:37,581 INFO: Microbial startup [int /home/new_user/Desktop/Flask_ss/app/__init__.py:77]
2022-01-29 02:50:59,314 INFO: Microbial startup [int /home/new_user/Desktop/Flask_ss/app/__init__.py:77]
2022-01-29 03:07:47,412 ERROR: Exception on /_styles.css [GET] [int /home/new_user/Desktop/Flask_ss/venv/lib/python3.8/site-packages/flask/app.py:1457]
Traceback (most recent call last):
  File "/home/new_user/Desktop/Flask_ss/venv/lib/python3.8/site-packages/flask/app.py", line 1516, in full_dispatch_request
    rv = self.dispatch_request()
  File "/home/new_user/Desktop/Flask_ss/venv/lib/python3.8/site-packages/flask/app.py", line 1492, in dispatch_request
    self.raise_routing_exception(req)
  File "/home/new_user/Desktop/Flask_ss/venv/lib/python3.8/site-packages/flask/app.py", line 1474, in raise_routing_exception
    raise request.routing_exception  # type: ignore
  File "/home/new_user/Desktop/Flask_ss/venv/lib/python3.8/site-packages/flask/ctx.py", line 367, in match_request
    result = self.url_adapter.match(return_rule=True)  # type: ignore
  File "/home/new_user/Desktop/Flask_ss/venv/lib/python3.8/site-packages/werkzeug/routing.py", line 2032, in match
    raise NotFound()
werkzeug.exceptions.NotFound: 404 Not Found: The requested URL was not found on the server. If you entered the URL manually please check your spelling and try again.

During handling of the above exception, another exception occurred:

Traceback (most recent call last):
  File "/home/new_user/Desktop/Flask_ss/venv/lib/python3.8/site-packages/flask/app.py", line 2073, in wsgi_app
    response = self.full_dispatch_request()
  File "/home/new_user/Desktop/Flask_ss/venv/lib/python3.8/site-packages/flask/app.py", line 1518, in full_dispatch_request
    rv = self.handle_user_exception(e)
  File "/home/new_user/Desktop/Flask_ss/venv/lib/python3.8/site-packages/flask/app.py", line 1386, in handle_user_exception
    return self.handle_http_exception(e)
  File "/home/new_user/Desktop/Flask_ss/venv/lib/python3.8/site-packages/flask/app.py", line 1326, in handle_http_exception
    return self.ensure_sync(handler)(e)
TypeError: not_found_error() takes 0 positional arguments but 1 was given
2022-01-29 03:07:50,916 ERROR: Exception on /favicon.ico [GET] [int /home/new_user/Desktop/Flask_ss/venv/lib/python3.8/site-packages/flask/app.py:1457]
Traceback (most recent call last):
  File "/home/new_user/Desktop/Flask_ss/venv/lib/python3.8/site-packages/flask/app.py", line 1516, in full_dispatch_request
    rv = self.dispatch_request()
  File "/home/new_user/Desktop/Flask_ss/venv/lib/python3.8/site-packages/flask/app.py", line 1492, in dispatch_request
    self.raise_routing_exception(req)
  File "/home/new_user/Desktop/Flask_ss/venv/lib/python3.8/site-packages/flask/app.py", line 1474, in raise_routing_exception
    raise request.routing_exception  # type: ignore
  File "/home/new_user/Desktop/Flask_ss/venv/lib/python3.8/site-packages/flask/ctx.py", line 367, in match_request
    result = self.url_adapter.match(return_rule=True)  # type: ignore
  File "/home/new_user/Desktop/Flask_ss/venv/lib/python3.8/site-packages/werkzeug/routing.py", line 2032, in match
    raise NotFound()
werkzeug.exceptions.NotFound: 404 Not Found: The requested URL was not found on the server. If you entered the URL manually please check your spelling and try again.

During handling of the above exception, another exception occurred:

Traceback (most recent call last):
  File "/home/new_user/Desktop/Flask_ss/venv/lib/python3.8/site-packages/flask/app.py", line 2073, in wsgi_app
    response = self.full_dispatch_request()
  File "/home/new_user/Desktop/Flask_ss/venv/lib/python3.8/site-packages/flask/app.py", line 1518, in full_dispatch_request
    rv = self.handle_user_exception(e)
  File "/home/new_user/Desktop/Flask_ss/venv/lib/python3.8/site-packages/flask/app.py", line 1386, in handle_user_exception
    return self.handle_http_exception(e)
  File "/home/new_user/Desktop/Flask_ss/venv/lib/python3.8/site-packages/flask/app.py", line 1326, in handle_http_exception
    return self.ensure_sync(handler)(e)
TypeError: not_found_error() takes 0 positional arguments but 1 was given
2022-01-29 03:22:26,955 INFO: Microbial startup [int /home/new_user/Desktop/Flask_ss/app/__init__.py:77]
2022-01-29 03:22:47,712 INFO: Microbial startup [int /home/new_user/Desktop/Flask_ss/app/__init__.py:77]
2022-01-29 03:24:15,599 ERROR: Exception on /_styles.css [GET] [int /home/new_user/Desktop/Flask_ss/venv/lib/python3.8/site-packages/flask/app.py:1457]
Traceback (most recent call last):
  File "/home/new_user/Desktop/Flask_ss/venv/lib/python3.8/site-packages/flask/app.py", line 1516, in full_dispatch_request
    rv = self.dispatch_request()
  File "/home/new_user/Desktop/Flask_ss/venv/lib/python3.8/site-packages/flask/app.py", line 1492, in dispatch_request
    self.raise_routing_exception(req)
  File "/home/new_user/Desktop/Flask_ss/venv/lib/python3.8/site-packages/flask/app.py", line 1474, in raise_routing_exception
    raise request.routing_exception  # type: ignore
  File "/home/new_user/Desktop/Flask_ss/venv/lib/python3.8/site-packages/flask/ctx.py", line 367, in match_request
    result = self.url_adapter.match(return_rule=True)  # type: ignore
  File "/home/new_user/Desktop/Flask_ss/venv/lib/python3.8/site-packages/werkzeug/routing.py", line 2032, in match
    raise NotFound()
werkzeug.exceptions.NotFound: 404 Not Found: The requested URL was not found on the server. If you entered the URL manually please check your spelling and try again.

During handling of the above exception, another exception occurred:

Traceback (most recent call last):
  File "/home/new_user/Desktop/Flask_ss/venv/lib/python3.8/site-packages/flask/app.py", line 2073, in wsgi_app
    response = self.full_dispatch_request()
  File "/home/new_user/Desktop/Flask_ss/venv/lib/python3.8/site-packages/flask/app.py", line 1518, in full_dispatch_request
    rv = self.handle_user_exception(e)
  File "/home/new_user/Desktop/Flask_ss/venv/lib/python3.8/site-packages/flask/app.py", line 1386, in handle_user_exception
    return self.handle_http_exception(e)
  File "/home/new_user/Desktop/Flask_ss/venv/lib/python3.8/site-packages/flask/app.py", line 1326, in handle_http_exception
    return self.ensure_sync(handler)(e)
TypeError: not_found_error() takes 0 positional arguments but 1 was given
2022-01-29 03:24:16,400 ERROR: Exception on /favicon.ico [GET] [int /home/new_user/Desktop/Flask_ss/venv/lib/python3.8/site-packages/flask/app.py:1457]
Traceback (most recent call last):
  File "/home/new_user/Desktop/Flask_ss/venv/lib/python3.8/site-packages/flask/app.py", line 1516, in full_dispatch_request
    rv = self.dispatch_request()
  File "/home/new_user/Desktop/Flask_ss/venv/lib/python3.8/site-packages/flask/app.py", line 1492, in dispatch_request
    self.raise_routing_exception(req)
  File "/home/new_user/Desktop/Flask_ss/venv/lib/python3.8/site-packages/flask/app.py", line 1474, in raise_routing_exception
    raise request.routing_exception  # type: ignore
  File "/home/new_user/Desktop/Flask_ss/venv/lib/python3.8/site-packages/flask/ctx.py", line 367, in match_request
    result = self.url_adapter.match(return_rule=True)  # type: ignore
  File "/home/new_user/Desktop/Flask_ss/venv/lib/python3.8/site-packages/werkzeug/routing.py", line 2032, in match
    raise NotFound()
werkzeug.exceptions.NotFound: 404 Not Found: The requested URL was not found on the server. If you entered the URL manually please check your spelling and try again.

During handling of the above exception, another exception occurred:

Traceback (most recent call last):
  File "/home/new_user/Desktop/Flask_ss/venv/lib/python3.8/site-packages/flask/app.py", line 2073, in wsgi_app
    response = self.full_dispatch_request()
  File "/home/new_user/Desktop/Flask_ss/venv/lib/python3.8/site-packages/flask/app.py", line 1518, in full_dispatch_request
    rv = self.handle_user_exception(e)
  File "/home/new_user/Desktop/Flask_ss/venv/lib/python3.8/site-packages/flask/app.py", line 1386, in handle_user_exception
    return self.handle_http_exception(e)
  File "/home/new_user/Desktop/Flask_ss/venv/lib/python3.8/site-packages/flask/app.py", line 1326, in handle_http_exception
    return self.ensure_sync(handler)(e)
TypeError: not_found_error() takes 0 positional arguments but 1 was given
2022-01-29 03:26:12,155 ERROR: Exception on /_styles.css [GET] [int /home/new_user/Desktop/Flask_ss/venv/lib/python3.8/site-packages/flask/app.py:1457]
Traceback (most recent call last):
  File "/home/new_user/Desktop/Flask_ss/venv/lib/python3.8/site-packages/flask/app.py", line 1516, in full_dispatch_request
    rv = self.dispatch_request()
  File "/home/new_user/Desktop/Flask_ss/venv/lib/python3.8/site-packages/flask/app.py", line 1492, in dispatch_request
    self.raise_routing_exception(req)
  File "/home/new_user/Desktop/Flask_ss/venv/lib/python3.8/site-packages/flask/app.py", line 1474, in raise_routing_exception
    raise request.routing_exception  # type: ignore
  File "/home/new_user/Desktop/Flask_ss/venv/lib/python3.8/site-packages/flask/ctx.py", line 367, in match_request
    result = self.url_adapter.match(return_rule=True)  # type: ignore
  File "/home/new_user/Desktop/Flask_ss/venv/lib/python3.8/site-packages/werkzeug/routing.py", line 2032, in match
    raise NotFound()
werkzeug.exceptions.NotFound: 404 Not Found: The requested URL was not found on the server. If you entered the URL manually please check your spelling and try again.

During handling of the above exception, another exception occurred:

Traceback (most recent call last):
  File "/home/new_user/Desktop/Flask_ss/venv/lib/python3.8/site-packages/flask/app.py", line 2073, in wsgi_app
    response = self.full_dispatch_request()
  File "/home/new_user/Desktop/Flask_ss/venv/lib/python3.8/site-packages/flask/app.py", line 1518, in full_dispatch_request
    rv = self.handle_user_exception(e)
  File "/home/new_user/Desktop/Flask_ss/venv/lib/python3.8/site-packages/flask/app.py", line 1386, in handle_user_exception
    return self.handle_http_exception(e)
  File "/home/new_user/Desktop/Flask_ss/venv/lib/python3.8/site-packages/flask/app.py", line 1326, in handle_http_exception
    return self.ensure_sync(handler)(e)
TypeError: not_found_error() takes 0 positional arguments but 1 was given
2022-01-29 03:26:12,610 ERROR: Exception on /favicon.ico [GET] [int /home/new_user/Desktop/Flask_ss/venv/lib/python3.8/site-packages/flask/app.py:1457]
Traceback (most recent call last):
  File "/home/new_user/Desktop/Flask_ss/venv/lib/python3.8/site-packages/flask/app.py", line 1516, in full_dispatch_request
    rv = self.dispatch_request()
  File "/home/new_user/Desktop/Flask_ss/venv/lib/python3.8/site-packages/flask/app.py", line 1492, in dispatch_request
    self.raise_routing_exception(req)
  File "/home/new_user/Desktop/Flask_ss/venv/lib/python3.8/site-packages/flask/app.py", line 1474, in raise_routing_exception
    raise request.routing_exception  # type: ignore
  File "/home/new_user/Desktop/Flask_ss/venv/lib/python3.8/site-packages/flask/ctx.py", line 367, in match_request
    result = self.url_adapter.match(return_rule=True)  # type: ignore
  File "/home/new_user/Desktop/Flask_ss/venv/lib/python3.8/site-packages/werkzeug/routing.py", line 2032, in match
    raise NotFound()
werkzeug.exceptions.NotFound: 404 Not Found: The requested URL was not found on the server. If you entered the URL manually please check your spelling and try again.

During handling of the above exception, another exception occurred:

Traceback (most recent call last):
  File "/home/new_user/Desktop/Flask_ss/venv/lib/python3.8/site-packages/flask/app.py", line 2073, in wsgi_app
    response = self.full_dispatch_request()
  File "/home/new_user/Desktop/Flask_ss/venv/lib/python3.8/site-packages/flask/app.py", line 1518, in full_dispatch_request
    rv = self.handle_user_exception(e)
  File "/home/new_user/Desktop/Flask_ss/venv/lib/python3.8/site-packages/flask/app.py", line 1386, in handle_user_exception
    return self.handle_http_exception(e)
  File "/home/new_user/Desktop/Flask_ss/venv/lib/python3.8/site-packages/flask/app.py", line 1326, in handle_http_exception
    return self.ensure_sync(handler)(e)
TypeError: not_found_error() takes 0 positional arguments but 1 was given
2022-01-29 03:26:14,652 ERROR: Exception on /_styles.css [GET] [int /home/new_user/Desktop/Flask_ss/venv/lib/python3.8/site-packages/flask/app.py:1457]
Traceback (most recent call last):
  File "/home/new_user/Desktop/Flask_ss/venv/lib/python3.8/site-packages/flask/app.py", line 1516, in full_dispatch_request
    rv = self.dispatch_request()
  File "/home/new_user/Desktop/Flask_ss/venv/lib/python3.8/site-packages/flask/app.py", line 1492, in dispatch_request
    self.raise_routing_exception(req)
  File "/home/new_user/Desktop/Flask_ss/venv/lib/python3.8/site-packages/flask/app.py", line 1474, in raise_routing_exception
    raise request.routing_exception  # type: ignore
  File "/home/new_user/Desktop/Flask_ss/venv/lib/python3.8/site-packages/flask/ctx.py", line 367, in match_request
    result = self.url_adapter.match(return_rule=True)  # type: ignore
  File "/home/new_user/Desktop/Flask_ss/venv/lib/python3.8/site-packages/werkzeug/routing.py", line 2032, in match
    raise NotFound()
werkzeug.exceptions.NotFound: 404 Not Found: The requested URL was not found on the server. If you entered the URL manually please check your spelling and try again.

During handling of the above exception, another exception occurred:

Traceback (most recent call last):
  File "/home/new_user/Desktop/Flask_ss/venv/lib/python3.8/site-packages/flask/app.py", line 2073, in wsgi_app
    response = self.full_dispatch_request()
  File "/home/new_user/Desktop/Flask_ss/venv/lib/python3.8/site-packages/flask/app.py", line 1518, in full_dispatch_request
    rv = self.handle_user_exception(e)
  File "/home/new_user/Desktop/Flask_ss/venv/lib/python3.8/site-packages/flask/app.py", line 1386, in handle_user_exception
    return self.handle_http_exception(e)
  File "/home/new_user/Desktop/Flask_ss/venv/lib/python3.8/site-packages/flask/app.py", line 1326, in handle_http_exception
    return self.ensure_sync(handler)(e)
TypeError: not_found_error() takes 0 positional arguments but 1 was given
2022-01-29 03:26:14,963 ERROR: Exception on /favicon.ico [GET] [int /home/new_user/Desktop/Flask_ss/venv/lib/python3.8/site-packages/flask/app.py:1457]
Traceback (most recent call last):
  File "/home/new_user/Desktop/Flask_ss/venv/lib/python3.8/site-packages/flask/app.py", line 1516, in full_dispatch_request
    rv = self.dispatch_request()
  File "/home/new_user/Desktop/Flask_ss/venv/lib/python3.8/site-packages/flask/app.py", line 1492, in dispatch_request
    self.raise_routing_exception(req)
  File "/home/new_user/Desktop/Flask_ss/venv/lib/python3.8/site-packages/flask/app.py", line 1474, in raise_routing_exception
    raise request.routing_exception  # type: ignore
  File "/home/new_user/Desktop/Flask_ss/venv/lib/python3.8/site-packages/flask/ctx.py", line 367, in match_request
    result = self.url_adapter.match(return_rule=True)  # type: ignore
  File "/home/new_user/Desktop/Flask_ss/venv/lib/python3.8/site-packages/werkzeug/routing.py", line 2032, in match
    raise NotFound()
werkzeug.exceptions.NotFound: 404 Not Found: The requested URL was not found on the server. If you entered the URL manually please check your spelling and try again.

During handling of the above exception, another exception occurred:

Traceback (most recent call last):
  File "/home/new_user/Desktop/Flask_ss/venv/lib/python3.8/site-packages/flask/app.py", line 2073, in wsgi_app
    response = self.full_dispatch_request()
  File "/home/new_user/Desktop/Flask_ss/venv/lib/python3.8/site-packages/flask/app.py", line 1518, in full_dispatch_request
    rv = self.handle_user_exception(e)
  File "/home/new_user/Desktop/Flask_ss/venv/lib/python3.8/site-packages/flask/app.py", line 1386, in handle_user_exception
    return self.handle_http_exception(e)
  File "/home/new_user/Desktop/Flask_ss/venv/lib/python3.8/site-packages/flask/app.py", line 1326, in handle_http_exception
    return self.ensure_sync(handler)(e)
TypeError: not_found_error() takes 0 positional arguments but 1 was given
2022-01-29 03:26:28,486 ERROR: Exception on /_styles.css [GET] [int /home/new_user/Desktop/Flask_ss/venv/lib/python3.8/site-packages/flask/app.py:1457]
Traceback (most recent call last):
  File "/home/new_user/Desktop/Flask_ss/venv/lib/python3.8/site-packages/flask/app.py", line 1516, in full_dispatch_request
    rv = self.dispatch_request()
  File "/home/new_user/Desktop/Flask_ss/venv/lib/python3.8/site-packages/flask/app.py", line 1492, in dispatch_request
    self.raise_routing_exception(req)
  File "/home/new_user/Desktop/Flask_ss/venv/lib/python3.8/site-packages/flask/app.py", line 1474, in raise_routing_exception
    raise request.routing_exception  # type: ignore
  File "/home/new_user/Desktop/Flask_ss/venv/lib/python3.8/site-packages/flask/ctx.py", line 367, in match_request
    result = self.url_adapter.match(return_rule=True)  # type: ignore
  File "/home/new_user/Desktop/Flask_ss/venv/lib/python3.8/site-packages/werkzeug/routing.py", line 2032, in match
    raise NotFound()
werkzeug.exceptions.NotFound: 404 Not Found: The requested URL was not found on the server. If you entered the URL manually please check your spelling and try again.

During handling of the above exception, another exception occurred:

Traceback (most recent call last):
  File "/home/new_user/Desktop/Flask_ss/venv/lib/python3.8/site-packages/flask/app.py", line 2073, in wsgi_app
    response = self.full_dispatch_request()
  File "/home/new_user/Desktop/Flask_ss/venv/lib/python3.8/site-packages/flask/app.py", line 1518, in full_dispatch_request
    rv = self.handle_user_exception(e)
  File "/home/new_user/Desktop/Flask_ss/venv/lib/python3.8/site-packages/flask/app.py", line 1386, in handle_user_exception
    return self.handle_http_exception(e)
  File "/home/new_user/Desktop/Flask_ss/venv/lib/python3.8/site-packages/flask/app.py", line 1326, in handle_http_exception
    return self.ensure_sync(handler)(e)
TypeError: not_found_error() takes 0 positional arguments but 1 was given
2022-01-29 03:26:28,729 ERROR: Exception on /favicon.ico [GET] [int /home/new_user/Desktop/Flask_ss/venv/lib/python3.8/site-packages/flask/app.py:1457]
Traceback (most recent call last):
  File "/home/new_user/Desktop/Flask_ss/venv/lib/python3.8/site-packages/flask/app.py", line 1516, in full_dispatch_request
    rv = self.dispatch_request()
  File "/home/new_user/Desktop/Flask_ss/venv/lib/python3.8/site-packages/flask/app.py", line 1492, in dispatch_request
    self.raise_routing_exception(req)
  File "/home/new_user/Desktop/Flask_ss/venv/lib/python3.8/site-packages/flask/app.py", line 1474, in raise_routing_exception
    raise request.routing_exception  # type: ignore
  File "/home/new_user/Desktop/Flask_ss/venv/lib/python3.8/site-packages/flask/ctx.py", line 367, in match_request
    result = self.url_adapter.match(return_rule=True)  # type: ignore
  File "/home/new_user/Desktop/Flask_ss/venv/lib/python3.8/site-packages/werkzeug/routing.py", line 2032, in match
    raise NotFound()
werkzeug.exceptions.NotFound: 404 Not Found: The requested URL was not found on the server. If you entered the URL manually please check your spelling and try again.

During handling of the above exception, another exception occurred:

Traceback (most recent call last):
  File "/home/new_user/Desktop/Flask_ss/venv/lib/python3.8/site-packages/flask/app.py", line 2073, in wsgi_app
    response = self.full_dispatch_request()
  File "/home/new_user/Desktop/Flask_ss/venv/lib/python3.8/site-packages/flask/app.py", line 1518, in full_dispatch_request
    rv = self.handle_user_exception(e)
  File "/home/new_user/Desktop/Flask_ss/venv/lib/python3.8/site-packages/flask/app.py", line 1386, in handle_user_exception
    return self.handle_http_exception(e)
  File "/home/new_user/Desktop/Flask_ss/venv/lib/python3.8/site-packages/flask/app.py", line 1326, in handle_http_exception
    return self.ensure_sync(handler)(e)
TypeError: not_found_error() takes 0 positional arguments but 1 was given
2022-01-29 03:28:38,999 INFO: Microbial startup [int /home/new_user/Desktop/Flask_ss/app/__init__.py:77]
2022-01-29 03:28:54,191 INFO: Microbial startup [int /home/new_user/Desktop/Flask_ss/app/__init__.py:77]
2022-01-29 03:29:10,694 ERROR: Exception on /_styles.css [GET] [int /home/new_user/Desktop/Flask_ss/venv/lib/python3.8/site-packages/flask/app.py:1457]
Traceback (most recent call last):
  File "/home/new_user/Desktop/Flask_ss/venv/lib/python3.8/site-packages/flask/app.py", line 1516, in full_dispatch_request
    rv = self.dispatch_request()
  File "/home/new_user/Desktop/Flask_ss/venv/lib/python3.8/site-packages/flask/app.py", line 1492, in dispatch_request
    self.raise_routing_exception(req)
  File "/home/new_user/Desktop/Flask_ss/venv/lib/python3.8/site-packages/flask/app.py", line 1474, in raise_routing_exception
    raise request.routing_exception  # type: ignore
  File "/home/new_user/Desktop/Flask_ss/venv/lib/python3.8/site-packages/flask/ctx.py", line 367, in match_request
    result = self.url_adapter.match(return_rule=True)  # type: ignore
  File "/home/new_user/Desktop/Flask_ss/venv/lib/python3.8/site-packages/werkzeug/routing.py", line 2032, in match
    raise NotFound()
werkzeug.exceptions.NotFound: 404 Not Found: The requested URL was not found on the server. If you entered the URL manually please check your spelling and try again.

During handling of the above exception, another exception occurred:

Traceback (most recent call last):
  File "/home/new_user/Desktop/Flask_ss/venv/lib/python3.8/site-packages/flask/app.py", line 2073, in wsgi_app
    response = self.full_dispatch_request()
  File "/home/new_user/Desktop/Flask_ss/venv/lib/python3.8/site-packages/flask/app.py", line 1518, in full_dispatch_request
    rv = self.handle_user_exception(e)
  File "/home/new_user/Desktop/Flask_ss/venv/lib/python3.8/site-packages/flask/app.py", line 1386, in handle_user_exception
    return self.handle_http_exception(e)
  File "/home/new_user/Desktop/Flask_ss/venv/lib/python3.8/site-packages/flask/app.py", line 1326, in handle_http_exception
    return self.ensure_sync(handler)(e)
TypeError: not_found_error() takes 0 positional arguments but 1 was given
2022-01-29 03:29:11,633 ERROR: Exception on /favicon.ico [GET] [int /home/new_user/Desktop/Flask_ss/venv/lib/python3.8/site-packages/flask/app.py:1457]
Traceback (most recent call last):
  File "/home/new_user/Desktop/Flask_ss/venv/lib/python3.8/site-packages/flask/app.py", line 1516, in full_dispatch_request
    rv = self.dispatch_request()
  File "/home/new_user/Desktop/Flask_ss/venv/lib/python3.8/site-packages/flask/app.py", line 1492, in dispatch_request
    self.raise_routing_exception(req)
  File "/home/new_user/Desktop/Flask_ss/venv/lib/python3.8/site-packages/flask/app.py", line 1474, in raise_routing_exception
    raise request.routing_exception  # type: ignore
  File "/home/new_user/Desktop/Flask_ss/venv/lib/python3.8/site-packages/flask/ctx.py", line 367, in match_request
    result = self.url_adapter.match(return_rule=True)  # type: ignore
  File "/home/new_user/Desktop/Flask_ss/venv/lib/python3.8/site-packages/werkzeug/routing.py", line 2032, in match
    raise NotFound()
werkzeug.exceptions.NotFound: 404 Not Found: The requested URL was not found on the server. If you entered the URL manually please check your spelling and try again.

During handling of the above exception, another exception occurred:

Traceback (most recent call last):
  File "/home/new_user/Desktop/Flask_ss/venv/lib/python3.8/site-packages/flask/app.py", line 2073, in wsgi_app
    response = self.full_dispatch_request()
  File "/home/new_user/Desktop/Flask_ss/venv/lib/python3.8/site-packages/flask/app.py", line 1518, in full_dispatch_request
    rv = self.handle_user_exception(e)
  File "/home/new_user/Desktop/Flask_ss/venv/lib/python3.8/site-packages/flask/app.py", line 1386, in handle_user_exception
    return self.handle_http_exception(e)
  File "/home/new_user/Desktop/Flask_ss/venv/lib/python3.8/site-packages/flask/app.py", line 1326, in handle_http_exception
    return self.ensure_sync(handler)(e)
TypeError: not_found_error() takes 0 positional arguments but 1 was given
2022-01-29 03:31:15,369 INFO: Microbial startup [int /home/new_user/Desktop/Flask_ss/app/__init__.py:77]
2022-01-29 03:31:29,066 INFO: Microbial startup [int /home/new_user/Desktop/Flask_ss/app/__init__.py:77]
2022-01-29 03:31:48,290 ERROR: Exception on /_styles.css [GET] [int /home/new_user/Desktop/Flask_ss/venv/lib/python3.8/site-packages/flask/app.py:1457]
Traceback (most recent call last):
  File "/home/new_user/Desktop/Flask_ss/venv/lib/python3.8/site-packages/flask/app.py", line 1516, in full_dispatch_request
    rv = self.dispatch_request()
  File "/home/new_user/Desktop/Flask_ss/venv/lib/python3.8/site-packages/flask/app.py", line 1492, in dispatch_request
    self.raise_routing_exception(req)
  File "/home/new_user/Desktop/Flask_ss/venv/lib/python3.8/site-packages/flask/app.py", line 1474, in raise_routing_exception
    raise request.routing_exception  # type: ignore
  File "/home/new_user/Desktop/Flask_ss/venv/lib/python3.8/site-packages/flask/ctx.py", line 367, in match_request
    result = self.url_adapter.match(return_rule=True)  # type: ignore
  File "/home/new_user/Desktop/Flask_ss/venv/lib/python3.8/site-packages/werkzeug/routing.py", line 2032, in match
    raise NotFound()
werkzeug.exceptions.NotFound: 404 Not Found: The requested URL was not found on the server. If you entered the URL manually please check your spelling and try again.

During handling of the above exception, another exception occurred:

Traceback (most recent call last):
  File "/home/new_user/Desktop/Flask_ss/venv/lib/python3.8/site-packages/flask/app.py", line 2073, in wsgi_app
    response = self.full_dispatch_request()
  File "/home/new_user/Desktop/Flask_ss/venv/lib/python3.8/site-packages/flask/app.py", line 1518, in full_dispatch_request
    rv = self.handle_user_exception(e)
  File "/home/new_user/Desktop/Flask_ss/venv/lib/python3.8/site-packages/flask/app.py", line 1386, in handle_user_exception
    return self.handle_http_exception(e)
  File "/home/new_user/Desktop/Flask_ss/venv/lib/python3.8/site-packages/flask/app.py", line 1326, in handle_http_exception
    return self.ensure_sync(handler)(e)
TypeError: not_found_error() takes 0 positional arguments but 1 was given
2022-01-29 03:31:49,109 ERROR: Exception on /favicon.ico [GET] [int /home/new_user/Desktop/Flask_ss/venv/lib/python3.8/site-packages/flask/app.py:1457]
Traceback (most recent call last):
  File "/home/new_user/Desktop/Flask_ss/venv/lib/python3.8/site-packages/flask/app.py", line 1516, in full_dispatch_request
    rv = self.dispatch_request()
  File "/home/new_user/Desktop/Flask_ss/venv/lib/python3.8/site-packages/flask/app.py", line 1492, in dispatch_request
    self.raise_routing_exception(req)
  File "/home/new_user/Desktop/Flask_ss/venv/lib/python3.8/site-packages/flask/app.py", line 1474, in raise_routing_exception
    raise request.routing_exception  # type: ignore
  File "/home/new_user/Desktop/Flask_ss/venv/lib/python3.8/site-packages/flask/ctx.py", line 367, in match_request
    result = self.url_adapter.match(return_rule=True)  # type: ignore
  File "/home/new_user/Desktop/Flask_ss/venv/lib/python3.8/site-packages/werkzeug/routing.py", line 2032, in match
    raise NotFound()
werkzeug.exceptions.NotFound: 404 Not Found: The requested URL was not found on the server. If you entered the URL manually please check your spelling and try again.

During handling of the above exception, another exception occurred:

Traceback (most recent call last):
  File "/home/new_user/Desktop/Flask_ss/venv/lib/python3.8/site-packages/flask/app.py", line 2073, in wsgi_app
    response = self.full_dispatch_request()
  File "/home/new_user/Desktop/Flask_ss/venv/lib/python3.8/site-packages/flask/app.py", line 1518, in full_dispatch_request
    rv = self.handle_user_exception(e)
  File "/home/new_user/Desktop/Flask_ss/venv/lib/python3.8/site-packages/flask/app.py", line 1386, in handle_user_exception
    return self.handle_http_exception(e)
  File "/home/new_user/Desktop/Flask_ss/venv/lib/python3.8/site-packages/flask/app.py", line 1326, in handle_http_exception
    return self.ensure_sync(handler)(e)
TypeError: not_found_error() takes 0 positional arguments but 1 was given
2022-01-29 03:31:56,204 ERROR: Exception on /_styles.css [GET] [int /home/new_user/Desktop/Flask_ss/venv/lib/python3.8/site-packages/flask/app.py:1457]
Traceback (most recent call last):
  File "/home/new_user/Desktop/Flask_ss/venv/lib/python3.8/site-packages/flask/app.py", line 1516, in full_dispatch_request
    rv = self.dispatch_request()
  File "/home/new_user/Desktop/Flask_ss/venv/lib/python3.8/site-packages/flask/app.py", line 1492, in dispatch_request
    self.raise_routing_exception(req)
  File "/home/new_user/Desktop/Flask_ss/venv/lib/python3.8/site-packages/flask/app.py", line 1474, in raise_routing_exception
    raise request.routing_exception  # type: ignore
  File "/home/new_user/Desktop/Flask_ss/venv/lib/python3.8/site-packages/flask/ctx.py", line 367, in match_request
    result = self.url_adapter.match(return_rule=True)  # type: ignore
  File "/home/new_user/Desktop/Flask_ss/venv/lib/python3.8/site-packages/werkzeug/routing.py", line 2032, in match
    raise NotFound()
werkzeug.exceptions.NotFound: 404 Not Found: The requested URL was not found on the server. If you entered the URL manually please check your spelling and try again.

During handling of the above exception, another exception occurred:

Traceback (most recent call last):
  File "/home/new_user/Desktop/Flask_ss/venv/lib/python3.8/site-packages/flask/app.py", line 2073, in wsgi_app
    response = self.full_dispatch_request()
  File "/home/new_user/Desktop/Flask_ss/venv/lib/python3.8/site-packages/flask/app.py", line 1518, in full_dispatch_request
    rv = self.handle_user_exception(e)
  File "/home/new_user/Desktop/Flask_ss/venv/lib/python3.8/site-packages/flask/app.py", line 1386, in handle_user_exception
    return self.handle_http_exception(e)
  File "/home/new_user/Desktop/Flask_ss/venv/lib/python3.8/site-packages/flask/app.py", line 1326, in handle_http_exception
    return self.ensure_sync(handler)(e)
TypeError: not_found_error() takes 0 positional arguments but 1 was given
2022-01-29 03:31:56,423 ERROR: Exception on /favicon.ico [GET] [int /home/new_user/Desktop/Flask_ss/venv/lib/python3.8/site-packages/flask/app.py:1457]
Traceback (most recent call last):
  File "/home/new_user/Desktop/Flask_ss/venv/lib/python3.8/site-packages/flask/app.py", line 1516, in full_dispatch_request
    rv = self.dispatch_request()
  File "/home/new_user/Desktop/Flask_ss/venv/lib/python3.8/site-packages/flask/app.py", line 1492, in dispatch_request
    self.raise_routing_exception(req)
  File "/home/new_user/Desktop/Flask_ss/venv/lib/python3.8/site-packages/flask/app.py", line 1474, in raise_routing_exception
    raise request.routing_exception  # type: ignore
  File "/home/new_user/Desktop/Flask_ss/venv/lib/python3.8/site-packages/flask/ctx.py", line 367, in match_request
    result = self.url_adapter.match(return_rule=True)  # type: ignore
  File "/home/new_user/Desktop/Flask_ss/venv/lib/python3.8/site-packages/werkzeug/routing.py", line 2032, in match
    raise NotFound()
werkzeug.exceptions.NotFound: 404 Not Found: The requested URL was not found on the server. If you entered the URL manually please check your spelling and try again.

During handling of the above exception, another exception occurred:

Traceback (most recent call last):
  File "/home/new_user/Desktop/Flask_ss/venv/lib/python3.8/site-packages/flask/app.py", line 2073, in wsgi_app
    response = self.full_dispatch_request()
  File "/home/new_user/Desktop/Flask_ss/venv/lib/python3.8/site-packages/flask/app.py", line 1518, in full_dispatch_request
    rv = self.handle_user_exception(e)
  File "/home/new_user/Desktop/Flask_ss/venv/lib/python3.8/site-packages/flask/app.py", line 1386, in handle_user_exception
    return self.handle_http_exception(e)
  File "/home/new_user/Desktop/Flask_ss/venv/lib/python3.8/site-packages/flask/app.py", line 1326, in handle_http_exception
    return self.ensure_sync(handler)(e)
TypeError: not_found_error() takes 0 positional arguments but 1 was given
2022-01-29 03:32:41,598 ERROR: Exception on /_styles.css [GET] [int /home/new_user/Desktop/Flask_ss/venv/lib/python3.8/site-packages/flask/app.py:1457]
Traceback (most recent call last):
  File "/home/new_user/Desktop/Flask_ss/venv/lib/python3.8/site-packages/flask/app.py", line 1516, in full_dispatch_request
    rv = self.dispatch_request()
  File "/home/new_user/Desktop/Flask_ss/venv/lib/python3.8/site-packages/flask/app.py", line 1492, in dispatch_request
    self.raise_routing_exception(req)
  File "/home/new_user/Desktop/Flask_ss/venv/lib/python3.8/site-packages/flask/app.py", line 1474, in raise_routing_exception
    raise request.routing_exception  # type: ignore
  File "/home/new_user/Desktop/Flask_ss/venv/lib/python3.8/site-packages/flask/ctx.py", line 367, in match_request
    result = self.url_adapter.match(return_rule=True)  # type: ignore
  File "/home/new_user/Desktop/Flask_ss/venv/lib/python3.8/site-packages/werkzeug/routing.py", line 2032, in match
    raise NotFound()
werkzeug.exceptions.NotFound: 404 Not Found: The requested URL was not found on the server. If you entered the URL manually please check your spelling and try again.

During handling of the above exception, another exception occurred:

Traceback (most recent call last):
  File "/home/new_user/Desktop/Flask_ss/venv/lib/python3.8/site-packages/flask/app.py", line 2073, in wsgi_app
    response = self.full_dispatch_request()
  File "/home/new_user/Desktop/Flask_ss/venv/lib/python3.8/site-packages/flask/app.py", line 1518, in full_dispatch_request
    rv = self.handle_user_exception(e)
  File "/home/new_user/Desktop/Flask_ss/venv/lib/python3.8/site-packages/flask/app.py", line 1386, in handle_user_exception
    return self.handle_http_exception(e)
  File "/home/new_user/Desktop/Flask_ss/venv/lib/python3.8/site-packages/flask/app.py", line 1326, in handle_http_exception
    return self.ensure_sync(handler)(e)
TypeError: not_found_error() takes 0 positional arguments but 1 was given
2022-01-29 03:32:41,730 ERROR: Exception on /favicon.ico [GET] [int /home/new_user/Desktop/Flask_ss/venv/lib/python3.8/site-packages/flask/app.py:1457]
Traceback (most recent call last):
  File "/home/new_user/Desktop/Flask_ss/venv/lib/python3.8/site-packages/flask/app.py", line 1516, in full_dispatch_request
    rv = self.dispatch_request()
  File "/home/new_user/Desktop/Flask_ss/venv/lib/python3.8/site-packages/flask/app.py", line 1492, in dispatch_request
    self.raise_routing_exception(req)
  File "/home/new_user/Desktop/Flask_ss/venv/lib/python3.8/site-packages/flask/app.py", line 1474, in raise_routing_exception
    raise request.routing_exception  # type: ignore
  File "/home/new_user/Desktop/Flask_ss/venv/lib/python3.8/site-packages/flask/ctx.py", line 367, in match_request
    result = self.url_adapter.match(return_rule=True)  # type: ignore
  File "/home/new_user/Desktop/Flask_ss/venv/lib/python3.8/site-packages/werkzeug/routing.py", line 2032, in match
    raise NotFound()
werkzeug.exceptions.NotFound: 404 Not Found: The requested URL was not found on the server. If you entered the URL manually please check your spelling and try again.

During handling of the above exception, another exception occurred:

Traceback (most recent call last):
  File "/home/new_user/Desktop/Flask_ss/venv/lib/python3.8/site-packages/flask/app.py", line 2073, in wsgi_app
    response = self.full_dispatch_request()
  File "/home/new_user/Desktop/Flask_ss/venv/lib/python3.8/site-packages/flask/app.py", line 1518, in full_dispatch_request
    rv = self.handle_user_exception(e)
  File "/home/new_user/Desktop/Flask_ss/venv/lib/python3.8/site-packages/flask/app.py", line 1386, in handle_user_exception
    return self.handle_http_exception(e)
  File "/home/new_user/Desktop/Flask_ss/venv/lib/python3.8/site-packages/flask/app.py", line 1326, in handle_http_exception
    return self.ensure_sync(handler)(e)
TypeError: not_found_error() takes 0 positional arguments but 1 was given
