2021-11-30 00:26:12,447 ERROR: Exception on /_styles.css [GET] [int /home/new_user/Desktop/Flask_ss/venv/lib/python3.8/site-packages/flask/app.py:1457]
Traceback (most recent call last):
  File "/home/new_user/Desktop/Flask_ss/venv/lib/python3.8/site-packages/flask/app.py", line 1516, in full_dispatch_request
    rv = self.dispatch_request()
  File "/home/new_user/Desktop/Flask_ss/venv/lib/python3.8/site-packages/flask/app.py", line 1492, in dispatch_request
    self.raise_routing_exception(req)
  File "/home/new_user/Desktop/Flask_ss/venv/lib/python3.8/site-packages/flask/app.py", line 1474, in raise_routing_exception
    raise request.routing_exception  # type: ignore
  File "/home/new_user/Desktop/Flask_ss/venv/lib/python3.8/site-packages/flask/ctx.py", line 367, in match_request
    result = self.url_adapter.match(return_rule=True)  # type: ignore
  File "/home/new_user/Desktop/Flask_ss/venv/lib/python3.8/site-packages/werkzeug/routing.py", line 2032, in match
    raise NotFound()
werkzeug.exceptions.NotFound: 404 Not Found: The requested URL was not found on the server. If you entered the URL manually please check your spelling and try again.

During handling of the above exception, another exception occurred:

Traceback (most recent call last):
  File "/home/new_user/Desktop/Flask_ss/venv/lib/python3.8/site-packages/flask/app.py", line 2073, in wsgi_app
    response = self.full_dispatch_request()
  File "/home/new_user/Desktop/Flask_ss/venv/lib/python3.8/site-packages/flask/app.py", line 1518, in full_dispatch_request
    rv = self.handle_user_exception(e)
  File "/home/new_user/Desktop/Flask_ss/venv/lib/python3.8/site-packages/flask/app.py", line 1386, in handle_user_exception
    return self.handle_http_exception(e)
  File "/home/new_user/Desktop/Flask_ss/venv/lib/python3.8/site-packages/flask/app.py", line 1326, in handle_http_exception
    return self.ensure_sync(handler)(e)
TypeError: not_found_error() takes 0 positional arguments but 1 was given
2021-11-30 00:26:12,499 ERROR: Exception on /favicon.ico [GET] [int /home/new_user/Desktop/Flask_ss/venv/lib/python3.8/site-packages/flask/app.py:1457]
Traceback (most recent call last):
  File "/home/new_user/Desktop/Flask_ss/venv/lib/python3.8/site-packages/flask/app.py", line 1516, in full_dispatch_request
    rv = self.dispatch_request()
  File "/home/new_user/Desktop/Flask_ss/venv/lib/python3.8/site-packages/flask/app.py", line 1492, in dispatch_request
    self.raise_routing_exception(req)
  File "/home/new_user/Desktop/Flask_ss/venv/lib/python3.8/site-packages/flask/app.py", line 1474, in raise_routing_exception
    raise request.routing_exception  # type: ignore
  File "/home/new_user/Desktop/Flask_ss/venv/lib/python3.8/site-packages/flask/ctx.py", line 367, in match_request
    result = self.url_adapter.match(return_rule=True)  # type: ignore
  File "/home/new_user/Desktop/Flask_ss/venv/lib/python3.8/site-packages/werkzeug/routing.py", line 2032, in match
    raise NotFound()
werkzeug.exceptions.NotFound: 404 Not Found: The requested URL was not found on the server. If you entered the URL manually please check your spelling and try again.

During handling of the above exception, another exception occurred:

Traceback (most recent call last):
  File "/home/new_user/Desktop/Flask_ss/venv/lib/python3.8/site-packages/flask/app.py", line 2073, in wsgi_app
    response = self.full_dispatch_request()
  File "/home/new_user/Desktop/Flask_ss/venv/lib/python3.8/site-packages/flask/app.py", line 1518, in full_dispatch_request
    rv = self.handle_user_exception(e)
  File "/home/new_user/Desktop/Flask_ss/venv/lib/python3.8/site-packages/flask/app.py", line 1386, in handle_user_exception
    return self.handle_http_exception(e)
  File "/home/new_user/Desktop/Flask_ss/venv/lib/python3.8/site-packages/flask/app.py", line 1326, in handle_http_exception
    return self.ensure_sync(handler)(e)
TypeError: not_found_error() takes 0 positional arguments but 1 was given
2021-11-30 00:27:23,494 INFO: Microbial startup [int /home/new_user/Desktop/Flask_ss/app/__init__.py:77]
2021-11-30 00:27:27,837 INFO: Microbial startup [int /home/new_user/Desktop/Flask_ss/app/__init__.py:77]
2021-11-30 00:27:35,461 ERROR: Exception on /_styles.css [GET] [int /home/new_user/Desktop/Flask_ss/venv/lib/python3.8/site-packages/flask/app.py:1457]
Traceback (most recent call last):
  File "/home/new_user/Desktop/Flask_ss/venv/lib/python3.8/site-packages/flask/app.py", line 1516, in full_dispatch_request
    rv = self.dispatch_request()
  File "/home/new_user/Desktop/Flask_ss/venv/lib/python3.8/site-packages/flask/app.py", line 1492, in dispatch_request
    self.raise_routing_exception(req)
  File "/home/new_user/Desktop/Flask_ss/venv/lib/python3.8/site-packages/flask/app.py", line 1474, in raise_routing_exception
    raise request.routing_exception  # type: ignore
  File "/home/new_user/Desktop/Flask_ss/venv/lib/python3.8/site-packages/flask/ctx.py", line 367, in match_request
    result = self.url_adapter.match(return_rule=True)  # type: ignore
  File "/home/new_user/Desktop/Flask_ss/venv/lib/python3.8/site-packages/werkzeug/routing.py", line 2032, in match
    raise NotFound()
werkzeug.exceptions.NotFound: 404 Not Found: The requested URL was not found on the server. If you entered the URL manually please check your spelling and try again.

During handling of the above exception, another exception occurred:

Traceback (most recent call last):
  File "/home/new_user/Desktop/Flask_ss/venv/lib/python3.8/site-packages/flask/app.py", line 2073, in wsgi_app
    response = self.full_dispatch_request()
  File "/home/new_user/Desktop/Flask_ss/venv/lib/python3.8/site-packages/flask/app.py", line 1518, in full_dispatch_request
    rv = self.handle_user_exception(e)
  File "/home/new_user/Desktop/Flask_ss/venv/lib/python3.8/site-packages/flask/app.py", line 1386, in handle_user_exception
    return self.handle_http_exception(e)
  File "/home/new_user/Desktop/Flask_ss/venv/lib/python3.8/site-packages/flask/app.py", line 1326, in handle_http_exception
    return self.ensure_sync(handler)(e)
TypeError: not_found_error() takes 0 positional arguments but 1 was given
2021-11-30 00:27:35,682 ERROR: Exception on /favicon.ico [GET] [int /home/new_user/Desktop/Flask_ss/venv/lib/python3.8/site-packages/flask/app.py:1457]
Traceback (most recent call last):
  File "/home/new_user/Desktop/Flask_ss/venv/lib/python3.8/site-packages/flask/app.py", line 1516, in full_dispatch_request
    rv = self.dispatch_request()
  File "/home/new_user/Desktop/Flask_ss/venv/lib/python3.8/site-packages/flask/app.py", line 1492, in dispatch_request
    self.raise_routing_exception(req)
  File "/home/new_user/Desktop/Flask_ss/venv/lib/python3.8/site-packages/flask/app.py", line 1474, in raise_routing_exception
    raise request.routing_exception  # type: ignore
  File "/home/new_user/Desktop/Flask_ss/venv/lib/python3.8/site-packages/flask/ctx.py", line 367, in match_request
    result = self.url_adapter.match(return_rule=True)  # type: ignore
  File "/home/new_user/Desktop/Flask_ss/venv/lib/python3.8/site-packages/werkzeug/routing.py", line 2032, in match
    raise NotFound()
werkzeug.exceptions.NotFound: 404 Not Found: The requested URL was not found on the server. If you entered the URL manually please check your spelling and try again.

During handling of the above exception, another exception occurred:

Traceback (most recent call last):
  File "/home/new_user/Desktop/Flask_ss/venv/lib/python3.8/site-packages/flask/app.py", line 2073, in wsgi_app
    response = self.full_dispatch_request()
  File "/home/new_user/Desktop/Flask_ss/venv/lib/python3.8/site-packages/flask/app.py", line 1518, in full_dispatch_request
    rv = self.handle_user_exception(e)
  File "/home/new_user/Desktop/Flask_ss/venv/lib/python3.8/site-packages/flask/app.py", line 1386, in handle_user_exception
    return self.handle_http_exception(e)
  File "/home/new_user/Desktop/Flask_ss/venv/lib/python3.8/site-packages/flask/app.py", line 1326, in handle_http_exception
    return self.ensure_sync(handler)(e)
TypeError: not_found_error() takes 0 positional arguments but 1 was given
2021-11-30 00:27:41,545 ERROR: Exception on /_styles.css [GET] [int /home/new_user/Desktop/Flask_ss/venv/lib/python3.8/site-packages/flask/app.py:1457]
Traceback (most recent call last):
  File "/home/new_user/Desktop/Flask_ss/venv/lib/python3.8/site-packages/flask/app.py", line 1516, in full_dispatch_request
    rv = self.dispatch_request()
  File "/home/new_user/Desktop/Flask_ss/venv/lib/python3.8/site-packages/flask/app.py", line 1492, in dispatch_request
    self.raise_routing_exception(req)
  File "/home/new_user/Desktop/Flask_ss/venv/lib/python3.8/site-packages/flask/app.py", line 1474, in raise_routing_exception
    raise request.routing_exception  # type: ignore
  File "/home/new_user/Desktop/Flask_ss/venv/lib/python3.8/site-packages/flask/ctx.py", line 367, in match_request
    result = self.url_adapter.match(return_rule=True)  # type: ignore
  File "/home/new_user/Desktop/Flask_ss/venv/lib/python3.8/site-packages/werkzeug/routing.py", line 2032, in match
    raise NotFound()
werkzeug.exceptions.NotFound: 404 Not Found: The requested URL was not found on the server. If you entered the URL manually please check your spelling and try again.

During handling of the above exception, another exception occurred:

Traceback (most recent call last):
  File "/home/new_user/Desktop/Flask_ss/venv/lib/python3.8/site-packages/flask/app.py", line 2073, in wsgi_app
    response = self.full_dispatch_request()
  File "/home/new_user/Desktop/Flask_ss/venv/lib/python3.8/site-packages/flask/app.py", line 1518, in full_dispatch_request
    rv = self.handle_user_exception(e)
  File "/home/new_user/Desktop/Flask_ss/venv/lib/python3.8/site-packages/flask/app.py", line 1386, in handle_user_exception
    return self.handle_http_exception(e)
  File "/home/new_user/Desktop/Flask_ss/venv/lib/python3.8/site-packages/flask/app.py", line 1326, in handle_http_exception
    return self.ensure_sync(handler)(e)
TypeError: not_found_error() takes 0 positional arguments but 1 was given
2021-11-30 00:27:41,630 ERROR: Exception on /favicon.ico [GET] [int /home/new_user/Desktop/Flask_ss/venv/lib/python3.8/site-packages/flask/app.py:1457]
Traceback (most recent call last):
  File "/home/new_user/Desktop/Flask_ss/venv/lib/python3.8/site-packages/flask/app.py", line 1516, in full_dispatch_request
    rv = self.dispatch_request()
  File "/home/new_user/Desktop/Flask_ss/venv/lib/python3.8/site-packages/flask/app.py", line 1492, in dispatch_request
    self.raise_routing_exception(req)
  File "/home/new_user/Desktop/Flask_ss/venv/lib/python3.8/site-packages/flask/app.py", line 1474, in raise_routing_exception
    raise request.routing_exception  # type: ignore
  File "/home/new_user/Desktop/Flask_ss/venv/lib/python3.8/site-packages/flask/ctx.py", line 367, in match_request
    result = self.url_adapter.match(return_rule=True)  # type: ignore
  File "/home/new_user/Desktop/Flask_ss/venv/lib/python3.8/site-packages/werkzeug/routing.py", line 2032, in match
    raise NotFound()
werkzeug.exceptions.NotFound: 404 Not Found: The requested URL was not found on the server. If you entered the URL manually please check your spelling and try again.

During handling of the above exception, another exception occurred:

Traceback (most recent call last):
  File "/home/new_user/Desktop/Flask_ss/venv/lib/python3.8/site-packages/flask/app.py", line 2073, in wsgi_app
    response = self.full_dispatch_request()
  File "/home/new_user/Desktop/Flask_ss/venv/lib/python3.8/site-packages/flask/app.py", line 1518, in full_dispatch_request
    rv = self.handle_user_exception(e)
  File "/home/new_user/Desktop/Flask_ss/venv/lib/python3.8/site-packages/flask/app.py", line 1386, in handle_user_exception
    return self.handle_http_exception(e)
  File "/home/new_user/Desktop/Flask_ss/venv/lib/python3.8/site-packages/flask/app.py", line 1326, in handle_http_exception
    return self.ensure_sync(handler)(e)
TypeError: not_found_error() takes 0 positional arguments but 1 was given
2021-11-30 00:27:44,810 ERROR: Exception on /admin [POST] [int /home/new_user/Desktop/Flask_ss/venv/lib/python3.8/site-packages/flask/app.py:1457]
Traceback (most recent call last):
  File "/home/new_user/Desktop/Flask_ss/venv/lib/python3.8/site-packages/flask/app.py", line 2073, in wsgi_app
    response = self.full_dispatch_request()
  File "/home/new_user/Desktop/Flask_ss/venv/lib/python3.8/site-packages/flask/app.py", line 1518, in full_dispatch_request
    rv = self.handle_user_exception(e)
  File "/home/new_user/Desktop/Flask_ss/venv/lib/python3.8/site-packages/flask/app.py", line 1516, in full_dispatch_request
    rv = self.dispatch_request()
  File "/home/new_user/Desktop/Flask_ss/venv/lib/python3.8/site-packages/flask/app.py", line 1502, in dispatch_request
    return self.ensure_sync(self.view_functions[rule.endpoint])(**req.view_args)
  File "/home/new_user/.local/lib/python3.8/site-packages/flask_login/utils.py", line 272, in decorated_view
    return func(*args, **kwargs)
  File "/home/new_user/Desktop/Flask_ss/app/admin/routes.py", line 27, in admin
    user = User.query.filter_by(username='ucmc'+datetime.now().year+'ss' + format(current_users_count, '03d')).first()
TypeError: can only concatenate str (not "int") to str
2021-11-30 00:27:44,880 ERROR: Exception on /_styles.css [GET] [int /home/new_user/Desktop/Flask_ss/venv/lib/python3.8/site-packages/flask/app.py:1457]
Traceback (most recent call last):
  File "/home/new_user/Desktop/Flask_ss/venv/lib/python3.8/site-packages/flask/app.py", line 1516, in full_dispatch_request
    rv = self.dispatch_request()
  File "/home/new_user/Desktop/Flask_ss/venv/lib/python3.8/site-packages/flask/app.py", line 1492, in dispatch_request
    self.raise_routing_exception(req)
  File "/home/new_user/Desktop/Flask_ss/venv/lib/python3.8/site-packages/flask/app.py", line 1474, in raise_routing_exception
    raise request.routing_exception  # type: ignore
  File "/home/new_user/Desktop/Flask_ss/venv/lib/python3.8/site-packages/flask/ctx.py", line 367, in match_request
    result = self.url_adapter.match(return_rule=True)  # type: ignore
  File "/home/new_user/Desktop/Flask_ss/venv/lib/python3.8/site-packages/werkzeug/routing.py", line 2032, in match
    raise NotFound()
werkzeug.exceptions.NotFound: 404 Not Found: The requested URL was not found on the server. If you entered the URL manually please check your spelling and try again.

During handling of the above exception, another exception occurred:

Traceback (most recent call last):
  File "/home/new_user/Desktop/Flask_ss/venv/lib/python3.8/site-packages/flask/app.py", line 2073, in wsgi_app
    response = self.full_dispatch_request()
  File "/home/new_user/Desktop/Flask_ss/venv/lib/python3.8/site-packages/flask/app.py", line 1518, in full_dispatch_request
    rv = self.handle_user_exception(e)
  File "/home/new_user/Desktop/Flask_ss/venv/lib/python3.8/site-packages/flask/app.py", line 1386, in handle_user_exception
    return self.handle_http_exception(e)
  File "/home/new_user/Desktop/Flask_ss/venv/lib/python3.8/site-packages/flask/app.py", line 1326, in handle_http_exception
    return self.ensure_sync(handler)(e)
TypeError: not_found_error() takes 0 positional arguments but 1 was given
2021-11-30 00:27:44,954 ERROR: Exception on /favicon.ico [GET] [int /home/new_user/Desktop/Flask_ss/venv/lib/python3.8/site-packages/flask/app.py:1457]
Traceback (most recent call last):
  File "/home/new_user/Desktop/Flask_ss/venv/lib/python3.8/site-packages/flask/app.py", line 1516, in full_dispatch_request
    rv = self.dispatch_request()
  File "/home/new_user/Desktop/Flask_ss/venv/lib/python3.8/site-packages/flask/app.py", line 1492, in dispatch_request
    self.raise_routing_exception(req)
  File "/home/new_user/Desktop/Flask_ss/venv/lib/python3.8/site-packages/flask/app.py", line 1474, in raise_routing_exception
    raise request.routing_exception  # type: ignore
  File "/home/new_user/Desktop/Flask_ss/venv/lib/python3.8/site-packages/flask/ctx.py", line 367, in match_request
    result = self.url_adapter.match(return_rule=True)  # type: ignore
  File "/home/new_user/Desktop/Flask_ss/venv/lib/python3.8/site-packages/werkzeug/routing.py", line 2032, in match
    raise NotFound()
werkzeug.exceptions.NotFound: 404 Not Found: The requested URL was not found on the server. If you entered the URL manually please check your spelling and try again.

During handling of the above exception, another exception occurred:

Traceback (most recent call last):
  File "/home/new_user/Desktop/Flask_ss/venv/lib/python3.8/site-packages/flask/app.py", line 2073, in wsgi_app
    response = self.full_dispatch_request()
  File "/home/new_user/Desktop/Flask_ss/venv/lib/python3.8/site-packages/flask/app.py", line 1518, in full_dispatch_request
    rv = self.handle_user_exception(e)
  File "/home/new_user/Desktop/Flask_ss/venv/lib/python3.8/site-packages/flask/app.py", line 1386, in handle_user_exception
    return self.handle_http_exception(e)
  File "/home/new_user/Desktop/Flask_ss/venv/lib/python3.8/site-packages/flask/app.py", line 1326, in handle_http_exception
    return self.ensure_sync(handler)(e)
TypeError: not_found_error() takes 0 positional arguments but 1 was given
2021-11-30 00:28:41,618 INFO: Microbial startup [int /home/new_user/Desktop/Flask_ss/app/__init__.py:77]
2021-11-30 00:28:41,640 INFO: Microbial startup [int /home/new_user/Desktop/Flask_ss/app/__init__.py:77]
2021-11-30 00:28:41,702 INFO: Microbial startup [int /home/new_user/Desktop/Flask_ss/app/__init__.py:77]
2021-11-30 00:28:41,894 INFO: Microbial startup [int /home/new_user/Desktop/Flask_ss/app/__init__.py:77]
2021-11-30 00:28:42,018 INFO: Microbial startup [int /home/new_user/Desktop/Flask_ss/app/__init__.py:77]
2021-11-30 00:28:42,071 INFO: Microbial startup [int /home/new_user/Desktop/Flask_ss/app/__init__.py:77]
2021-11-30 00:28:42,102 INFO: Microbial startup [int /home/new_user/Desktop/Flask_ss/app/__init__.py:77]
2021-11-30 00:28:42,202 INFO: Microbial startup [int /home/new_user/Desktop/Flask_ss/app/__init__.py:77]
2021-11-30 00:28:42,225 INFO: Microbial startup [int /home/new_user/Desktop/Flask_ss/app/__init__.py:77]
2021-12-05 19:24:02,397 INFO: Microbial startup [int /home/new_user/Desktop/Flask_ss/app/__init__.py:77]
2021-12-05 19:24:25,303 INFO: Microbial startup [int /home/new_user/Desktop/Flask_ss/app/__init__.py:77]
2021-12-05 19:27:10,963 ERROR: Exception on /_styles.css [GET] [int /home/new_user/Desktop/Flask_ss/venv/lib/python3.8/site-packages/flask/app.py:1457]
Traceback (most recent call last):
  File "/home/new_user/Desktop/Flask_ss/venv/lib/python3.8/site-packages/flask/app.py", line 1516, in full_dispatch_request
    rv = self.dispatch_request()
  File "/home/new_user/Desktop/Flask_ss/venv/lib/python3.8/site-packages/flask/app.py", line 1492, in dispatch_request
    self.raise_routing_exception(req)
  File "/home/new_user/Desktop/Flask_ss/venv/lib/python3.8/site-packages/flask/app.py", line 1474, in raise_routing_exception
    raise request.routing_exception  # type: ignore
  File "/home/new_user/Desktop/Flask_ss/venv/lib/python3.8/site-packages/flask/ctx.py", line 367, in match_request
    result = self.url_adapter.match(return_rule=True)  # type: ignore
  File "/home/new_user/Desktop/Flask_ss/venv/lib/python3.8/site-packages/werkzeug/routing.py", line 2032, in match
    raise NotFound()
werkzeug.exceptions.NotFound: 404 Not Found: The requested URL was not found on the server. If you entered the URL manually please check your spelling and try again.

During handling of the above exception, another exception occurred:

Traceback (most recent call last):
  File "/home/new_user/Desktop/Flask_ss/venv/lib/python3.8/site-packages/flask/app.py", line 2073, in wsgi_app
    response = self.full_dispatch_request()
  File "/home/new_user/Desktop/Flask_ss/venv/lib/python3.8/site-packages/flask/app.py", line 1518, in full_dispatch_request
    rv = self.handle_user_exception(e)
  File "/home/new_user/Desktop/Flask_ss/venv/lib/python3.8/site-packages/flask/app.py", line 1386, in handle_user_exception
    return self.handle_http_exception(e)
  File "/home/new_user/Desktop/Flask_ss/venv/lib/python3.8/site-packages/flask/app.py", line 1326, in handle_http_exception
    return self.ensure_sync(handler)(e)
TypeError: not_found_error() takes 0 positional arguments but 1 was given
2021-12-05 19:27:11,971 ERROR: Exception on /favicon.ico [GET] [int /home/new_user/Desktop/Flask_ss/venv/lib/python3.8/site-packages/flask/app.py:1457]
Traceback (most recent call last):
  File "/home/new_user/Desktop/Flask_ss/venv/lib/python3.8/site-packages/flask/app.py", line 1516, in full_dispatch_request
    rv = self.dispatch_request()
  File "/home/new_user/Desktop/Flask_ss/venv/lib/python3.8/site-packages/flask/app.py", line 1492, in dispatch_request
    self.raise_routing_exception(req)
  File "/home/new_user/Desktop/Flask_ss/venv/lib/python3.8/site-packages/flask/app.py", line 1474, in raise_routing_exception
    raise request.routing_exception  # type: ignore
  File "/home/new_user/Desktop/Flask_ss/venv/lib/python3.8/site-packages/flask/ctx.py", line 367, in match_request
    result = self.url_adapter.match(return_rule=True)  # type: ignore
  File "/home/new_user/Desktop/Flask_ss/venv/lib/python3.8/site-packages/werkzeug/routing.py", line 2032, in match
    raise NotFound()
werkzeug.exceptions.NotFound: 404 Not Found: The requested URL was not found on the server. If you entered the URL manually please check your spelling and try again.

During handling of the above exception, another exception occurred:

Traceback (most recent call last):
  File "/home/new_user/Desktop/Flask_ss/venv/lib/python3.8/site-packages/flask/app.py", line 2073, in wsgi_app
    response = self.full_dispatch_request()
  File "/home/new_user/Desktop/Flask_ss/venv/lib/python3.8/site-packages/flask/app.py", line 1518, in full_dispatch_request
    rv = self.handle_user_exception(e)
  File "/home/new_user/Desktop/Flask_ss/venv/lib/python3.8/site-packages/flask/app.py", line 1386, in handle_user_exception
    return self.handle_http_exception(e)
  File "/home/new_user/Desktop/Flask_ss/venv/lib/python3.8/site-packages/flask/app.py", line 1326, in handle_http_exception
    return self.ensure_sync(handler)(e)
TypeError: not_found_error() takes 0 positional arguments but 1 was given
2021-12-05 19:27:19,317 ERROR: Exception on /_styles.css [GET] [int /home/new_user/Desktop/Flask_ss/venv/lib/python3.8/site-packages/flask/app.py:1457]
Traceback (most recent call last):
  File "/home/new_user/Desktop/Flask_ss/venv/lib/python3.8/site-packages/flask/app.py", line 1516, in full_dispatch_request
    rv = self.dispatch_request()
  File "/home/new_user/Desktop/Flask_ss/venv/lib/python3.8/site-packages/flask/app.py", line 1492, in dispatch_request
    self.raise_routing_exception(req)
  File "/home/new_user/Desktop/Flask_ss/venv/lib/python3.8/site-packages/flask/app.py", line 1474, in raise_routing_exception
    raise request.routing_exception  # type: ignore
  File "/home/new_user/Desktop/Flask_ss/venv/lib/python3.8/site-packages/flask/ctx.py", line 367, in match_request
    result = self.url_adapter.match(return_rule=True)  # type: ignore
  File "/home/new_user/Desktop/Flask_ss/venv/lib/python3.8/site-packages/werkzeug/routing.py", line 2032, in match
    raise NotFound()
werkzeug.exceptions.NotFound: 404 Not Found: The requested URL was not found on the server. If you entered the URL manually please check your spelling and try again.

During handling of the above exception, another exception occurred:

Traceback (most recent call last):
  File "/home/new_user/Desktop/Flask_ss/venv/lib/python3.8/site-packages/flask/app.py", line 2073, in wsgi_app
    response = self.full_dispatch_request()
  File "/home/new_user/Desktop/Flask_ss/venv/lib/python3.8/site-packages/flask/app.py", line 1518, in full_dispatch_request
    rv = self.handle_user_exception(e)
  File "/home/new_user/Desktop/Flask_ss/venv/lib/python3.8/site-packages/flask/app.py", line 1386, in handle_user_exception
    return self.handle_http_exception(e)
  File "/home/new_user/Desktop/Flask_ss/venv/lib/python3.8/site-packages/flask/app.py", line 1326, in handle_http_exception
    return self.ensure_sync(handler)(e)
TypeError: not_found_error() takes 0 positional arguments but 1 was given
2021-12-05 19:27:19,536 ERROR: Exception on /favicon.ico [GET] [int /home/new_user/Desktop/Flask_ss/venv/lib/python3.8/site-packages/flask/app.py:1457]
Traceback (most recent call last):
  File "/home/new_user/Desktop/Flask_ss/venv/lib/python3.8/site-packages/flask/app.py", line 1516, in full_dispatch_request
    rv = self.dispatch_request()
  File "/home/new_user/Desktop/Flask_ss/venv/lib/python3.8/site-packages/flask/app.py", line 1492, in dispatch_request
    self.raise_routing_exception(req)
  File "/home/new_user/Desktop/Flask_ss/venv/lib/python3.8/site-packages/flask/app.py", line 1474, in raise_routing_exception
    raise request.routing_exception  # type: ignore
  File "/home/new_user/Desktop/Flask_ss/venv/lib/python3.8/site-packages/flask/ctx.py", line 367, in match_request
    result = self.url_adapter.match(return_rule=True)  # type: ignore
  File "/home/new_user/Desktop/Flask_ss/venv/lib/python3.8/site-packages/werkzeug/routing.py", line 2032, in match
    raise NotFound()
werkzeug.exceptions.NotFound: 404 Not Found: The requested URL was not found on the server. If you entered the URL manually please check your spelling and try again.

During handling of the above exception, another exception occurred:

Traceback (most recent call last):
  File "/home/new_user/Desktop/Flask_ss/venv/lib/python3.8/site-packages/flask/app.py", line 2073, in wsgi_app
    response = self.full_dispatch_request()
  File "/home/new_user/Desktop/Flask_ss/venv/lib/python3.8/site-packages/flask/app.py", line 1518, in full_dispatch_request
    rv = self.handle_user_exception(e)
  File "/home/new_user/Desktop/Flask_ss/venv/lib/python3.8/site-packages/flask/app.py", line 1386, in handle_user_exception
    return self.handle_http_exception(e)
  File "/home/new_user/Desktop/Flask_ss/venv/lib/python3.8/site-packages/flask/app.py", line 1326, in handle_http_exception
    return self.ensure_sync(handler)(e)
TypeError: not_found_error() takes 0 positional arguments but 1 was given
2021-12-05 19:28:12,791 ERROR: Exception on /admin/register [GET] [int /home/new_user/Desktop/Flask_ss/venv/lib/python3.8/site-packages/flask/app.py:1457]
Traceback (most recent call last):
  File "/home/new_user/Desktop/Flask_ss/venv/lib/python3.8/site-packages/flask/app.py", line 1516, in full_dispatch_request
    rv = self.dispatch_request()
  File "/home/new_user/Desktop/Flask_ss/venv/lib/python3.8/site-packages/flask/app.py", line 1492, in dispatch_request
    self.raise_routing_exception(req)
  File "/home/new_user/Desktop/Flask_ss/venv/lib/python3.8/site-packages/flask/app.py", line 1474, in raise_routing_exception
    raise request.routing_exception  # type: ignore
  File "/home/new_user/Desktop/Flask_ss/venv/lib/python3.8/site-packages/flask/ctx.py", line 367, in match_request
    result = self.url_adapter.match(return_rule=True)  # type: ignore
  File "/home/new_user/Desktop/Flask_ss/venv/lib/python3.8/site-packages/werkzeug/routing.py", line 2032, in match
    raise NotFound()
werkzeug.exceptions.NotFound: 404 Not Found: The requested URL was not found on the server. If you entered the URL manually please check your spelling and try again.

During handling of the above exception, another exception occurred:

Traceback (most recent call last):
  File "/home/new_user/Desktop/Flask_ss/venv/lib/python3.8/site-packages/flask/app.py", line 2073, in wsgi_app
    response = self.full_dispatch_request()
  File "/home/new_user/Desktop/Flask_ss/venv/lib/python3.8/site-packages/flask/app.py", line 1518, in full_dispatch_request
    rv = self.handle_user_exception(e)
  File "/home/new_user/Desktop/Flask_ss/venv/lib/python3.8/site-packages/flask/app.py", line 1386, in handle_user_exception
    return self.handle_http_exception(e)
  File "/home/new_user/Desktop/Flask_ss/venv/lib/python3.8/site-packages/flask/app.py", line 1326, in handle_http_exception
    return self.ensure_sync(handler)(e)
TypeError: not_found_error() takes 0 positional arguments but 1 was given
2021-12-05 19:28:12,882 ERROR: Exception on /admin/_styles.css [GET] [int /home/new_user/Desktop/Flask_ss/venv/lib/python3.8/site-packages/flask/app.py:1457]
Traceback (most recent call last):
  File "/home/new_user/Desktop/Flask_ss/venv/lib/python3.8/site-packages/flask/app.py", line 1516, in full_dispatch_request
    rv = self.dispatch_request()
  File "/home/new_user/Desktop/Flask_ss/venv/lib/python3.8/site-packages/flask/app.py", line 1492, in dispatch_request
    self.raise_routing_exception(req)
  File "/home/new_user/Desktop/Flask_ss/venv/lib/python3.8/site-packages/flask/app.py", line 1474, in raise_routing_exception
    raise request.routing_exception  # type: ignore
  File "/home/new_user/Desktop/Flask_ss/venv/lib/python3.8/site-packages/flask/ctx.py", line 367, in match_request
    result = self.url_adapter.match(return_rule=True)  # type: ignore
  File "/home/new_user/Desktop/Flask_ss/venv/lib/python3.8/site-packages/werkzeug/routing.py", line 2032, in match
    raise NotFound()
werkzeug.exceptions.NotFound: 404 Not Found: The requested URL was not found on the server. If you entered the URL manually please check your spelling and try again.

During handling of the above exception, another exception occurred:

Traceback (most recent call last):
  File "/home/new_user/Desktop/Flask_ss/venv/lib/python3.8/site-packages/flask/app.py", line 2073, in wsgi_app
    response = self.full_dispatch_request()
  File "/home/new_user/Desktop/Flask_ss/venv/lib/python3.8/site-packages/flask/app.py", line 1518, in full_dispatch_request
    rv = self.handle_user_exception(e)
  File "/home/new_user/Desktop/Flask_ss/venv/lib/python3.8/site-packages/flask/app.py", line 1386, in handle_user_exception
    return self.handle_http_exception(e)
  File "/home/new_user/Desktop/Flask_ss/venv/lib/python3.8/site-packages/flask/app.py", line 1326, in handle_http_exception
    return self.ensure_sync(handler)(e)
TypeError: not_found_error() takes 0 positional arguments but 1 was given
2021-12-05 19:28:13,216 ERROR: Exception on /favicon.ico [GET] [int /home/new_user/Desktop/Flask_ss/venv/lib/python3.8/site-packages/flask/app.py:1457]
Traceback (most recent call last):
  File "/home/new_user/Desktop/Flask_ss/venv/lib/python3.8/site-packages/flask/app.py", line 1516, in full_dispatch_request
    rv = self.dispatch_request()
  File "/home/new_user/Desktop/Flask_ss/venv/lib/python3.8/site-packages/flask/app.py", line 1492, in dispatch_request
    self.raise_routing_exception(req)
  File "/home/new_user/Desktop/Flask_ss/venv/lib/python3.8/site-packages/flask/app.py", line 1474, in raise_routing_exception
    raise request.routing_exception  # type: ignore
  File "/home/new_user/Desktop/Flask_ss/venv/lib/python3.8/site-packages/flask/ctx.py", line 367, in match_request
    result = self.url_adapter.match(return_rule=True)  # type: ignore
  File "/home/new_user/Desktop/Flask_ss/venv/lib/python3.8/site-packages/werkzeug/routing.py", line 2032, in match
    raise NotFound()
werkzeug.exceptions.NotFound: 404 Not Found: The requested URL was not found on the server. If you entered the URL manually please check your spelling and try again.

During handling of the above exception, another exception occurred:

Traceback (most recent call last):
  File "/home/new_user/Desktop/Flask_ss/venv/lib/python3.8/site-packages/flask/app.py", line 2073, in wsgi_app
    response = self.full_dispatch_request()
  File "/home/new_user/Desktop/Flask_ss/venv/lib/python3.8/site-packages/flask/app.py", line 1518, in full_dispatch_request
    rv = self.handle_user_exception(e)
  File "/home/new_user/Desktop/Flask_ss/venv/lib/python3.8/site-packages/flask/app.py", line 1386, in handle_user_exception
    return self.handle_http_exception(e)
  File "/home/new_user/Desktop/Flask_ss/venv/lib/python3.8/site-packages/flask/app.py", line 1326, in handle_http_exception
    return self.ensure_sync(handler)(e)
TypeError: not_found_error() takes 0 positional arguments but 1 was given
2021-12-05 19:28:22,034 ERROR: Exception on /_styles.css [GET] [int /home/new_user/Desktop/Flask_ss/venv/lib/python3.8/site-packages/flask/app.py:1457]
Traceback (most recent call last):
  File "/home/new_user/Desktop/Flask_ss/venv/lib/python3.8/site-packages/flask/app.py", line 1516, in full_dispatch_request
    rv = self.dispatch_request()
  File "/home/new_user/Desktop/Flask_ss/venv/lib/python3.8/site-packages/flask/app.py", line 1492, in dispatch_request
    self.raise_routing_exception(req)
  File "/home/new_user/Desktop/Flask_ss/venv/lib/python3.8/site-packages/flask/app.py", line 1474, in raise_routing_exception
    raise request.routing_exception  # type: ignore
  File "/home/new_user/Desktop/Flask_ss/venv/lib/python3.8/site-packages/flask/ctx.py", line 367, in match_request
    result = self.url_adapter.match(return_rule=True)  # type: ignore
  File "/home/new_user/Desktop/Flask_ss/venv/lib/python3.8/site-packages/werkzeug/routing.py", line 2032, in match
    raise NotFound()
werkzeug.exceptions.NotFound: 404 Not Found: The requested URL was not found on the server. If you entered the URL manually please check your spelling and try again.

During handling of the above exception, another exception occurred:

Traceback (most recent call last):
  File "/home/new_user/Desktop/Flask_ss/venv/lib/python3.8/site-packages/flask/app.py", line 2073, in wsgi_app
    response = self.full_dispatch_request()
  File "/home/new_user/Desktop/Flask_ss/venv/lib/python3.8/site-packages/flask/app.py", line 1518, in full_dispatch_request
    rv = self.handle_user_exception(e)
  File "/home/new_user/Desktop/Flask_ss/venv/lib/python3.8/site-packages/flask/app.py", line 1386, in handle_user_exception
    return self.handle_http_exception(e)
  File "/home/new_user/Desktop/Flask_ss/venv/lib/python3.8/site-packages/flask/app.py", line 1326, in handle_http_exception
    return self.ensure_sync(handler)(e)
TypeError: not_found_error() takes 0 positional arguments but 1 was given
2021-12-05 19:28:22,456 ERROR: Exception on /favicon.ico [GET] [int /home/new_user/Desktop/Flask_ss/venv/lib/python3.8/site-packages/flask/app.py:1457]
Traceback (most recent call last):
  File "/home/new_user/Desktop/Flask_ss/venv/lib/python3.8/site-packages/flask/app.py", line 1516, in full_dispatch_request
    rv = self.dispatch_request()
  File "/home/new_user/Desktop/Flask_ss/venv/lib/python3.8/site-packages/flask/app.py", line 1492, in dispatch_request
    self.raise_routing_exception(req)
  File "/home/new_user/Desktop/Flask_ss/venv/lib/python3.8/site-packages/flask/app.py", line 1474, in raise_routing_exception
    raise request.routing_exception  # type: ignore
  File "/home/new_user/Desktop/Flask_ss/venv/lib/python3.8/site-packages/flask/ctx.py", line 367, in match_request
    result = self.url_adapter.match(return_rule=True)  # type: ignore
  File "/home/new_user/Desktop/Flask_ss/venv/lib/python3.8/site-packages/werkzeug/routing.py", line 2032, in match
    raise NotFound()
werkzeug.exceptions.NotFound: 404 Not Found: The requested URL was not found on the server. If you entered the URL manually please check your spelling and try again.

During handling of the above exception, another exception occurred:

Traceback (most recent call last):
  File "/home/new_user/Desktop/Flask_ss/venv/lib/python3.8/site-packages/flask/app.py", line 2073, in wsgi_app
    response = self.full_dispatch_request()
  File "/home/new_user/Desktop/Flask_ss/venv/lib/python3.8/site-packages/flask/app.py", line 1518, in full_dispatch_request
    rv = self.handle_user_exception(e)
  File "/home/new_user/Desktop/Flask_ss/venv/lib/python3.8/site-packages/flask/app.py", line 1386, in handle_user_exception
    return self.handle_http_exception(e)
  File "/home/new_user/Desktop/Flask_ss/venv/lib/python3.8/site-packages/flask/app.py", line 1326, in handle_http_exception
    return self.ensure_sync(handler)(e)
TypeError: not_found_error() takes 0 positional arguments but 1 was given
2021-12-05 19:36:35,616 ERROR: Exception on /_styles.css [GET] [int /home/new_user/Desktop/Flask_ss/venv/lib/python3.8/site-packages/flask/app.py:1457]
Traceback (most recent call last):
  File "/home/new_user/Desktop/Flask_ss/venv/lib/python3.8/site-packages/flask/app.py", line 1516, in full_dispatch_request
    rv = self.dispatch_request()
  File "/home/new_user/Desktop/Flask_ss/venv/lib/python3.8/site-packages/flask/app.py", line 1492, in dispatch_request
    self.raise_routing_exception(req)
  File "/home/new_user/Desktop/Flask_ss/venv/lib/python3.8/site-packages/flask/app.py", line 1474, in raise_routing_exception
    raise request.routing_exception  # type: ignore
  File "/home/new_user/Desktop/Flask_ss/venv/lib/python3.8/site-packages/flask/ctx.py", line 367, in match_request
    result = self.url_adapter.match(return_rule=True)  # type: ignore
  File "/home/new_user/Desktop/Flask_ss/venv/lib/python3.8/site-packages/werkzeug/routing.py", line 2032, in match
    raise NotFound()
werkzeug.exceptions.NotFound: 404 Not Found: The requested URL was not found on the server. If you entered the URL manually please check your spelling and try again.

During handling of the above exception, another exception occurred:

Traceback (most recent call last):
  File "/home/new_user/Desktop/Flask_ss/venv/lib/python3.8/site-packages/flask/app.py", line 2073, in wsgi_app
    response = self.full_dispatch_request()
  File "/home/new_user/Desktop/Flask_ss/venv/lib/python3.8/site-packages/flask/app.py", line 1518, in full_dispatch_request
    rv = self.handle_user_exception(e)
  File "/home/new_user/Desktop/Flask_ss/venv/lib/python3.8/site-packages/flask/app.py", line 1386, in handle_user_exception
    return self.handle_http_exception(e)
  File "/home/new_user/Desktop/Flask_ss/venv/lib/python3.8/site-packages/flask/app.py", line 1326, in handle_http_exception
    return self.ensure_sync(handler)(e)
TypeError: not_found_error() takes 0 positional arguments but 1 was given
2021-12-05 19:36:35,810 ERROR: Exception on /favicon.ico [GET] [int /home/new_user/Desktop/Flask_ss/venv/lib/python3.8/site-packages/flask/app.py:1457]
Traceback (most recent call last):
  File "/home/new_user/Desktop/Flask_ss/venv/lib/python3.8/site-packages/flask/app.py", line 1516, in full_dispatch_request
    rv = self.dispatch_request()
  File "/home/new_user/Desktop/Flask_ss/venv/lib/python3.8/site-packages/flask/app.py", line 1492, in dispatch_request
    self.raise_routing_exception(req)
  File "/home/new_user/Desktop/Flask_ss/venv/lib/python3.8/site-packages/flask/app.py", line 1474, in raise_routing_exception
    raise request.routing_exception  # type: ignore
  File "/home/new_user/Desktop/Flask_ss/venv/lib/python3.8/site-packages/flask/ctx.py", line 367, in match_request
    result = self.url_adapter.match(return_rule=True)  # type: ignore
  File "/home/new_user/Desktop/Flask_ss/venv/lib/python3.8/site-packages/werkzeug/routing.py", line 2032, in match
    raise NotFound()
werkzeug.exceptions.NotFound: 404 Not Found: The requested URL was not found on the server. If you entered the URL manually please check your spelling and try again.

During handling of the above exception, another exception occurred:

Traceback (most recent call last):
  File "/home/new_user/Desktop/Flask_ss/venv/lib/python3.8/site-packages/flask/app.py", line 2073, in wsgi_app
    response = self.full_dispatch_request()
  File "/home/new_user/Desktop/Flask_ss/venv/lib/python3.8/site-packages/flask/app.py", line 1518, in full_dispatch_request
    rv = self.handle_user_exception(e)
  File "/home/new_user/Desktop/Flask_ss/venv/lib/python3.8/site-packages/flask/app.py", line 1386, in handle_user_exception
    return self.handle_http_exception(e)
  File "/home/new_user/Desktop/Flask_ss/venv/lib/python3.8/site-packages/flask/app.py", line 1326, in handle_http_exception
    return self.ensure_sync(handler)(e)
TypeError: not_found_error() takes 0 positional arguments but 1 was given
2021-12-05 19:40:03,464 ERROR: Exception on /uthgtu [GET] [int /home/new_user/Desktop/Flask_ss/venv/lib/python3.8/site-packages/flask/app.py:1457]
Traceback (most recent call last):
  File "/home/new_user/Desktop/Flask_ss/venv/lib/python3.8/site-packages/flask/app.py", line 1516, in full_dispatch_request
    rv = self.dispatch_request()
  File "/home/new_user/Desktop/Flask_ss/venv/lib/python3.8/site-packages/flask/app.py", line 1492, in dispatch_request
    self.raise_routing_exception(req)
  File "/home/new_user/Desktop/Flask_ss/venv/lib/python3.8/site-packages/flask/app.py", line 1474, in raise_routing_exception
    raise request.routing_exception  # type: ignore
  File "/home/new_user/Desktop/Flask_ss/venv/lib/python3.8/site-packages/flask/ctx.py", line 367, in match_request
    result = self.url_adapter.match(return_rule=True)  # type: ignore
  File "/home/new_user/Desktop/Flask_ss/venv/lib/python3.8/site-packages/werkzeug/routing.py", line 2032, in match
    raise NotFound()
werkzeug.exceptions.NotFound: 404 Not Found: The requested URL was not found on the server. If you entered the URL manually please check your spelling and try again.

During handling of the above exception, another exception occurred:

Traceback (most recent call last):
  File "/home/new_user/Desktop/Flask_ss/venv/lib/python3.8/site-packages/flask/app.py", line 2073, in wsgi_app
    response = self.full_dispatch_request()
  File "/home/new_user/Desktop/Flask_ss/venv/lib/python3.8/site-packages/flask/app.py", line 1518, in full_dispatch_request
    rv = self.handle_user_exception(e)
  File "/home/new_user/Desktop/Flask_ss/venv/lib/python3.8/site-packages/flask/app.py", line 1386, in handle_user_exception
    return self.handle_http_exception(e)
  File "/home/new_user/Desktop/Flask_ss/venv/lib/python3.8/site-packages/flask/app.py", line 1326, in handle_http_exception
    return self.ensure_sync(handler)(e)
TypeError: not_found_error() takes 0 positional arguments but 1 was given
2021-12-05 19:40:03,508 ERROR: Exception on /_styles.css [GET] [int /home/new_user/Desktop/Flask_ss/venv/lib/python3.8/site-packages/flask/app.py:1457]
Traceback (most recent call last):
  File "/home/new_user/Desktop/Flask_ss/venv/lib/python3.8/site-packages/flask/app.py", line 1516, in full_dispatch_request
    rv = self.dispatch_request()
  File "/home/new_user/Desktop/Flask_ss/venv/lib/python3.8/site-packages/flask/app.py", line 1492, in dispatch_request
    self.raise_routing_exception(req)
  File "/home/new_user/Desktop/Flask_ss/venv/lib/python3.8/site-packages/flask/app.py", line 1474, in raise_routing_exception
    raise request.routing_exception  # type: ignore
  File "/home/new_user/Desktop/Flask_ss/venv/lib/python3.8/site-packages/flask/ctx.py", line 367, in match_request
    result = self.url_adapter.match(return_rule=True)  # type: ignore
  File "/home/new_user/Desktop/Flask_ss/venv/lib/python3.8/site-packages/werkzeug/routing.py", line 2032, in match
    raise NotFound()
werkzeug.exceptions.NotFound: 404 Not Found: The requested URL was not found on the server. If you entered the URL manually please check your spelling and try again.

During handling of the above exception, another exception occurred:

Traceback (most recent call last):
  File "/home/new_user/Desktop/Flask_ss/venv/lib/python3.8/site-packages/flask/app.py", line 2073, in wsgi_app
    response = self.full_dispatch_request()
  File "/home/new_user/Desktop/Flask_ss/venv/lib/python3.8/site-packages/flask/app.py", line 1518, in full_dispatch_request
    rv = self.handle_user_exception(e)
  File "/home/new_user/Desktop/Flask_ss/venv/lib/python3.8/site-packages/flask/app.py", line 1386, in handle_user_exception
    return self.handle_http_exception(e)
  File "/home/new_user/Desktop/Flask_ss/venv/lib/python3.8/site-packages/flask/app.py", line 1326, in handle_http_exception
    return self.ensure_sync(handler)(e)
TypeError: not_found_error() takes 0 positional arguments but 1 was given
2021-12-05 19:40:03,665 ERROR: Exception on /favicon.ico [GET] [int /home/new_user/Desktop/Flask_ss/venv/lib/python3.8/site-packages/flask/app.py:1457]
Traceback (most recent call last):
  File "/home/new_user/Desktop/Flask_ss/venv/lib/python3.8/site-packages/flask/app.py", line 1516, in full_dispatch_request
    rv = self.dispatch_request()
  File "/home/new_user/Desktop/Flask_ss/venv/lib/python3.8/site-packages/flask/app.py", line 1492, in dispatch_request
    self.raise_routing_exception(req)
  File "/home/new_user/Desktop/Flask_ss/venv/lib/python3.8/site-packages/flask/app.py", line 1474, in raise_routing_exception
    raise request.routing_exception  # type: ignore
  File "/home/new_user/Desktop/Flask_ss/venv/lib/python3.8/site-packages/flask/ctx.py", line 367, in match_request
    result = self.url_adapter.match(return_rule=True)  # type: ignore
  File "/home/new_user/Desktop/Flask_ss/venv/lib/python3.8/site-packages/werkzeug/routing.py", line 2032, in match
    raise NotFound()
werkzeug.exceptions.NotFound: 404 Not Found: The requested URL was not found on the server. If you entered the URL manually please check your spelling and try again.

During handling of the above exception, another exception occurred:

Traceback (most recent call last):
  File "/home/new_user/Desktop/Flask_ss/venv/lib/python3.8/site-packages/flask/app.py", line 2073, in wsgi_app
    response = self.full_dispatch_request()
  File "/home/new_user/Desktop/Flask_ss/venv/lib/python3.8/site-packages/flask/app.py", line 1518, in full_dispatch_request
    rv = self.handle_user_exception(e)
  File "/home/new_user/Desktop/Flask_ss/venv/lib/python3.8/site-packages/flask/app.py", line 1386, in handle_user_exception
    return self.handle_http_exception(e)
  File "/home/new_user/Desktop/Flask_ss/venv/lib/python3.8/site-packages/flask/app.py", line 1326, in handle_http_exception
    return self.ensure_sync(handler)(e)
TypeError: not_found_error() takes 0 positional arguments but 1 was given
2021-12-05 19:43:31,167 ERROR: Exception on /_styles.css [GET] [int /home/new_user/Desktop/Flask_ss/venv/lib/python3.8/site-packages/flask/app.py:1457]
Traceback (most recent call last):
  File "/home/new_user/Desktop/Flask_ss/venv/lib/python3.8/site-packages/flask/app.py", line 1516, in full_dispatch_request
    rv = self.dispatch_request()
  File "/home/new_user/Desktop/Flask_ss/venv/lib/python3.8/site-packages/flask/app.py", line 1492, in dispatch_request
    self.raise_routing_exception(req)
  File "/home/new_user/Desktop/Flask_ss/venv/lib/python3.8/site-packages/flask/app.py", line 1474, in raise_routing_exception
    raise request.routing_exception  # type: ignore
  File "/home/new_user/Desktop/Flask_ss/venv/lib/python3.8/site-packages/flask/ctx.py", line 367, in match_request
    result = self.url_adapter.match(return_rule=True)  # type: ignore
  File "/home/new_user/Desktop/Flask_ss/venv/lib/python3.8/site-packages/werkzeug/routing.py", line 2032, in match
    raise NotFound()
werkzeug.exceptions.NotFound: 404 Not Found: The requested URL was not found on the server. If you entered the URL manually please check your spelling and try again.

During handling of the above exception, another exception occurred:

Traceback (most recent call last):
  File "/home/new_user/Desktop/Flask_ss/venv/lib/python3.8/site-packages/flask/app.py", line 2073, in wsgi_app
    response = self.full_dispatch_request()
  File "/home/new_user/Desktop/Flask_ss/venv/lib/python3.8/site-packages/flask/app.py", line 1518, in full_dispatch_request
    rv = self.handle_user_exception(e)
  File "/home/new_user/Desktop/Flask_ss/venv/lib/python3.8/site-packages/flask/app.py", line 1386, in handle_user_exception
    return self.handle_http_exception(e)
  File "/home/new_user/Desktop/Flask_ss/venv/lib/python3.8/site-packages/flask/app.py", line 1326, in handle_http_exception
    return self.ensure_sync(handler)(e)
TypeError: not_found_error() takes 0 positional arguments but 1 was given
2021-12-05 19:43:31,251 ERROR: Exception on /favicon.ico [GET] [int /home/new_user/Desktop/Flask_ss/venv/lib/python3.8/site-packages/flask/app.py:1457]
Traceback (most recent call last):
  File "/home/new_user/Desktop/Flask_ss/venv/lib/python3.8/site-packages/flask/app.py", line 1516, in full_dispatch_request
    rv = self.dispatch_request()
  File "/home/new_user/Desktop/Flask_ss/venv/lib/python3.8/site-packages/flask/app.py", line 1492, in dispatch_request
    self.raise_routing_exception(req)
  File "/home/new_user/Desktop/Flask_ss/venv/lib/python3.8/site-packages/flask/app.py", line 1474, in raise_routing_exception
    raise request.routing_exception  # type: ignore
  File "/home/new_user/Desktop/Flask_ss/venv/lib/python3.8/site-packages/flask/ctx.py", line 367, in match_request
    result = self.url_adapter.match(return_rule=True)  # type: ignore
  File "/home/new_user/Desktop/Flask_ss/venv/lib/python3.8/site-packages/werkzeug/routing.py", line 2032, in match
    raise NotFound()
werkzeug.exceptions.NotFound: 404 Not Found: The requested URL was not found on the server. If you entered the URL manually please check your spelling and try again.

During handling of the above exception, another exception occurred:

Traceback (most recent call last):
  File "/home/new_user/Desktop/Flask_ss/venv/lib/python3.8/site-packages/flask/app.py", line 2073, in wsgi_app
    response = self.full_dispatch_request()
  File "/home/new_user/Desktop/Flask_ss/venv/lib/python3.8/site-packages/flask/app.py", line 1518, in full_dispatch_request
    rv = self.handle_user_exception(e)
  File "/home/new_user/Desktop/Flask_ss/venv/lib/python3.8/site-packages/flask/app.py", line 1386, in handle_user_exception
    return self.handle_http_exception(e)
  File "/home/new_user/Desktop/Flask_ss/venv/lib/python3.8/site-packages/flask/app.py", line 1326, in handle_http_exception
    return self.ensure_sync(handler)(e)
TypeError: not_found_error() takes 0 positional arguments but 1 was given
2021-12-05 19:45:08,642 ERROR: Exception on /_styles.css [GET] [int /home/new_user/Desktop/Flask_ss/venv/lib/python3.8/site-packages/flask/app.py:1457]
Traceback (most recent call last):
  File "/home/new_user/Desktop/Flask_ss/venv/lib/python3.8/site-packages/flask/app.py", line 1516, in full_dispatch_request
    rv = self.dispatch_request()
  File "/home/new_user/Desktop/Flask_ss/venv/lib/python3.8/site-packages/flask/app.py", line 1492, in dispatch_request
    self.raise_routing_exception(req)
  File "/home/new_user/Desktop/Flask_ss/venv/lib/python3.8/site-packages/flask/app.py", line 1474, in raise_routing_exception
    raise request.routing_exception  # type: ignore
  File "/home/new_user/Desktop/Flask_ss/venv/lib/python3.8/site-packages/flask/ctx.py", line 367, in match_request
    result = self.url_adapter.match(return_rule=True)  # type: ignore
  File "/home/new_user/Desktop/Flask_ss/venv/lib/python3.8/site-packages/werkzeug/routing.py", line 2032, in match
    raise NotFound()
werkzeug.exceptions.NotFound: 404 Not Found: The requested URL was not found on the server. If you entered the URL manually please check your spelling and try again.

During handling of the above exception, another exception occurred:

Traceback (most recent call last):
  File "/home/new_user/Desktop/Flask_ss/venv/lib/python3.8/site-packages/flask/app.py", line 2073, in wsgi_app
    response = self.full_dispatch_request()
  File "/home/new_user/Desktop/Flask_ss/venv/lib/python3.8/site-packages/flask/app.py", line 1518, in full_dispatch_request
    rv = self.handle_user_exception(e)
  File "/home/new_user/Desktop/Flask_ss/venv/lib/python3.8/site-packages/flask/app.py", line 1386, in handle_user_exception
    return self.handle_http_exception(e)
  File "/home/new_user/Desktop/Flask_ss/venv/lib/python3.8/site-packages/flask/app.py", line 1326, in handle_http_exception
    return self.ensure_sync(handler)(e)
TypeError: not_found_error() takes 0 positional arguments but 1 was given
2021-12-05 19:45:08,741 ERROR: Exception on /favicon.ico [GET] [int /home/new_user/Desktop/Flask_ss/venv/lib/python3.8/site-packages/flask/app.py:1457]
Traceback (most recent call last):
  File "/home/new_user/Desktop/Flask_ss/venv/lib/python3.8/site-packages/flask/app.py", line 1516, in full_dispatch_request
    rv = self.dispatch_request()
  File "/home/new_user/Desktop/Flask_ss/venv/lib/python3.8/site-packages/flask/app.py", line 1492, in dispatch_request
    self.raise_routing_exception(req)
  File "/home/new_user/Desktop/Flask_ss/venv/lib/python3.8/site-packages/flask/app.py", line 1474, in raise_routing_exception
    raise request.routing_exception  # type: ignore
  File "/home/new_user/Desktop/Flask_ss/venv/lib/python3.8/site-packages/flask/ctx.py", line 367, in match_request
    result = self.url_adapter.match(return_rule=True)  # type: ignore
  File "/home/new_user/Desktop/Flask_ss/venv/lib/python3.8/site-packages/werkzeug/routing.py", line 2032, in match
    raise NotFound()
werkzeug.exceptions.NotFound: 404 Not Found: The requested URL was not found on the server. If you entered the URL manually please check your spelling and try again.

During handling of the above exception, another exception occurred:

Traceback (most recent call last):
  File "/home/new_user/Desktop/Flask_ss/venv/lib/python3.8/site-packages/flask/app.py", line 2073, in wsgi_app
    response = self.full_dispatch_request()
  File "/home/new_user/Desktop/Flask_ss/venv/lib/python3.8/site-packages/flask/app.py", line 1518, in full_dispatch_request
    rv = self.handle_user_exception(e)
  File "/home/new_user/Desktop/Flask_ss/venv/lib/python3.8/site-packages/flask/app.py", line 1386, in handle_user_exception
    return self.handle_http_exception(e)
  File "/home/new_user/Desktop/Flask_ss/venv/lib/python3.8/site-packages/flask/app.py", line 1326, in handle_http_exception
    return self.ensure_sync(handler)(e)
TypeError: not_found_error() takes 0 positional arguments but 1 was given
2021-12-05 19:45:16,901 ERROR: Exception on /_styles.css [GET] [int /home/new_user/Desktop/Flask_ss/venv/lib/python3.8/site-packages/flask/app.py:1457]
Traceback (most recent call last):
  File "/home/new_user/Desktop/Flask_ss/venv/lib/python3.8/site-packages/flask/app.py", line 1516, in full_dispatch_request
    rv = self.dispatch_request()
  File "/home/new_user/Desktop/Flask_ss/venv/lib/python3.8/site-packages/flask/app.py", line 1492, in dispatch_request
    self.raise_routing_exception(req)
  File "/home/new_user/Desktop/Flask_ss/venv/lib/python3.8/site-packages/flask/app.py", line 1474, in raise_routing_exception
    raise request.routing_exception  # type: ignore
  File "/home/new_user/Desktop/Flask_ss/venv/lib/python3.8/site-packages/flask/ctx.py", line 367, in match_request
    result = self.url_adapter.match(return_rule=True)  # type: ignore
  File "/home/new_user/Desktop/Flask_ss/venv/lib/python3.8/site-packages/werkzeug/routing.py", line 2032, in match
    raise NotFound()
werkzeug.exceptions.NotFound: 404 Not Found: The requested URL was not found on the server. If you entered the URL manually please check your spelling and try again.

During handling of the above exception, another exception occurred:

Traceback (most recent call last):
  File "/home/new_user/Desktop/Flask_ss/venv/lib/python3.8/site-packages/flask/app.py", line 2073, in wsgi_app
    response = self.full_dispatch_request()
  File "/home/new_user/Desktop/Flask_ss/venv/lib/python3.8/site-packages/flask/app.py", line 1518, in full_dispatch_request
    rv = self.handle_user_exception(e)
  File "/home/new_user/Desktop/Flask_ss/venv/lib/python3.8/site-packages/flask/app.py", line 1386, in handle_user_exception
    return self.handle_http_exception(e)
  File "/home/new_user/Desktop/Flask_ss/venv/lib/python3.8/site-packages/flask/app.py", line 1326, in handle_http_exception
    return self.ensure_sync(handler)(e)
TypeError: not_found_error() takes 0 positional arguments but 1 was given
2021-12-05 19:45:17,167 ERROR: Exception on /favicon.ico [GET] [int /home/new_user/Desktop/Flask_ss/venv/lib/python3.8/site-packages/flask/app.py:1457]
Traceback (most recent call last):
  File "/home/new_user/Desktop/Flask_ss/venv/lib/python3.8/site-packages/flask/app.py", line 1516, in full_dispatch_request
    rv = self.dispatch_request()
  File "/home/new_user/Desktop/Flask_ss/venv/lib/python3.8/site-packages/flask/app.py", line 1492, in dispatch_request
    self.raise_routing_exception(req)
  File "/home/new_user/Desktop/Flask_ss/venv/lib/python3.8/site-packages/flask/app.py", line 1474, in raise_routing_exception
    raise request.routing_exception  # type: ignore
  File "/home/new_user/Desktop/Flask_ss/venv/lib/python3.8/site-packages/flask/ctx.py", line 367, in match_request
    result = self.url_adapter.match(return_rule=True)  # type: ignore
  File "/home/new_user/Desktop/Flask_ss/venv/lib/python3.8/site-packages/werkzeug/routing.py", line 2032, in match
    raise NotFound()
werkzeug.exceptions.NotFound: 404 Not Found: The requested URL was not found on the server. If you entered the URL manually please check your spelling and try again.

During handling of the above exception, another exception occurred:

Traceback (most recent call last):
  File "/home/new_user/Desktop/Flask_ss/venv/lib/python3.8/site-packages/flask/app.py", line 2073, in wsgi_app
    response = self.full_dispatch_request()
  File "/home/new_user/Desktop/Flask_ss/venv/lib/python3.8/site-packages/flask/app.py", line 1518, in full_dispatch_request
    rv = self.handle_user_exception(e)
  File "/home/new_user/Desktop/Flask_ss/venv/lib/python3.8/site-packages/flask/app.py", line 1386, in handle_user_exception
    return self.handle_http_exception(e)
  File "/home/new_user/Desktop/Flask_ss/venv/lib/python3.8/site-packages/flask/app.py", line 1326, in handle_http_exception
    return self.ensure_sync(handler)(e)
TypeError: not_found_error() takes 0 positional arguments but 1 was given
2021-12-05 19:45:25,858 ERROR: Exception on /_styles.css [GET] [int /home/new_user/Desktop/Flask_ss/venv/lib/python3.8/site-packages/flask/app.py:1457]
Traceback (most recent call last):
  File "/home/new_user/Desktop/Flask_ss/venv/lib/python3.8/site-packages/flask/app.py", line 1516, in full_dispatch_request
    rv = self.dispatch_request()
  File "/home/new_user/Desktop/Flask_ss/venv/lib/python3.8/site-packages/flask/app.py", line 1492, in dispatch_request
    self.raise_routing_exception(req)
  File "/home/new_user/Desktop/Flask_ss/venv/lib/python3.8/site-packages/flask/app.py", line 1474, in raise_routing_exception
    raise request.routing_exception  # type: ignore
  File "/home/new_user/Desktop/Flask_ss/venv/lib/python3.8/site-packages/flask/ctx.py", line 367, in match_request
    result = self.url_adapter.match(return_rule=True)  # type: ignore
  File "/home/new_user/Desktop/Flask_ss/venv/lib/python3.8/site-packages/werkzeug/routing.py", line 2032, in match
    raise NotFound()
werkzeug.exceptions.NotFound: 404 Not Found: The requested URL was not found on the server. If you entered the URL manually please check your spelling and try again.

During handling of the above exception, another exception occurred:

Traceback (most recent call last):
  File "/home/new_user/Desktop/Flask_ss/venv/lib/python3.8/site-packages/flask/app.py", line 2073, in wsgi_app
    response = self.full_dispatch_request()
  File "/home/new_user/Desktop/Flask_ss/venv/lib/python3.8/site-packages/flask/app.py", line 1518, in full_dispatch_request
    rv = self.handle_user_exception(e)
  File "/home/new_user/Desktop/Flask_ss/venv/lib/python3.8/site-packages/flask/app.py", line 1386, in handle_user_exception
    return self.handle_http_exception(e)
  File "/home/new_user/Desktop/Flask_ss/venv/lib/python3.8/site-packages/flask/app.py", line 1326, in handle_http_exception
    return self.ensure_sync(handler)(e)
TypeError: not_found_error() takes 0 positional arguments but 1 was given
2021-12-05 19:45:25,955 ERROR: Exception on /favicon.ico [GET] [int /home/new_user/Desktop/Flask_ss/venv/lib/python3.8/site-packages/flask/app.py:1457]
Traceback (most recent call last):
  File "/home/new_user/Desktop/Flask_ss/venv/lib/python3.8/site-packages/flask/app.py", line 1516, in full_dispatch_request
    rv = self.dispatch_request()
  File "/home/new_user/Desktop/Flask_ss/venv/lib/python3.8/site-packages/flask/app.py", line 1492, in dispatch_request
    self.raise_routing_exception(req)
  File "/home/new_user/Desktop/Flask_ss/venv/lib/python3.8/site-packages/flask/app.py", line 1474, in raise_routing_exception
    raise request.routing_exception  # type: ignore
  File "/home/new_user/Desktop/Flask_ss/venv/lib/python3.8/site-packages/flask/ctx.py", line 367, in match_request
    result = self.url_adapter.match(return_rule=True)  # type: ignore
  File "/home/new_user/Desktop/Flask_ss/venv/lib/python3.8/site-packages/werkzeug/routing.py", line 2032, in match
    raise NotFound()
werkzeug.exceptions.NotFound: 404 Not Found: The requested URL was not found on the server. If you entered the URL manually please check your spelling and try again.

During handling of the above exception, another exception occurred:

Traceback (most recent call last):
  File "/home/new_user/Desktop/Flask_ss/venv/lib/python3.8/site-packages/flask/app.py", line 2073, in wsgi_app
    response = self.full_dispatch_request()
  File "/home/new_user/Desktop/Flask_ss/venv/lib/python3.8/site-packages/flask/app.py", line 1518, in full_dispatch_request
    rv = self.handle_user_exception(e)
  File "/home/new_user/Desktop/Flask_ss/venv/lib/python3.8/site-packages/flask/app.py", line 1386, in handle_user_exception
    return self.handle_http_exception(e)
  File "/home/new_user/Desktop/Flask_ss/venv/lib/python3.8/site-packages/flask/app.py", line 1326, in handle_http_exception
    return self.ensure_sync(handler)(e)
TypeError: not_found_error() takes 0 positional arguments but 1 was given
2021-12-12 21:29:30,694 INFO: Microbial startup [int /home/new_user/Desktop/Flask_ss/app/__init__.py:77]
2021-12-12 21:29:38,613 INFO: Microbial startup [int /home/new_user/Desktop/Flask_ss/app/__init__.py:77]
2021-12-12 21:29:55,023 ERROR: Exception on /_styles.css [GET] [int /home/new_user/Desktop/Flask_ss/venv/lib/python3.8/site-packages/flask/app.py:1457]
Traceback (most recent call last):
  File "/home/new_user/Desktop/Flask_ss/venv/lib/python3.8/site-packages/flask/app.py", line 1516, in full_dispatch_request
    rv = self.dispatch_request()
  File "/home/new_user/Desktop/Flask_ss/venv/lib/python3.8/site-packages/flask/app.py", line 1492, in dispatch_request
    self.raise_routing_exception(req)
  File "/home/new_user/Desktop/Flask_ss/venv/lib/python3.8/site-packages/flask/app.py", line 1474, in raise_routing_exception
    raise request.routing_exception  # type: ignore
  File "/home/new_user/Desktop/Flask_ss/venv/lib/python3.8/site-packages/flask/ctx.py", line 367, in match_request
    result = self.url_adapter.match(return_rule=True)  # type: ignore
  File "/home/new_user/Desktop/Flask_ss/venv/lib/python3.8/site-packages/werkzeug/routing.py", line 2032, in match
    raise NotFound()
werkzeug.exceptions.NotFound: 404 Not Found: The requested URL was not found on the server. If you entered the URL manually please check your spelling and try again.

During handling of the above exception, another exception occurred:

Traceback (most recent call last):
  File "/home/new_user/Desktop/Flask_ss/venv/lib/python3.8/site-packages/flask/app.py", line 2073, in wsgi_app
    response = self.full_dispatch_request()
  File "/home/new_user/Desktop/Flask_ss/venv/lib/python3.8/site-packages/flask/app.py", line 1518, in full_dispatch_request
    rv = self.handle_user_exception(e)
  File "/home/new_user/Desktop/Flask_ss/venv/lib/python3.8/site-packages/flask/app.py", line 1386, in handle_user_exception
    return self.handle_http_exception(e)
  File "/home/new_user/Desktop/Flask_ss/venv/lib/python3.8/site-packages/flask/app.py", line 1326, in handle_http_exception
    return self.ensure_sync(handler)(e)
TypeError: not_found_error() takes 0 positional arguments but 1 was given
