2021-11-28 22:33:12,517 ERROR: Exception on /_styles.css [GET] [int /home/new_user/Desktop/Flask_ss/venv/lib/python3.8/site-packages/flask/app.py:1457]
Traceback (most recent call last):
  File "/home/new_user/Desktop/Flask_ss/venv/lib/python3.8/site-packages/flask/app.py", line 1516, in full_dispatch_request
    rv = self.dispatch_request()
  File "/home/new_user/Desktop/Flask_ss/venv/lib/python3.8/site-packages/flask/app.py", line 1492, in dispatch_request
    self.raise_routing_exception(req)
  File "/home/new_user/Desktop/Flask_ss/venv/lib/python3.8/site-packages/flask/app.py", line 1474, in raise_routing_exception
    raise request.routing_exception  # type: ignore
  File "/home/new_user/Desktop/Flask_ss/venv/lib/python3.8/site-packages/flask/ctx.py", line 367, in match_request
    result = self.url_adapter.match(return_rule=True)  # type: ignore
  File "/home/new_user/Desktop/Flask_ss/venv/lib/python3.8/site-packages/werkzeug/routing.py", line 2032, in match
    raise NotFound()
werkzeug.exceptions.NotFound: 404 Not Found: The requested URL was not found on the server. If you entered the URL manually please check your spelling and try again.

During handling of the above exception, another exception occurred:

Traceback (most recent call last):
  File "/home/new_user/Desktop/Flask_ss/venv/lib/python3.8/site-packages/flask/app.py", line 2073, in wsgi_app
    response = self.full_dispatch_request()
  File "/home/new_user/Desktop/Flask_ss/venv/lib/python3.8/site-packages/flask/app.py", line 1518, in full_dispatch_request
    rv = self.handle_user_exception(e)
  File "/home/new_user/Desktop/Flask_ss/venv/lib/python3.8/site-packages/flask/app.py", line 1386, in handle_user_exception
    return self.handle_http_exception(e)
  File "/home/new_user/Desktop/Flask_ss/venv/lib/python3.8/site-packages/flask/app.py", line 1326, in handle_http_exception
    return self.ensure_sync(handler)(e)
TypeError: not_found_error() takes 0 positional arguments but 1 was given
2021-11-28 22:33:13,350 ERROR: Exception on /favicon.ico [GET] [int /home/new_user/Desktop/Flask_ss/venv/lib/python3.8/site-packages/flask/app.py:1457]
Traceback (most recent call last):
  File "/home/new_user/Desktop/Flask_ss/venv/lib/python3.8/site-packages/flask/app.py", line 1516, in full_dispatch_request
    rv = self.dispatch_request()
  File "/home/new_user/Desktop/Flask_ss/venv/lib/python3.8/site-packages/flask/app.py", line 1492, in dispatch_request
    self.raise_routing_exception(req)
  File "/home/new_user/Desktop/Flask_ss/venv/lib/python3.8/site-packages/flask/app.py", line 1474, in raise_routing_exception
    raise request.routing_exception  # type: ignore
  File "/home/new_user/Desktop/Flask_ss/venv/lib/python3.8/site-packages/flask/ctx.py", line 367, in match_request
    result = self.url_adapter.match(return_rule=True)  # type: ignore
  File "/home/new_user/Desktop/Flask_ss/venv/lib/python3.8/site-packages/werkzeug/routing.py", line 2032, in match
    raise NotFound()
werkzeug.exceptions.NotFound: 404 Not Found: The requested URL was not found on the server. If you entered the URL manually please check your spelling and try again.

During handling of the above exception, another exception occurred:

Traceback (most recent call last):
  File "/home/new_user/Desktop/Flask_ss/venv/lib/python3.8/site-packages/flask/app.py", line 2073, in wsgi_app
    response = self.full_dispatch_request()
  File "/home/new_user/Desktop/Flask_ss/venv/lib/python3.8/site-packages/flask/app.py", line 1518, in full_dispatch_request
    rv = self.handle_user_exception(e)
  File "/home/new_user/Desktop/Flask_ss/venv/lib/python3.8/site-packages/flask/app.py", line 1386, in handle_user_exception
    return self.handle_http_exception(e)
  File "/home/new_user/Desktop/Flask_ss/venv/lib/python3.8/site-packages/flask/app.py", line 1326, in handle_http_exception
    return self.ensure_sync(handler)(e)
TypeError: not_found_error() takes 0 positional arguments but 1 was given
2021-11-28 22:36:50,012 ERROR: Exception on /user/123/home_page [GET] [int /home/new_user/Desktop/Flask_ss/venv/lib/python3.8/site-packages/flask/app.py:1457]
Traceback (most recent call last):
  File "/home/new_user/Desktop/Flask_ss/venv/lib/python3.8/site-packages/flask/app.py", line 1516, in full_dispatch_request
    rv = self.dispatch_request()
  File "/home/new_user/Desktop/Flask_ss/venv/lib/python3.8/site-packages/flask/app.py", line 1502, in dispatch_request
    return self.ensure_sync(self.view_functions[rule.endpoint])(**req.view_args)
  File "/home/new_user/.local/lib/python3.8/site-packages/flask_login/utils.py", line 272, in decorated_view
    return func(*args, **kwargs)
  File "/home/new_user/Desktop/Flask_ss/app/main/routes.py", line 38, in user_page
    user = User.query.filter_by(username=username).first_or_404()
  File "/home/new_user/.local/lib/python3.8/site-packages/flask_sqlalchemy/__init__.py", line 470, in first_or_404
    abort(404, description=description)
  File "/home/new_user/Desktop/Flask_ss/venv/lib/python3.8/site-packages/werkzeug/exceptions.py", line 940, in abort
    _aborter(status, *args, **kwargs)
  File "/home/new_user/Desktop/Flask_ss/venv/lib/python3.8/site-packages/werkzeug/exceptions.py", line 923, in __call__
    raise self.mapping[code](*args, **kwargs)
werkzeug.exceptions.NotFound: 404 Not Found: The requested URL was not found on the server. If you entered the URL manually please check your spelling and try again.

During handling of the above exception, another exception occurred:

Traceback (most recent call last):
  File "/home/new_user/Desktop/Flask_ss/venv/lib/python3.8/site-packages/flask/app.py", line 2073, in wsgi_app
    response = self.full_dispatch_request()
  File "/home/new_user/Desktop/Flask_ss/venv/lib/python3.8/site-packages/flask/app.py", line 1518, in full_dispatch_request
    rv = self.handle_user_exception(e)
  File "/home/new_user/Desktop/Flask_ss/venv/lib/python3.8/site-packages/flask/app.py", line 1386, in handle_user_exception
    return self.handle_http_exception(e)
  File "/home/new_user/Desktop/Flask_ss/venv/lib/python3.8/site-packages/flask/app.py", line 1326, in handle_http_exception
    return self.ensure_sync(handler)(e)
TypeError: not_found_error() takes 0 positional arguments but 1 was given
2021-11-28 22:36:50,419 ERROR: Exception on /user/123/_styles.css [GET] [int /home/new_user/Desktop/Flask_ss/venv/lib/python3.8/site-packages/flask/app.py:1457]
Traceback (most recent call last):
  File "/home/new_user/Desktop/Flask_ss/venv/lib/python3.8/site-packages/flask/app.py", line 1516, in full_dispatch_request
    rv = self.dispatch_request()
  File "/home/new_user/Desktop/Flask_ss/venv/lib/python3.8/site-packages/flask/app.py", line 1502, in dispatch_request
    return self.ensure_sync(self.view_functions[rule.endpoint])(**req.view_args)
  File "/home/new_user/Desktop/Flask_ss/app/main/routes.py", line 18, in send_textures
    cur_user = User.query.filter_by(username=username).first_or_404()
  File "/home/new_user/.local/lib/python3.8/site-packages/flask_sqlalchemy/__init__.py", line 470, in first_or_404
    abort(404, description=description)
  File "/home/new_user/Desktop/Flask_ss/venv/lib/python3.8/site-packages/werkzeug/exceptions.py", line 940, in abort
    _aborter(status, *args, **kwargs)
  File "/home/new_user/Desktop/Flask_ss/venv/lib/python3.8/site-packages/werkzeug/exceptions.py", line 923, in __call__
    raise self.mapping[code](*args, **kwargs)
werkzeug.exceptions.NotFound: 404 Not Found: The requested URL was not found on the server. If you entered the URL manually please check your spelling and try again.

During handling of the above exception, another exception occurred:

Traceback (most recent call last):
  File "/home/new_user/Desktop/Flask_ss/venv/lib/python3.8/site-packages/flask/app.py", line 2073, in wsgi_app
    response = self.full_dispatch_request()
  File "/home/new_user/Desktop/Flask_ss/venv/lib/python3.8/site-packages/flask/app.py", line 1518, in full_dispatch_request
    rv = self.handle_user_exception(e)
  File "/home/new_user/Desktop/Flask_ss/venv/lib/python3.8/site-packages/flask/app.py", line 1386, in handle_user_exception
    return self.handle_http_exception(e)
  File "/home/new_user/Desktop/Flask_ss/venv/lib/python3.8/site-packages/flask/app.py", line 1326, in handle_http_exception
    return self.ensure_sync(handler)(e)
TypeError: not_found_error() takes 0 positional arguments but 1 was given
2021-11-28 22:36:50,489 ERROR: Exception on /favicon.ico [GET] [int /home/new_user/Desktop/Flask_ss/venv/lib/python3.8/site-packages/flask/app.py:1457]
Traceback (most recent call last):
  File "/home/new_user/Desktop/Flask_ss/venv/lib/python3.8/site-packages/flask/app.py", line 1516, in full_dispatch_request
    rv = self.dispatch_request()
  File "/home/new_user/Desktop/Flask_ss/venv/lib/python3.8/site-packages/flask/app.py", line 1492, in dispatch_request
    self.raise_routing_exception(req)
  File "/home/new_user/Desktop/Flask_ss/venv/lib/python3.8/site-packages/flask/app.py", line 1474, in raise_routing_exception
    raise request.routing_exception  # type: ignore
  File "/home/new_user/Desktop/Flask_ss/venv/lib/python3.8/site-packages/flask/ctx.py", line 367, in match_request
    result = self.url_adapter.match(return_rule=True)  # type: ignore
  File "/home/new_user/Desktop/Flask_ss/venv/lib/python3.8/site-packages/werkzeug/routing.py", line 2032, in match
    raise NotFound()
werkzeug.exceptions.NotFound: 404 Not Found: The requested URL was not found on the server. If you entered the URL manually please check your spelling and try again.

During handling of the above exception, another exception occurred:

Traceback (most recent call last):
  File "/home/new_user/Desktop/Flask_ss/venv/lib/python3.8/site-packages/flask/app.py", line 2073, in wsgi_app
    response = self.full_dispatch_request()
  File "/home/new_user/Desktop/Flask_ss/venv/lib/python3.8/site-packages/flask/app.py", line 1518, in full_dispatch_request
    rv = self.handle_user_exception(e)
  File "/home/new_user/Desktop/Flask_ss/venv/lib/python3.8/site-packages/flask/app.py", line 1386, in handle_user_exception
    return self.handle_http_exception(e)
  File "/home/new_user/Desktop/Flask_ss/venv/lib/python3.8/site-packages/flask/app.py", line 1326, in handle_http_exception
    return self.ensure_sync(handler)(e)
TypeError: not_found_error() takes 0 positional arguments but 1 was given
2021-11-28 22:36:58,160 ERROR: Exception on /user/ucmc2020ss254/_styles.css [GET] [int /home/new_user/Desktop/Flask_ss/venv/lib/python3.8/site-packages/flask/app.py:1457]
Traceback (most recent call last):
  File "/home/new_user/Desktop/Flask_ss/venv/lib/python3.8/site-packages/flask/app.py", line 1516, in full_dispatch_request
    rv = self.dispatch_request()
  File "/home/new_user/Desktop/Flask_ss/venv/lib/python3.8/site-packages/flask/app.py", line 1502, in dispatch_request
    return self.ensure_sync(self.view_functions[rule.endpoint])(**req.view_args)
  File "/home/new_user/Desktop/Flask_ss/app/main/routes.py", line 21, in send_textures
    return send_from_directory(cur_folder, path)
  File "/home/new_user/Desktop/Flask_ss/venv/lib/python3.8/site-packages/flask/helpers.py", line 700, in send_from_directory
    return werkzeug.utils.send_from_directory(  # type: ignore
  File "/home/new_user/Desktop/Flask_ss/venv/lib/python3.8/site-packages/werkzeug/utils.py", line 841, in send_from_directory
    raise NotFound()
werkzeug.exceptions.NotFound: 404 Not Found: The requested URL was not found on the server. If you entered the URL manually please check your spelling and try again.

During handling of the above exception, another exception occurred:

Traceback (most recent call last):
  File "/home/new_user/Desktop/Flask_ss/venv/lib/python3.8/site-packages/flask/app.py", line 2073, in wsgi_app
    response = self.full_dispatch_request()
  File "/home/new_user/Desktop/Flask_ss/venv/lib/python3.8/site-packages/flask/app.py", line 1518, in full_dispatch_request
    rv = self.handle_user_exception(e)
  File "/home/new_user/Desktop/Flask_ss/venv/lib/python3.8/site-packages/flask/app.py", line 1386, in handle_user_exception
    return self.handle_http_exception(e)
  File "/home/new_user/Desktop/Flask_ss/venv/lib/python3.8/site-packages/flask/app.py", line 1326, in handle_http_exception
    return self.ensure_sync(handler)(e)
TypeError: not_found_error() takes 0 positional arguments but 1 was given
2021-11-28 22:36:58,201 ERROR: Exception on /favicon.ico [GET] [int /home/new_user/Desktop/Flask_ss/venv/lib/python3.8/site-packages/flask/app.py:1457]
Traceback (most recent call last):
  File "/home/new_user/Desktop/Flask_ss/venv/lib/python3.8/site-packages/flask/app.py", line 1516, in full_dispatch_request
    rv = self.dispatch_request()
  File "/home/new_user/Desktop/Flask_ss/venv/lib/python3.8/site-packages/flask/app.py", line 1492, in dispatch_request
    self.raise_routing_exception(req)
  File "/home/new_user/Desktop/Flask_ss/venv/lib/python3.8/site-packages/flask/app.py", line 1474, in raise_routing_exception
    raise request.routing_exception  # type: ignore
  File "/home/new_user/Desktop/Flask_ss/venv/lib/python3.8/site-packages/flask/ctx.py", line 367, in match_request
    result = self.url_adapter.match(return_rule=True)  # type: ignore
  File "/home/new_user/Desktop/Flask_ss/venv/lib/python3.8/site-packages/werkzeug/routing.py", line 2032, in match
    raise NotFound()
werkzeug.exceptions.NotFound: 404 Not Found: The requested URL was not found on the server. If you entered the URL manually please check your spelling and try again.

During handling of the above exception, another exception occurred:

Traceback (most recent call last):
  File "/home/new_user/Desktop/Flask_ss/venv/lib/python3.8/site-packages/flask/app.py", line 2073, in wsgi_app
    response = self.full_dispatch_request()
  File "/home/new_user/Desktop/Flask_ss/venv/lib/python3.8/site-packages/flask/app.py", line 1518, in full_dispatch_request
    rv = self.handle_user_exception(e)
  File "/home/new_user/Desktop/Flask_ss/venv/lib/python3.8/site-packages/flask/app.py", line 1386, in handle_user_exception
    return self.handle_http_exception(e)
  File "/home/new_user/Desktop/Flask_ss/venv/lib/python3.8/site-packages/flask/app.py", line 1326, in handle_http_exception
    return self.ensure_sync(handler)(e)
TypeError: not_found_error() takes 0 positional arguments but 1 was given
2021-11-28 22:38:41,563 ERROR: Exception on /_styles.css [GET] [int /home/new_user/Desktop/Flask_ss/venv/lib/python3.8/site-packages/flask/app.py:1457]
Traceback (most recent call last):
  File "/home/new_user/Desktop/Flask_ss/venv/lib/python3.8/site-packages/flask/app.py", line 1516, in full_dispatch_request
    rv = self.dispatch_request()
  File "/home/new_user/Desktop/Flask_ss/venv/lib/python3.8/site-packages/flask/app.py", line 1492, in dispatch_request
    self.raise_routing_exception(req)
  File "/home/new_user/Desktop/Flask_ss/venv/lib/python3.8/site-packages/flask/app.py", line 1474, in raise_routing_exception
    raise request.routing_exception  # type: ignore
  File "/home/new_user/Desktop/Flask_ss/venv/lib/python3.8/site-packages/flask/ctx.py", line 367, in match_request
    result = self.url_adapter.match(return_rule=True)  # type: ignore
  File "/home/new_user/Desktop/Flask_ss/venv/lib/python3.8/site-packages/werkzeug/routing.py", line 2032, in match
    raise NotFound()
werkzeug.exceptions.NotFound: 404 Not Found: The requested URL was not found on the server. If you entered the URL manually please check your spelling and try again.

During handling of the above exception, another exception occurred:

Traceback (most recent call last):
  File "/home/new_user/Desktop/Flask_ss/venv/lib/python3.8/site-packages/flask/app.py", line 2073, in wsgi_app
    response = self.full_dispatch_request()
  File "/home/new_user/Desktop/Flask_ss/venv/lib/python3.8/site-packages/flask/app.py", line 1518, in full_dispatch_request
    rv = self.handle_user_exception(e)
  File "/home/new_user/Desktop/Flask_ss/venv/lib/python3.8/site-packages/flask/app.py", line 1386, in handle_user_exception
    return self.handle_http_exception(e)
  File "/home/new_user/Desktop/Flask_ss/venv/lib/python3.8/site-packages/flask/app.py", line 1326, in handle_http_exception
    return self.ensure_sync(handler)(e)
TypeError: not_found_error() takes 0 positional arguments but 1 was given
2021-11-28 22:38:41,701 ERROR: Exception on /favicon.ico [GET] [int /home/new_user/Desktop/Flask_ss/venv/lib/python3.8/site-packages/flask/app.py:1457]
Traceback (most recent call last):
  File "/home/new_user/Desktop/Flask_ss/venv/lib/python3.8/site-packages/flask/app.py", line 1516, in full_dispatch_request
    rv = self.dispatch_request()
  File "/home/new_user/Desktop/Flask_ss/venv/lib/python3.8/site-packages/flask/app.py", line 1492, in dispatch_request
    self.raise_routing_exception(req)
  File "/home/new_user/Desktop/Flask_ss/venv/lib/python3.8/site-packages/flask/app.py", line 1474, in raise_routing_exception
    raise request.routing_exception  # type: ignore
  File "/home/new_user/Desktop/Flask_ss/venv/lib/python3.8/site-packages/flask/ctx.py", line 367, in match_request
    result = self.url_adapter.match(return_rule=True)  # type: ignore
  File "/home/new_user/Desktop/Flask_ss/venv/lib/python3.8/site-packages/werkzeug/routing.py", line 2032, in match
    raise NotFound()
werkzeug.exceptions.NotFound: 404 Not Found: The requested URL was not found on the server. If you entered the URL manually please check your spelling and try again.

During handling of the above exception, another exception occurred:

Traceback (most recent call last):
  File "/home/new_user/Desktop/Flask_ss/venv/lib/python3.8/site-packages/flask/app.py", line 2073, in wsgi_app
    response = self.full_dispatch_request()
  File "/home/new_user/Desktop/Flask_ss/venv/lib/python3.8/site-packages/flask/app.py", line 1518, in full_dispatch_request
    rv = self.handle_user_exception(e)
  File "/home/new_user/Desktop/Flask_ss/venv/lib/python3.8/site-packages/flask/app.py", line 1386, in handle_user_exception
    return self.handle_http_exception(e)
  File "/home/new_user/Desktop/Flask_ss/venv/lib/python3.8/site-packages/flask/app.py", line 1326, in handle_http_exception
    return self.ensure_sync(handler)(e)
TypeError: not_found_error() takes 0 positional arguments but 1 was given
2021-11-28 22:38:59,583 ERROR: Exception on /user/ucmc2020ss254/_styles.css [GET] [int /home/new_user/Desktop/Flask_ss/venv/lib/python3.8/site-packages/flask/app.py:1457]
Traceback (most recent call last):
  File "/home/new_user/Desktop/Flask_ss/venv/lib/python3.8/site-packages/flask/app.py", line 1516, in full_dispatch_request
    rv = self.dispatch_request()
  File "/home/new_user/Desktop/Flask_ss/venv/lib/python3.8/site-packages/flask/app.py", line 1502, in dispatch_request
    return self.ensure_sync(self.view_functions[rule.endpoint])(**req.view_args)
  File "/home/new_user/Desktop/Flask_ss/app/main/routes.py", line 21, in send_textures
    return send_from_directory(cur_folder, path)
  File "/home/new_user/Desktop/Flask_ss/venv/lib/python3.8/site-packages/flask/helpers.py", line 700, in send_from_directory
    return werkzeug.utils.send_from_directory(  # type: ignore
  File "/home/new_user/Desktop/Flask_ss/venv/lib/python3.8/site-packages/werkzeug/utils.py", line 841, in send_from_directory
    raise NotFound()
werkzeug.exceptions.NotFound: 404 Not Found: The requested URL was not found on the server. If you entered the URL manually please check your spelling and try again.

During handling of the above exception, another exception occurred:

Traceback (most recent call last):
  File "/home/new_user/Desktop/Flask_ss/venv/lib/python3.8/site-packages/flask/app.py", line 2073, in wsgi_app
    response = self.full_dispatch_request()
  File "/home/new_user/Desktop/Flask_ss/venv/lib/python3.8/site-packages/flask/app.py", line 1518, in full_dispatch_request
    rv = self.handle_user_exception(e)
  File "/home/new_user/Desktop/Flask_ss/venv/lib/python3.8/site-packages/flask/app.py", line 1386, in handle_user_exception
    return self.handle_http_exception(e)
  File "/home/new_user/Desktop/Flask_ss/venv/lib/python3.8/site-packages/flask/app.py", line 1326, in handle_http_exception
    return self.ensure_sync(handler)(e)
TypeError: not_found_error() takes 0 positional arguments but 1 was given
2021-11-28 22:38:59,632 ERROR: Exception on /favicon.ico [GET] [int /home/new_user/Desktop/Flask_ss/venv/lib/python3.8/site-packages/flask/app.py:1457]
Traceback (most recent call last):
  File "/home/new_user/Desktop/Flask_ss/venv/lib/python3.8/site-packages/flask/app.py", line 1516, in full_dispatch_request
    rv = self.dispatch_request()
  File "/home/new_user/Desktop/Flask_ss/venv/lib/python3.8/site-packages/flask/app.py", line 1492, in dispatch_request
    self.raise_routing_exception(req)
  File "/home/new_user/Desktop/Flask_ss/venv/lib/python3.8/site-packages/flask/app.py", line 1474, in raise_routing_exception
    raise request.routing_exception  # type: ignore
  File "/home/new_user/Desktop/Flask_ss/venv/lib/python3.8/site-packages/flask/ctx.py", line 367, in match_request
    result = self.url_adapter.match(return_rule=True)  # type: ignore
  File "/home/new_user/Desktop/Flask_ss/venv/lib/python3.8/site-packages/werkzeug/routing.py", line 2032, in match
    raise NotFound()
werkzeug.exceptions.NotFound: 404 Not Found: The requested URL was not found on the server. If you entered the URL manually please check your spelling and try again.

During handling of the above exception, another exception occurred:

Traceback (most recent call last):
  File "/home/new_user/Desktop/Flask_ss/venv/lib/python3.8/site-packages/flask/app.py", line 2073, in wsgi_app
    response = self.full_dispatch_request()
  File "/home/new_user/Desktop/Flask_ss/venv/lib/python3.8/site-packages/flask/app.py", line 1518, in full_dispatch_request
    rv = self.handle_user_exception(e)
  File "/home/new_user/Desktop/Flask_ss/venv/lib/python3.8/site-packages/flask/app.py", line 1386, in handle_user_exception
    return self.handle_http_exception(e)
  File "/home/new_user/Desktop/Flask_ss/venv/lib/python3.8/site-packages/flask/app.py", line 1326, in handle_http_exception
    return self.ensure_sync(handler)(e)
TypeError: not_found_error() takes 0 positional arguments but 1 was given
2021-11-28 22:39:01,530 ERROR: Exception on /_styles.css [GET] [int /home/new_user/Desktop/Flask_ss/venv/lib/python3.8/site-packages/flask/app.py:1457]
Traceback (most recent call last):
  File "/home/new_user/Desktop/Flask_ss/venv/lib/python3.8/site-packages/flask/app.py", line 1516, in full_dispatch_request
    rv = self.dispatch_request()
  File "/home/new_user/Desktop/Flask_ss/venv/lib/python3.8/site-packages/flask/app.py", line 1492, in dispatch_request
    self.raise_routing_exception(req)
  File "/home/new_user/Desktop/Flask_ss/venv/lib/python3.8/site-packages/flask/app.py", line 1474, in raise_routing_exception
    raise request.routing_exception  # type: ignore
  File "/home/new_user/Desktop/Flask_ss/venv/lib/python3.8/site-packages/flask/ctx.py", line 367, in match_request
    result = self.url_adapter.match(return_rule=True)  # type: ignore
  File "/home/new_user/Desktop/Flask_ss/venv/lib/python3.8/site-packages/werkzeug/routing.py", line 2032, in match
    raise NotFound()
werkzeug.exceptions.NotFound: 404 Not Found: The requested URL was not found on the server. If you entered the URL manually please check your spelling and try again.

During handling of the above exception, another exception occurred:

Traceback (most recent call last):
  File "/home/new_user/Desktop/Flask_ss/venv/lib/python3.8/site-packages/flask/app.py", line 2073, in wsgi_app
    response = self.full_dispatch_request()
  File "/home/new_user/Desktop/Flask_ss/venv/lib/python3.8/site-packages/flask/app.py", line 1518, in full_dispatch_request
    rv = self.handle_user_exception(e)
  File "/home/new_user/Desktop/Flask_ss/venv/lib/python3.8/site-packages/flask/app.py", line 1386, in handle_user_exception
    return self.handle_http_exception(e)
  File "/home/new_user/Desktop/Flask_ss/venv/lib/python3.8/site-packages/flask/app.py", line 1326, in handle_http_exception
    return self.ensure_sync(handler)(e)
TypeError: not_found_error() takes 0 positional arguments but 1 was given
2021-11-28 22:39:04,754 ERROR: Exception on /user/ucmc2020ss254/Json_models/Page_cfg.json [GET] [int /home/new_user/Desktop/Flask_ss/venv/lib/python3.8/site-packages/flask/app.py:1457]
Traceback (most recent call last):
  File "/home/new_user/Desktop/Flask_ss/venv/lib/python3.8/site-packages/flask/app.py", line 1516, in full_dispatch_request
    rv = self.dispatch_request()
  File "/home/new_user/Desktop/Flask_ss/venv/lib/python3.8/site-packages/flask/app.py", line 1502, in dispatch_request
    return self.ensure_sync(self.view_functions[rule.endpoint])(**req.view_args)
  File "/home/new_user/Desktop/Flask_ss/app/main/routes.py", line 21, in send_textures
    return send_from_directory(cur_folder, path)
  File "/home/new_user/Desktop/Flask_ss/venv/lib/python3.8/site-packages/flask/helpers.py", line 700, in send_from_directory
    return werkzeug.utils.send_from_directory(  # type: ignore
  File "/home/new_user/Desktop/Flask_ss/venv/lib/python3.8/site-packages/werkzeug/utils.py", line 841, in send_from_directory
    raise NotFound()
werkzeug.exceptions.NotFound: 404 Not Found: The requested URL was not found on the server. If you entered the URL manually please check your spelling and try again.

During handling of the above exception, another exception occurred:

Traceback (most recent call last):
  File "/home/new_user/Desktop/Flask_ss/venv/lib/python3.8/site-packages/flask/app.py", line 2073, in wsgi_app
    response = self.full_dispatch_request()
  File "/home/new_user/Desktop/Flask_ss/venv/lib/python3.8/site-packages/flask/app.py", line 1518, in full_dispatch_request
    rv = self.handle_user_exception(e)
  File "/home/new_user/Desktop/Flask_ss/venv/lib/python3.8/site-packages/flask/app.py", line 1386, in handle_user_exception
    return self.handle_http_exception(e)
  File "/home/new_user/Desktop/Flask_ss/venv/lib/python3.8/site-packages/flask/app.py", line 1326, in handle_http_exception
    return self.ensure_sync(handler)(e)
TypeError: not_found_error() takes 0 positional arguments but 1 was given
2021-11-28 22:39:16,436 ERROR: Exception on /favicon.ico [GET] [int /home/new_user/Desktop/Flask_ss/venv/lib/python3.8/site-packages/flask/app.py:1457]
Traceback (most recent call last):
  File "/home/new_user/Desktop/Flask_ss/venv/lib/python3.8/site-packages/flask/app.py", line 1516, in full_dispatch_request
    rv = self.dispatch_request()
  File "/home/new_user/Desktop/Flask_ss/venv/lib/python3.8/site-packages/flask/app.py", line 1492, in dispatch_request
    self.raise_routing_exception(req)
  File "/home/new_user/Desktop/Flask_ss/venv/lib/python3.8/site-packages/flask/app.py", line 1474, in raise_routing_exception
    raise request.routing_exception  # type: ignore
  File "/home/new_user/Desktop/Flask_ss/venv/lib/python3.8/site-packages/flask/ctx.py", line 367, in match_request
    result = self.url_adapter.match(return_rule=True)  # type: ignore
  File "/home/new_user/Desktop/Flask_ss/venv/lib/python3.8/site-packages/werkzeug/routing.py", line 2032, in match
    raise NotFound()
werkzeug.exceptions.NotFound: 404 Not Found: The requested URL was not found on the server. If you entered the URL manually please check your spelling and try again.

During handling of the above exception, another exception occurred:

Traceback (most recent call last):
  File "/home/new_user/Desktop/Flask_ss/venv/lib/python3.8/site-packages/flask/app.py", line 2073, in wsgi_app
    response = self.full_dispatch_request()
  File "/home/new_user/Desktop/Flask_ss/venv/lib/python3.8/site-packages/flask/app.py", line 1518, in full_dispatch_request
    rv = self.handle_user_exception(e)
  File "/home/new_user/Desktop/Flask_ss/venv/lib/python3.8/site-packages/flask/app.py", line 1386, in handle_user_exception
    return self.handle_http_exception(e)
  File "/home/new_user/Desktop/Flask_ss/venv/lib/python3.8/site-packages/flask/app.py", line 1326, in handle_http_exception
    return self.ensure_sync(handler)(e)
TypeError: not_found_error() takes 0 positional arguments but 1 was given
2021-11-28 22:41:27,614 ERROR: Exception on /_styles.css [GET] [int /home/new_user/Desktop/Flask_ss/venv/lib/python3.8/site-packages/flask/app.py:1457]
Traceback (most recent call last):
  File "/home/new_user/Desktop/Flask_ss/venv/lib/python3.8/site-packages/flask/app.py", line 1516, in full_dispatch_request
    rv = self.dispatch_request()
  File "/home/new_user/Desktop/Flask_ss/venv/lib/python3.8/site-packages/flask/app.py", line 1492, in dispatch_request
    self.raise_routing_exception(req)
  File "/home/new_user/Desktop/Flask_ss/venv/lib/python3.8/site-packages/flask/app.py", line 1474, in raise_routing_exception
    raise request.routing_exception  # type: ignore
  File "/home/new_user/Desktop/Flask_ss/venv/lib/python3.8/site-packages/flask/ctx.py", line 367, in match_request
    result = self.url_adapter.match(return_rule=True)  # type: ignore
  File "/home/new_user/Desktop/Flask_ss/venv/lib/python3.8/site-packages/werkzeug/routing.py", line 2032, in match
    raise NotFound()
werkzeug.exceptions.NotFound: 404 Not Found: The requested URL was not found on the server. If you entered the URL manually please check your spelling and try again.

During handling of the above exception, another exception occurred:

Traceback (most recent call last):
  File "/home/new_user/Desktop/Flask_ss/venv/lib/python3.8/site-packages/flask/app.py", line 2073, in wsgi_app
    response = self.full_dispatch_request()
  File "/home/new_user/Desktop/Flask_ss/venv/lib/python3.8/site-packages/flask/app.py", line 1518, in full_dispatch_request
    rv = self.handle_user_exception(e)
  File "/home/new_user/Desktop/Flask_ss/venv/lib/python3.8/site-packages/flask/app.py", line 1386, in handle_user_exception
    return self.handle_http_exception(e)
  File "/home/new_user/Desktop/Flask_ss/venv/lib/python3.8/site-packages/flask/app.py", line 1326, in handle_http_exception
    return self.ensure_sync(handler)(e)
TypeError: not_found_error() takes 0 positional arguments but 1 was given
2021-11-28 22:41:30,774 ERROR: Exception on /user/ucmc2020ss254/Json_models/Page_cfg.json [GET] [int /home/new_user/Desktop/Flask_ss/venv/lib/python3.8/site-packages/flask/app.py:1457]
Traceback (most recent call last):
  File "/home/new_user/Desktop/Flask_ss/venv/lib/python3.8/site-packages/flask/app.py", line 1516, in full_dispatch_request
    rv = self.dispatch_request()
  File "/home/new_user/Desktop/Flask_ss/venv/lib/python3.8/site-packages/flask/app.py", line 1502, in dispatch_request
    return self.ensure_sync(self.view_functions[rule.endpoint])(**req.view_args)
  File "/home/new_user/Desktop/Flask_ss/app/main/routes.py", line 21, in send_textures
    return send_from_directory(cur_folder, path)
  File "/home/new_user/Desktop/Flask_ss/venv/lib/python3.8/site-packages/flask/helpers.py", line 700, in send_from_directory
    return werkzeug.utils.send_from_directory(  # type: ignore
  File "/home/new_user/Desktop/Flask_ss/venv/lib/python3.8/site-packages/werkzeug/utils.py", line 841, in send_from_directory
    raise NotFound()
werkzeug.exceptions.NotFound: 404 Not Found: The requested URL was not found on the server. If you entered the URL manually please check your spelling and try again.

During handling of the above exception, another exception occurred:

Traceback (most recent call last):
  File "/home/new_user/Desktop/Flask_ss/venv/lib/python3.8/site-packages/flask/app.py", line 2073, in wsgi_app
    response = self.full_dispatch_request()
  File "/home/new_user/Desktop/Flask_ss/venv/lib/python3.8/site-packages/flask/app.py", line 1518, in full_dispatch_request
    rv = self.handle_user_exception(e)
  File "/home/new_user/Desktop/Flask_ss/venv/lib/python3.8/site-packages/flask/app.py", line 1386, in handle_user_exception
    return self.handle_http_exception(e)
  File "/home/new_user/Desktop/Flask_ss/venv/lib/python3.8/site-packages/flask/app.py", line 1326, in handle_http_exception
    return self.ensure_sync(handler)(e)
TypeError: not_found_error() takes 0 positional arguments but 1 was given
2021-11-28 22:49:54,307 ERROR: Exception on /favicon.ico [GET] [int /home/new_user/Desktop/Flask_ss/venv/lib/python3.8/site-packages/flask/app.py:1457]
Traceback (most recent call last):
  File "/home/new_user/Desktop/Flask_ss/venv/lib/python3.8/site-packages/flask/app.py", line 1516, in full_dispatch_request
    rv = self.dispatch_request()
  File "/home/new_user/Desktop/Flask_ss/venv/lib/python3.8/site-packages/flask/app.py", line 1492, in dispatch_request
    self.raise_routing_exception(req)
  File "/home/new_user/Desktop/Flask_ss/venv/lib/python3.8/site-packages/flask/app.py", line 1474, in raise_routing_exception
    raise request.routing_exception  # type: ignore
  File "/home/new_user/Desktop/Flask_ss/venv/lib/python3.8/site-packages/flask/ctx.py", line 367, in match_request
    result = self.url_adapter.match(return_rule=True)  # type: ignore
  File "/home/new_user/Desktop/Flask_ss/venv/lib/python3.8/site-packages/werkzeug/routing.py", line 2032, in match
    raise NotFound()
werkzeug.exceptions.NotFound: 404 Not Found: The requested URL was not found on the server. If you entered the URL manually please check your spelling and try again.

During handling of the above exception, another exception occurred:

Traceback (most recent call last):
  File "/home/new_user/Desktop/Flask_ss/venv/lib/python3.8/site-packages/flask/app.py", line 2073, in wsgi_app
    response = self.full_dispatch_request()
  File "/home/new_user/Desktop/Flask_ss/venv/lib/python3.8/site-packages/flask/app.py", line 1518, in full_dispatch_request
    rv = self.handle_user_exception(e)
  File "/home/new_user/Desktop/Flask_ss/venv/lib/python3.8/site-packages/flask/app.py", line 1386, in handle_user_exception
    return self.handle_http_exception(e)
  File "/home/new_user/Desktop/Flask_ss/venv/lib/python3.8/site-packages/flask/app.py", line 1326, in handle_http_exception
    return self.ensure_sync(handler)(e)
TypeError: not_found_error() takes 0 positional arguments but 1 was given
2021-11-28 22:54:23,588 INFO: Microbial startup [int /home/new_user/Desktop/Flask_ss/app/__init__.py:74]
2021-11-28 22:54:34,778 INFO: Microbial startup [int /home/new_user/Desktop/Flask_ss/app/__init__.py:74]
2021-11-28 22:54:58,222 ERROR: Exception on /_styles.css [GET] [int /home/new_user/Desktop/Flask_ss/venv/lib/python3.8/site-packages/flask/app.py:1457]
Traceback (most recent call last):
  File "/home/new_user/Desktop/Flask_ss/venv/lib/python3.8/site-packages/flask/app.py", line 1516, in full_dispatch_request
    rv = self.dispatch_request()
  File "/home/new_user/Desktop/Flask_ss/venv/lib/python3.8/site-packages/flask/app.py", line 1492, in dispatch_request
    self.raise_routing_exception(req)
  File "/home/new_user/Desktop/Flask_ss/venv/lib/python3.8/site-packages/flask/app.py", line 1474, in raise_routing_exception
    raise request.routing_exception  # type: ignore
  File "/home/new_user/Desktop/Flask_ss/venv/lib/python3.8/site-packages/flask/ctx.py", line 367, in match_request
    result = self.url_adapter.match(return_rule=True)  # type: ignore
  File "/home/new_user/Desktop/Flask_ss/venv/lib/python3.8/site-packages/werkzeug/routing.py", line 2032, in match
    raise NotFound()
werkzeug.exceptions.NotFound: 404 Not Found: The requested URL was not found on the server. If you entered the URL manually please check your spelling and try again.

During handling of the above exception, another exception occurred:

Traceback (most recent call last):
  File "/home/new_user/Desktop/Flask_ss/venv/lib/python3.8/site-packages/flask/app.py", line 2073, in wsgi_app
    response = self.full_dispatch_request()
  File "/home/new_user/Desktop/Flask_ss/venv/lib/python3.8/site-packages/flask/app.py", line 1518, in full_dispatch_request
    rv = self.handle_user_exception(e)
  File "/home/new_user/Desktop/Flask_ss/venv/lib/python3.8/site-packages/flask/app.py", line 1386, in handle_user_exception
    return self.handle_http_exception(e)
  File "/home/new_user/Desktop/Flask_ss/venv/lib/python3.8/site-packages/flask/app.py", line 1326, in handle_http_exception
    return self.ensure_sync(handler)(e)
TypeError: not_found_error() takes 0 positional arguments but 1 was given
2021-11-28 22:54:58,892 ERROR: Exception on /favicon.ico [GET] [int /home/new_user/Desktop/Flask_ss/venv/lib/python3.8/site-packages/flask/app.py:1457]
Traceback (most recent call last):
  File "/home/new_user/Desktop/Flask_ss/venv/lib/python3.8/site-packages/flask/app.py", line 1516, in full_dispatch_request
    rv = self.dispatch_request()
  File "/home/new_user/Desktop/Flask_ss/venv/lib/python3.8/site-packages/flask/app.py", line 1492, in dispatch_request
    self.raise_routing_exception(req)
  File "/home/new_user/Desktop/Flask_ss/venv/lib/python3.8/site-packages/flask/app.py", line 1474, in raise_routing_exception
    raise request.routing_exception  # type: ignore
  File "/home/new_user/Desktop/Flask_ss/venv/lib/python3.8/site-packages/flask/ctx.py", line 367, in match_request
    result = self.url_adapter.match(return_rule=True)  # type: ignore
  File "/home/new_user/Desktop/Flask_ss/venv/lib/python3.8/site-packages/werkzeug/routing.py", line 2032, in match
    raise NotFound()
werkzeug.exceptions.NotFound: 404 Not Found: The requested URL was not found on the server. If you entered the URL manually please check your spelling and try again.

During handling of the above exception, another exception occurred:

Traceback (most recent call last):
  File "/home/new_user/Desktop/Flask_ss/venv/lib/python3.8/site-packages/flask/app.py", line 2073, in wsgi_app
    response = self.full_dispatch_request()
  File "/home/new_user/Desktop/Flask_ss/venv/lib/python3.8/site-packages/flask/app.py", line 1518, in full_dispatch_request
    rv = self.handle_user_exception(e)
  File "/home/new_user/Desktop/Flask_ss/venv/lib/python3.8/site-packages/flask/app.py", line 1386, in handle_user_exception
    return self.handle_http_exception(e)
  File "/home/new_user/Desktop/Flask_ss/venv/lib/python3.8/site-packages/flask/app.py", line 1326, in handle_http_exception
    return self.ensure_sync(handler)(e)
TypeError: not_found_error() takes 0 positional arguments but 1 was given
2021-11-28 22:55:02,770 ERROR: Exception on /_styles.css [GET] [int /home/new_user/Desktop/Flask_ss/venv/lib/python3.8/site-packages/flask/app.py:1457]
Traceback (most recent call last):
  File "/home/new_user/Desktop/Flask_ss/venv/lib/python3.8/site-packages/flask/app.py", line 1516, in full_dispatch_request
    rv = self.dispatch_request()
  File "/home/new_user/Desktop/Flask_ss/venv/lib/python3.8/site-packages/flask/app.py", line 1492, in dispatch_request
    self.raise_routing_exception(req)
  File "/home/new_user/Desktop/Flask_ss/venv/lib/python3.8/site-packages/flask/app.py", line 1474, in raise_routing_exception
    raise request.routing_exception  # type: ignore
  File "/home/new_user/Desktop/Flask_ss/venv/lib/python3.8/site-packages/flask/ctx.py", line 367, in match_request
    result = self.url_adapter.match(return_rule=True)  # type: ignore
  File "/home/new_user/Desktop/Flask_ss/venv/lib/python3.8/site-packages/werkzeug/routing.py", line 2032, in match
    raise NotFound()
werkzeug.exceptions.NotFound: 404 Not Found: The requested URL was not found on the server. If you entered the URL manually please check your spelling and try again.

During handling of the above exception, another exception occurred:

Traceback (most recent call last):
  File "/home/new_user/Desktop/Flask_ss/venv/lib/python3.8/site-packages/flask/app.py", line 2073, in wsgi_app
    response = self.full_dispatch_request()
  File "/home/new_user/Desktop/Flask_ss/venv/lib/python3.8/site-packages/flask/app.py", line 1518, in full_dispatch_request
    rv = self.handle_user_exception(e)
  File "/home/new_user/Desktop/Flask_ss/venv/lib/python3.8/site-packages/flask/app.py", line 1386, in handle_user_exception
    return self.handle_http_exception(e)
  File "/home/new_user/Desktop/Flask_ss/venv/lib/python3.8/site-packages/flask/app.py", line 1326, in handle_http_exception
    return self.ensure_sync(handler)(e)
TypeError: not_found_error() takes 0 positional arguments but 1 was given
2021-11-28 22:55:02,823 ERROR: Exception on /favicon.ico [GET] [int /home/new_user/Desktop/Flask_ss/venv/lib/python3.8/site-packages/flask/app.py:1457]
Traceback (most recent call last):
  File "/home/new_user/Desktop/Flask_ss/venv/lib/python3.8/site-packages/flask/app.py", line 1516, in full_dispatch_request
    rv = self.dispatch_request()
  File "/home/new_user/Desktop/Flask_ss/venv/lib/python3.8/site-packages/flask/app.py", line 1492, in dispatch_request
    self.raise_routing_exception(req)
  File "/home/new_user/Desktop/Flask_ss/venv/lib/python3.8/site-packages/flask/app.py", line 1474, in raise_routing_exception
    raise request.routing_exception  # type: ignore
  File "/home/new_user/Desktop/Flask_ss/venv/lib/python3.8/site-packages/flask/ctx.py", line 367, in match_request
    result = self.url_adapter.match(return_rule=True)  # type: ignore
  File "/home/new_user/Desktop/Flask_ss/venv/lib/python3.8/site-packages/werkzeug/routing.py", line 2032, in match
    raise NotFound()
werkzeug.exceptions.NotFound: 404 Not Found: The requested URL was not found on the server. If you entered the URL manually please check your spelling and try again.

During handling of the above exception, another exception occurred:

Traceback (most recent call last):
  File "/home/new_user/Desktop/Flask_ss/venv/lib/python3.8/site-packages/flask/app.py", line 2073, in wsgi_app
    response = self.full_dispatch_request()
  File "/home/new_user/Desktop/Flask_ss/venv/lib/python3.8/site-packages/flask/app.py", line 1518, in full_dispatch_request
    rv = self.handle_user_exception(e)
  File "/home/new_user/Desktop/Flask_ss/venv/lib/python3.8/site-packages/flask/app.py", line 1386, in handle_user_exception
    return self.handle_http_exception(e)
  File "/home/new_user/Desktop/Flask_ss/venv/lib/python3.8/site-packages/flask/app.py", line 1326, in handle_http_exception
    return self.ensure_sync(handler)(e)
TypeError: not_found_error() takes 0 positional arguments but 1 was given
2021-11-28 22:55:12,197 ERROR: Exception on /register [GET] [int /home/new_user/Desktop/Flask_ss/venv/lib/python3.8/site-packages/flask/app.py:1457]
Traceback (most recent call last):
  File "/home/new_user/Desktop/Flask_ss/venv/lib/python3.8/site-packages/flask/app.py", line 1516, in full_dispatch_request
    rv = self.dispatch_request()
  File "/home/new_user/Desktop/Flask_ss/venv/lib/python3.8/site-packages/flask/app.py", line 1492, in dispatch_request
    self.raise_routing_exception(req)
  File "/home/new_user/Desktop/Flask_ss/venv/lib/python3.8/site-packages/flask/app.py", line 1474, in raise_routing_exception
    raise request.routing_exception  # type: ignore
  File "/home/new_user/Desktop/Flask_ss/venv/lib/python3.8/site-packages/flask/ctx.py", line 367, in match_request
    result = self.url_adapter.match(return_rule=True)  # type: ignore
  File "/home/new_user/Desktop/Flask_ss/venv/lib/python3.8/site-packages/werkzeug/routing.py", line 2032, in match
    raise NotFound()
werkzeug.exceptions.NotFound: 404 Not Found: The requested URL was not found on the server. If you entered the URL manually please check your spelling and try again.

During handling of the above exception, another exception occurred:

Traceback (most recent call last):
  File "/home/new_user/Desktop/Flask_ss/venv/lib/python3.8/site-packages/flask/app.py", line 2073, in wsgi_app
    response = self.full_dispatch_request()
  File "/home/new_user/Desktop/Flask_ss/venv/lib/python3.8/site-packages/flask/app.py", line 1518, in full_dispatch_request
    rv = self.handle_user_exception(e)
  File "/home/new_user/Desktop/Flask_ss/venv/lib/python3.8/site-packages/flask/app.py", line 1386, in handle_user_exception
    return self.handle_http_exception(e)
  File "/home/new_user/Desktop/Flask_ss/venv/lib/python3.8/site-packages/flask/app.py", line 1326, in handle_http_exception
    return self.ensure_sync(handler)(e)
TypeError: not_found_error() takes 0 positional arguments but 1 was given
2021-11-28 22:55:12,241 ERROR: Exception on /_styles.css [GET] [int /home/new_user/Desktop/Flask_ss/venv/lib/python3.8/site-packages/flask/app.py:1457]
Traceback (most recent call last):
  File "/home/new_user/Desktop/Flask_ss/venv/lib/python3.8/site-packages/flask/app.py", line 1516, in full_dispatch_request
    rv = self.dispatch_request()
  File "/home/new_user/Desktop/Flask_ss/venv/lib/python3.8/site-packages/flask/app.py", line 1492, in dispatch_request
    self.raise_routing_exception(req)
  File "/home/new_user/Desktop/Flask_ss/venv/lib/python3.8/site-packages/flask/app.py", line 1474, in raise_routing_exception
    raise request.routing_exception  # type: ignore
  File "/home/new_user/Desktop/Flask_ss/venv/lib/python3.8/site-packages/flask/ctx.py", line 367, in match_request
    result = self.url_adapter.match(return_rule=True)  # type: ignore
  File "/home/new_user/Desktop/Flask_ss/venv/lib/python3.8/site-packages/werkzeug/routing.py", line 2032, in match
    raise NotFound()
werkzeug.exceptions.NotFound: 404 Not Found: The requested URL was not found on the server. If you entered the URL manually please check your spelling and try again.

During handling of the above exception, another exception occurred:

Traceback (most recent call last):
  File "/home/new_user/Desktop/Flask_ss/venv/lib/python3.8/site-packages/flask/app.py", line 2073, in wsgi_app
    response = self.full_dispatch_request()
  File "/home/new_user/Desktop/Flask_ss/venv/lib/python3.8/site-packages/flask/app.py", line 1518, in full_dispatch_request
    rv = self.handle_user_exception(e)
  File "/home/new_user/Desktop/Flask_ss/venv/lib/python3.8/site-packages/flask/app.py", line 1386, in handle_user_exception
    return self.handle_http_exception(e)
  File "/home/new_user/Desktop/Flask_ss/venv/lib/python3.8/site-packages/flask/app.py", line 1326, in handle_http_exception
    return self.ensure_sync(handler)(e)
TypeError: not_found_error() takes 0 positional arguments but 1 was given
2021-11-28 22:55:12,313 ERROR: Exception on /favicon.ico [GET] [int /home/new_user/Desktop/Flask_ss/venv/lib/python3.8/site-packages/flask/app.py:1457]
Traceback (most recent call last):
  File "/home/new_user/Desktop/Flask_ss/venv/lib/python3.8/site-packages/flask/app.py", line 1516, in full_dispatch_request
    rv = self.dispatch_request()
  File "/home/new_user/Desktop/Flask_ss/venv/lib/python3.8/site-packages/flask/app.py", line 1492, in dispatch_request
    self.raise_routing_exception(req)
  File "/home/new_user/Desktop/Flask_ss/venv/lib/python3.8/site-packages/flask/app.py", line 1474, in raise_routing_exception
    raise request.routing_exception  # type: ignore
  File "/home/new_user/Desktop/Flask_ss/venv/lib/python3.8/site-packages/flask/ctx.py", line 367, in match_request
    result = self.url_adapter.match(return_rule=True)  # type: ignore
  File "/home/new_user/Desktop/Flask_ss/venv/lib/python3.8/site-packages/werkzeug/routing.py", line 2032, in match
    raise NotFound()
werkzeug.exceptions.NotFound: 404 Not Found: The requested URL was not found on the server. If you entered the URL manually please check your spelling and try again.

During handling of the above exception, another exception occurred:

Traceback (most recent call last):
  File "/home/new_user/Desktop/Flask_ss/venv/lib/python3.8/site-packages/flask/app.py", line 2073, in wsgi_app
    response = self.full_dispatch_request()
  File "/home/new_user/Desktop/Flask_ss/venv/lib/python3.8/site-packages/flask/app.py", line 1518, in full_dispatch_request
    rv = self.handle_user_exception(e)
  File "/home/new_user/Desktop/Flask_ss/venv/lib/python3.8/site-packages/flask/app.py", line 1386, in handle_user_exception
    return self.handle_http_exception(e)
  File "/home/new_user/Desktop/Flask_ss/venv/lib/python3.8/site-packages/flask/app.py", line 1326, in handle_http_exception
    return self.ensure_sync(handler)(e)
TypeError: not_found_error() takes 0 positional arguments but 1 was given
2021-11-28 23:00:26,989 INFO: Microbial startup [int /home/new_user/Desktop/Flask_ss/app/__init__.py:77]
2021-11-28 23:00:32,836 INFO: Microbial startup [int /home/new_user/Desktop/Flask_ss/app/__init__.py:77]
2021-11-28 23:00:42,245 ERROR: Exception on /_styles.css [GET] [int /home/new_user/Desktop/Flask_ss/venv/lib/python3.8/site-packages/flask/app.py:1457]
Traceback (most recent call last):
  File "/home/new_user/Desktop/Flask_ss/venv/lib/python3.8/site-packages/flask/app.py", line 1516, in full_dispatch_request
    rv = self.dispatch_request()
  File "/home/new_user/Desktop/Flask_ss/venv/lib/python3.8/site-packages/flask/app.py", line 1492, in dispatch_request
    self.raise_routing_exception(req)
  File "/home/new_user/Desktop/Flask_ss/venv/lib/python3.8/site-packages/flask/app.py", line 1474, in raise_routing_exception
    raise request.routing_exception  # type: ignore
  File "/home/new_user/Desktop/Flask_ss/venv/lib/python3.8/site-packages/flask/ctx.py", line 367, in match_request
    result = self.url_adapter.match(return_rule=True)  # type: ignore
  File "/home/new_user/Desktop/Flask_ss/venv/lib/python3.8/site-packages/werkzeug/routing.py", line 2032, in match
    raise NotFound()
werkzeug.exceptions.NotFound: 404 Not Found: The requested URL was not found on the server. If you entered the URL manually please check your spelling and try again.

During handling of the above exception, another exception occurred:

Traceback (most recent call last):
  File "/home/new_user/Desktop/Flask_ss/venv/lib/python3.8/site-packages/flask/app.py", line 2073, in wsgi_app
    response = self.full_dispatch_request()
  File "/home/new_user/Desktop/Flask_ss/venv/lib/python3.8/site-packages/flask/app.py", line 1518, in full_dispatch_request
    rv = self.handle_user_exception(e)
  File "/home/new_user/Desktop/Flask_ss/venv/lib/python3.8/site-packages/flask/app.py", line 1386, in handle_user_exception
    return self.handle_http_exception(e)
  File "/home/new_user/Desktop/Flask_ss/venv/lib/python3.8/site-packages/flask/app.py", line 1326, in handle_http_exception
    return self.ensure_sync(handler)(e)
TypeError: not_found_error() takes 0 positional arguments but 1 was given
2021-11-28 23:00:43,135 ERROR: Exception on /favicon.ico [GET] [int /home/new_user/Desktop/Flask_ss/venv/lib/python3.8/site-packages/flask/app.py:1457]
Traceback (most recent call last):
  File "/home/new_user/Desktop/Flask_ss/venv/lib/python3.8/site-packages/flask/app.py", line 1516, in full_dispatch_request
    rv = self.dispatch_request()
  File "/home/new_user/Desktop/Flask_ss/venv/lib/python3.8/site-packages/flask/app.py", line 1492, in dispatch_request
    self.raise_routing_exception(req)
  File "/home/new_user/Desktop/Flask_ss/venv/lib/python3.8/site-packages/flask/app.py", line 1474, in raise_routing_exception
    raise request.routing_exception  # type: ignore
  File "/home/new_user/Desktop/Flask_ss/venv/lib/python3.8/site-packages/flask/ctx.py", line 367, in match_request
    result = self.url_adapter.match(return_rule=True)  # type: ignore
  File "/home/new_user/Desktop/Flask_ss/venv/lib/python3.8/site-packages/werkzeug/routing.py", line 2032, in match
    raise NotFound()
werkzeug.exceptions.NotFound: 404 Not Found: The requested URL was not found on the server. If you entered the URL manually please check your spelling and try again.

During handling of the above exception, another exception occurred:

Traceback (most recent call last):
  File "/home/new_user/Desktop/Flask_ss/venv/lib/python3.8/site-packages/flask/app.py", line 2073, in wsgi_app
    response = self.full_dispatch_request()
  File "/home/new_user/Desktop/Flask_ss/venv/lib/python3.8/site-packages/flask/app.py", line 1518, in full_dispatch_request
    rv = self.handle_user_exception(e)
  File "/home/new_user/Desktop/Flask_ss/venv/lib/python3.8/site-packages/flask/app.py", line 1386, in handle_user_exception
    return self.handle_http_exception(e)
  File "/home/new_user/Desktop/Flask_ss/venv/lib/python3.8/site-packages/flask/app.py", line 1326, in handle_http_exception
    return self.ensure_sync(handler)(e)
TypeError: not_found_error() takes 0 positional arguments but 1 was given
2021-11-28 23:00:44,560 ERROR: Exception on /_styles.css [GET] [int /home/new_user/Desktop/Flask_ss/venv/lib/python3.8/site-packages/flask/app.py:1457]
Traceback (most recent call last):
  File "/home/new_user/Desktop/Flask_ss/venv/lib/python3.8/site-packages/flask/app.py", line 1516, in full_dispatch_request
    rv = self.dispatch_request()
  File "/home/new_user/Desktop/Flask_ss/venv/lib/python3.8/site-packages/flask/app.py", line 1492, in dispatch_request
    self.raise_routing_exception(req)
  File "/home/new_user/Desktop/Flask_ss/venv/lib/python3.8/site-packages/flask/app.py", line 1474, in raise_routing_exception
    raise request.routing_exception  # type: ignore
  File "/home/new_user/Desktop/Flask_ss/venv/lib/python3.8/site-packages/flask/ctx.py", line 367, in match_request
    result = self.url_adapter.match(return_rule=True)  # type: ignore
  File "/home/new_user/Desktop/Flask_ss/venv/lib/python3.8/site-packages/werkzeug/routing.py", line 2032, in match
    raise NotFound()
werkzeug.exceptions.NotFound: 404 Not Found: The requested URL was not found on the server. If you entered the URL manually please check your spelling and try again.

During handling of the above exception, another exception occurred:

Traceback (most recent call last):
  File "/home/new_user/Desktop/Flask_ss/venv/lib/python3.8/site-packages/flask/app.py", line 2073, in wsgi_app
    response = self.full_dispatch_request()
  File "/home/new_user/Desktop/Flask_ss/venv/lib/python3.8/site-packages/flask/app.py", line 1518, in full_dispatch_request
    rv = self.handle_user_exception(e)
  File "/home/new_user/Desktop/Flask_ss/venv/lib/python3.8/site-packages/flask/app.py", line 1386, in handle_user_exception
    return self.handle_http_exception(e)
  File "/home/new_user/Desktop/Flask_ss/venv/lib/python3.8/site-packages/flask/app.py", line 1326, in handle_http_exception
    return self.ensure_sync(handler)(e)
TypeError: not_found_error() takes 0 positional arguments but 1 was given
2021-11-28 23:00:44,865 ERROR: Exception on /favicon.ico [GET] [int /home/new_user/Desktop/Flask_ss/venv/lib/python3.8/site-packages/flask/app.py:1457]
Traceback (most recent call last):
  File "/home/new_user/Desktop/Flask_ss/venv/lib/python3.8/site-packages/flask/app.py", line 1516, in full_dispatch_request
    rv = self.dispatch_request()
  File "/home/new_user/Desktop/Flask_ss/venv/lib/python3.8/site-packages/flask/app.py", line 1492, in dispatch_request
    self.raise_routing_exception(req)
  File "/home/new_user/Desktop/Flask_ss/venv/lib/python3.8/site-packages/flask/app.py", line 1474, in raise_routing_exception
    raise request.routing_exception  # type: ignore
  File "/home/new_user/Desktop/Flask_ss/venv/lib/python3.8/site-packages/flask/ctx.py", line 367, in match_request
    result = self.url_adapter.match(return_rule=True)  # type: ignore
  File "/home/new_user/Desktop/Flask_ss/venv/lib/python3.8/site-packages/werkzeug/routing.py", line 2032, in match
    raise NotFound()
werkzeug.exceptions.NotFound: 404 Not Found: The requested URL was not found on the server. If you entered the URL manually please check your spelling and try again.

During handling of the above exception, another exception occurred:

Traceback (most recent call last):
  File "/home/new_user/Desktop/Flask_ss/venv/lib/python3.8/site-packages/flask/app.py", line 2073, in wsgi_app
    response = self.full_dispatch_request()
  File "/home/new_user/Desktop/Flask_ss/venv/lib/python3.8/site-packages/flask/app.py", line 1518, in full_dispatch_request
    rv = self.handle_user_exception(e)
  File "/home/new_user/Desktop/Flask_ss/venv/lib/python3.8/site-packages/flask/app.py", line 1386, in handle_user_exception
    return self.handle_http_exception(e)
  File "/home/new_user/Desktop/Flask_ss/venv/lib/python3.8/site-packages/flask/app.py", line 1326, in handle_http_exception
    return self.ensure_sync(handler)(e)
TypeError: not_found_error() takes 0 positional arguments but 1 was given
2021-11-28 23:00:58,433 ERROR: Exception on /_styles.css [GET] [int /home/new_user/Desktop/Flask_ss/venv/lib/python3.8/site-packages/flask/app.py:1457]
Traceback (most recent call last):
  File "/home/new_user/Desktop/Flask_ss/venv/lib/python3.8/site-packages/flask/app.py", line 1516, in full_dispatch_request
    rv = self.dispatch_request()
  File "/home/new_user/Desktop/Flask_ss/venv/lib/python3.8/site-packages/flask/app.py", line 1492, in dispatch_request
    self.raise_routing_exception(req)
  File "/home/new_user/Desktop/Flask_ss/venv/lib/python3.8/site-packages/flask/app.py", line 1474, in raise_routing_exception
    raise request.routing_exception  # type: ignore
  File "/home/new_user/Desktop/Flask_ss/venv/lib/python3.8/site-packages/flask/ctx.py", line 367, in match_request
    result = self.url_adapter.match(return_rule=True)  # type: ignore
  File "/home/new_user/Desktop/Flask_ss/venv/lib/python3.8/site-packages/werkzeug/routing.py", line 2032, in match
    raise NotFound()
werkzeug.exceptions.NotFound: 404 Not Found: The requested URL was not found on the server. If you entered the URL manually please check your spelling and try again.

During handling of the above exception, another exception occurred:

Traceback (most recent call last):
  File "/home/new_user/Desktop/Flask_ss/venv/lib/python3.8/site-packages/flask/app.py", line 2073, in wsgi_app
    response = self.full_dispatch_request()
  File "/home/new_user/Desktop/Flask_ss/venv/lib/python3.8/site-packages/flask/app.py", line 1518, in full_dispatch_request
    rv = self.handle_user_exception(e)
  File "/home/new_user/Desktop/Flask_ss/venv/lib/python3.8/site-packages/flask/app.py", line 1386, in handle_user_exception
    return self.handle_http_exception(e)
  File "/home/new_user/Desktop/Flask_ss/venv/lib/python3.8/site-packages/flask/app.py", line 1326, in handle_http_exception
    return self.ensure_sync(handler)(e)
TypeError: not_found_error() takes 0 positional arguments but 1 was given
2021-11-28 23:00:58,921 ERROR: Exception on /favicon.ico [GET] [int /home/new_user/Desktop/Flask_ss/venv/lib/python3.8/site-packages/flask/app.py:1457]
Traceback (most recent call last):
  File "/home/new_user/Desktop/Flask_ss/venv/lib/python3.8/site-packages/flask/app.py", line 1516, in full_dispatch_request
    rv = self.dispatch_request()
  File "/home/new_user/Desktop/Flask_ss/venv/lib/python3.8/site-packages/flask/app.py", line 1492, in dispatch_request
    self.raise_routing_exception(req)
  File "/home/new_user/Desktop/Flask_ss/venv/lib/python3.8/site-packages/flask/app.py", line 1474, in raise_routing_exception
    raise request.routing_exception  # type: ignore
  File "/home/new_user/Desktop/Flask_ss/venv/lib/python3.8/site-packages/flask/ctx.py", line 367, in match_request
    result = self.url_adapter.match(return_rule=True)  # type: ignore
  File "/home/new_user/Desktop/Flask_ss/venv/lib/python3.8/site-packages/werkzeug/routing.py", line 2032, in match
    raise NotFound()
werkzeug.exceptions.NotFound: 404 Not Found: The requested URL was not found on the server. If you entered the URL manually please check your spelling and try again.

During handling of the above exception, another exception occurred:

Traceback (most recent call last):
  File "/home/new_user/Desktop/Flask_ss/venv/lib/python3.8/site-packages/flask/app.py", line 2073, in wsgi_app
    response = self.full_dispatch_request()
  File "/home/new_user/Desktop/Flask_ss/venv/lib/python3.8/site-packages/flask/app.py", line 1518, in full_dispatch_request
    rv = self.handle_user_exception(e)
  File "/home/new_user/Desktop/Flask_ss/venv/lib/python3.8/site-packages/flask/app.py", line 1386, in handle_user_exception
    return self.handle_http_exception(e)
  File "/home/new_user/Desktop/Flask_ss/venv/lib/python3.8/site-packages/flask/app.py", line 1326, in handle_http_exception
    return self.ensure_sync(handler)(e)
TypeError: not_found_error() takes 0 positional arguments but 1 was given
2021-11-28 23:01:11,128 ERROR: Exception on /_styles.css [GET] [int /home/new_user/Desktop/Flask_ss/venv/lib/python3.8/site-packages/flask/app.py:1457]
Traceback (most recent call last):
  File "/home/new_user/Desktop/Flask_ss/venv/lib/python3.8/site-packages/flask/app.py", line 1516, in full_dispatch_request
    rv = self.dispatch_request()
  File "/home/new_user/Desktop/Flask_ss/venv/lib/python3.8/site-packages/flask/app.py", line 1492, in dispatch_request
    self.raise_routing_exception(req)
  File "/home/new_user/Desktop/Flask_ss/venv/lib/python3.8/site-packages/flask/app.py", line 1474, in raise_routing_exception
    raise request.routing_exception  # type: ignore
  File "/home/new_user/Desktop/Flask_ss/venv/lib/python3.8/site-packages/flask/ctx.py", line 367, in match_request
    result = self.url_adapter.match(return_rule=True)  # type: ignore
  File "/home/new_user/Desktop/Flask_ss/venv/lib/python3.8/site-packages/werkzeug/routing.py", line 2032, in match
    raise NotFound()
werkzeug.exceptions.NotFound: 404 Not Found: The requested URL was not found on the server. If you entered the URL manually please check your spelling and try again.

During handling of the above exception, another exception occurred:

Traceback (most recent call last):
  File "/home/new_user/Desktop/Flask_ss/venv/lib/python3.8/site-packages/flask/app.py", line 2073, in wsgi_app
    response = self.full_dispatch_request()
  File "/home/new_user/Desktop/Flask_ss/venv/lib/python3.8/site-packages/flask/app.py", line 1518, in full_dispatch_request
    rv = self.handle_user_exception(e)
  File "/home/new_user/Desktop/Flask_ss/venv/lib/python3.8/site-packages/flask/app.py", line 1386, in handle_user_exception
    return self.handle_http_exception(e)
  File "/home/new_user/Desktop/Flask_ss/venv/lib/python3.8/site-packages/flask/app.py", line 1326, in handle_http_exception
    return self.ensure_sync(handler)(e)
TypeError: not_found_error() takes 0 positional arguments but 1 was given
2021-11-28 23:01:11,315 ERROR: Exception on /favicon.ico [GET] [int /home/new_user/Desktop/Flask_ss/venv/lib/python3.8/site-packages/flask/app.py:1457]
Traceback (most recent call last):
  File "/home/new_user/Desktop/Flask_ss/venv/lib/python3.8/site-packages/flask/app.py", line 1516, in full_dispatch_request
    rv = self.dispatch_request()
  File "/home/new_user/Desktop/Flask_ss/venv/lib/python3.8/site-packages/flask/app.py", line 1492, in dispatch_request
    self.raise_routing_exception(req)
  File "/home/new_user/Desktop/Flask_ss/venv/lib/python3.8/site-packages/flask/app.py", line 1474, in raise_routing_exception
    raise request.routing_exception  # type: ignore
  File "/home/new_user/Desktop/Flask_ss/venv/lib/python3.8/site-packages/flask/ctx.py", line 367, in match_request
    result = self.url_adapter.match(return_rule=True)  # type: ignore
  File "/home/new_user/Desktop/Flask_ss/venv/lib/python3.8/site-packages/werkzeug/routing.py", line 2032, in match
    raise NotFound()
werkzeug.exceptions.NotFound: 404 Not Found: The requested URL was not found on the server. If you entered the URL manually please check your spelling and try again.

During handling of the above exception, another exception occurred:

Traceback (most recent call last):
  File "/home/new_user/Desktop/Flask_ss/venv/lib/python3.8/site-packages/flask/app.py", line 2073, in wsgi_app
    response = self.full_dispatch_request()
  File "/home/new_user/Desktop/Flask_ss/venv/lib/python3.8/site-packages/flask/app.py", line 1518, in full_dispatch_request
    rv = self.handle_user_exception(e)
  File "/home/new_user/Desktop/Flask_ss/venv/lib/python3.8/site-packages/flask/app.py", line 1386, in handle_user_exception
    return self.handle_http_exception(e)
  File "/home/new_user/Desktop/Flask_ss/venv/lib/python3.8/site-packages/flask/app.py", line 1326, in handle_http_exception
    return self.ensure_sync(handler)(e)
TypeError: not_found_error() takes 0 positional arguments but 1 was given
